package com.gtocore.common.data.machines;

import com.gtocore.api.machine.part.GTOPartAbility;
import com.gtocore.api.pattern.GTOPredicates;
import com.gtocore.common.data.*;
import com.gtocore.common.machine.multiblock.electric.FishingGroundMachine;
import com.gtocore.common.machine.multiblock.electric.StellarForgeMachine;
import com.gtocore.common.machine.multiblock.electric.assembly.PrecisionAssemblerMachine;
import com.gtocore.common.machine.multiblock.electric.voidseries.VoidFluidDrillingRigMachine;
import com.gtocore.common.machine.multiblock.electric.voidseries.VoidMinerMachine;
import com.gtocore.common.machine.multiblock.noenergy.AdvancedPrimitiveBlastFurnaceMachine;
import com.gtocore.common.machine.multiblock.steam.LargeSteamCircuitAssemblerMachine;
import com.gtocore.common.machine.multiblock.steam.LargeSteamMultiblockMachine;
import com.gtocore.common.machine.multiblock.steam.SteamMultiblockMachine;

import com.gtolib.GTOCore;
import com.gtolib.api.annotation.NewDataAttributes;
import com.gtolib.api.annotation.component_builder.ComponentBuilder;
import com.gtolib.api.annotation.component_builder.StyleBuilder;
import com.gtolib.api.machine.feature.multiblock.ICoilMachine;
import com.gtolib.api.machine.multiblock.*;
import com.gtolib.api.recipe.modifier.ParallelLogic;
import com.gtolib.api.recipe.modifier.RecipeModifierFunction;
import com.gtolib.utils.MultiBlockFileReader;
import com.gtolib.utils.RegistriesUtils;

import com.gregtechceu.gtceu.GTCEu;
import com.gregtechceu.gtceu.api.GTValues;
import com.gregtechceu.gtceu.api.data.chemical.ChemicalHelper;
import com.gregtechceu.gtceu.api.data.tag.TagPrefix;
import com.gregtechceu.gtceu.api.machine.MultiblockMachineDefinition;
import com.gregtechceu.gtceu.api.machine.multiblock.PartAbility;
import com.gregtechceu.gtceu.api.pattern.FactoryBlockPattern;
import com.gregtechceu.gtceu.api.pattern.MultiblockShapeInfo;
import com.gregtechceu.gtceu.api.pattern.Predicates;
import com.gregtechceu.gtceu.api.pattern.util.RelativeDirection;
import com.gregtechceu.gtceu.common.data.*;

import net.minecraft.core.Direction;
import net.minecraft.network.chat.Component;
import net.minecraft.world.item.DyeColor;
import net.minecraft.world.level.block.Blocks;
import net.minecraft.world.level.block.DirectionalBlock;
import net.minecraft.world.level.material.Fluids;

import appeng.core.definitions.AEBlocks;

import java.util.Comparator;

import static com.gregtechceu.gtceu.api.machine.multiblock.PartAbility.*;
import static com.gregtechceu.gtceu.api.pattern.Predicates.*;
import static com.gregtechceu.gtceu.api.pattern.util.RelativeDirection.*;
import static com.gregtechceu.gtceu.common.data.GTMaterials.Aluminium;
import static com.gtocore.common.block.BlockMap.CALMAP;
import static com.gtocore.common.block.BlockMap.SCMAP;
import static com.gtolib.api.GTOValues.*;
import static com.gtolib.utils.register.MachineRegisterUtils.CHEMICAL_PLANT_DISPLAY;
import static com.gtolib.utils.register.MachineRegisterUtils.multiblock;

public final class MultiBlockA {

    public static void init() {}

    public static final MultiblockMachineDefinition EVAPORATION_PLANT = multiblock("evaporation_plant", "蒸发塔", ElectricMultiblockMachine::new)
            .nonYAxisRotation()
            .recipeTypes(GTORecipeTypes.EVAPORATION_RECIPES)
            .overclock()
            .block(GTOBlocks.STAINLESS_EVAPORATION_CASING)
            .pattern(definition -> FactoryBlockPattern.start(RIGHT, BACK, UP)
                    .aisle("FYF", "YYY", "FYF")
                    .aisle("YSY", "Y#Y", "YYY")
                    .aisle("XXX", "X#X", "XXX").setRepeatable(5)
                    .aisle(" Z ", "ZZZ", " Z ")
                    .where('S', Predicates.controller(blocks(definition.getBlock())))
                    .where('Y', blocks(GTOBlocks.STAINLESS_EVAPORATION_CASING.get())
                            .or(Predicates.abilities(PartAbility.INPUT_ENERGY).setMinGlobalLimited(1)
                                    .setMaxGlobalLimited(2))
                            .or(Predicates.abilities(PartAbility.IMPORT_FLUIDS).setExactLimit(1))
                            .or(Predicates.abilities(PartAbility.EXPORT_ITEMS).setMaxGlobalLimited(1)))
                    .where('X', blocks(GTOBlocks.STAINLESS_EVAPORATION_CASING.get())
                            .or(Predicates.abilities(PartAbility.EXPORT_FLUIDS_1X).setMinLayerLimited(1)
                                    .setMaxLayerLimited(1)))
                    .where('Z', blocks(GTOBlocks.STAINLESS_EVAPORATION_CASING.get()))
                    .where('F', Predicates.frames(Aluminium))
                    .where('#', Predicates.air())
                    .where(' ', Predicates.any())
                    .build())
            .partSorter(Comparator.comparingInt(a -> a.self().getPos().getY()))
            .workableCasingRenderer(GTOCore.id("block/casings/stainless_evaporation_casing"), GTCEu.id("block/multiblock/evaporation_plant"))
            .register();

    public static final MultiblockMachineDefinition PLASMA_CONDENSER = multiblock("plasma_condenser", "等离子冷凝器", ElectricMultiblockMachine::new)
            .allRotation()
            .recipeTypes(GTORecipeTypes.PLASMA_CONDENSER_RECIPES)
            .perfectOCTooltips()
            .perfectOverclock()
            .block(GTOBlocks.ANTIFREEZE_HEATPROOF_MACHINE_CASING)
            .pattern(definition -> FactoryBlockPattern.start()
                    .aisle("       ", "       ", "  aaa  ", "  aaa  ", "  aaa  ", "       ", "       ")
                    .aisle("       ", "  aaa  ", " aaaaa ", " aabaa ", " aaaaa ", "  aaa  ", "       ")
                    .aisle("  aaa  ", " aaaaa ", "aabbbaa", "aabcbaa", "aabbbaa", " aaaaa ", "  aaa  ")
                    .aisle("  aaa  ", " aabaa ", "aabcbaa", "abcccba", "aabcbaa", " aabaa ", "  aaa  ")
                    .aisle("  aaa  ", " aaaaa ", "aabbbaa", "aabcbaa", "aabbbaa", " aaaaa ", "  aaa  ")
                    .aisle("       ", "  aaa  ", " aaaaa ", " aabaa ", " aaaaa ", "  aaa  ", "       ")
                    .aisle("       ", "       ", "  aaa  ", "  ada  ", "  aaa  ", "       ", "       ")
                    .where('a', blocks(GTOBlocks.ANTIFREEZE_HEATPROOF_MACHINE_CASING.get())
                            .setMinGlobalLimited(120)
                            .or(autoAbilities(definition.getRecipeTypes()))
                            .or(abilities(MAINTENANCE).setExactLimit(1)))
                    .where('b', blocks(GTOBlocks.AMPROSIUM_PIPE_CASING.get()))
                    .where('c', blocks(GTOBlocks.LASER_COOLING_CASING.get()))
                    .where('d', controller(blocks(definition.get())))
                    .where(' ', any())
                    .build())
            .workableCasingRenderer(GTOCore.id("block/casings/antifreeze_heatproof_machine_casing"), GTCEu.id("block/multiblock/vacuum_freezer"))
            .register();

    public static final MultiblockMachineDefinition RARE_EARTH_CENTRIFUGAL = multiblock("rare_earth_centrifugal", "稀土离心机", ElectricMultiblockMachine::new)
            .allRotation()
            .recipeTypes(GTORecipeTypes.RARE_EARTH_CENTRIFUGAL_RECIPES)
            .parallelizableTooltips()
            .parallelizableOverclock()
            .block(GTBlocks.CASING_HSSE_STURDY)
            .pattern(definition -> FactoryBlockPattern.start()
                    .aisle(" bbb ", "bbbbb", "bbbbb", "bbbbb", " bbb ")
                    .aisle("bbbbb", "bcccb", "bcccb", "bcccb", "bbbbb")
                    .aisle("bbbbb", "bcdcb", "bcdcb", "bcdcb", "bbbbb")
                    .aisle("bbbbb", "bcccb", "bcccb", "bcccb", "bbbbb")
                    .aisle(" bbb ", "bbbbb", "bbabb", "bbbbb", " bbb ")
                    .where('a', controller(blocks(definition.get())))
                    .where('b', blocks(GTBlocks.CASING_HSSE_STURDY.get())
                            .setMinGlobalLimited(80)
                            .or(abilities(PARALLEL_HATCH).setMaxGlobalLimited(1))
                            .or(autoAbilities(definition.getRecipeTypes()))
                            .or(abilities(MAINTENANCE).setExactLimit(1)))
                    .where('c', blocks(GTBlocks.CASING_TUNGSTENSTEEL_GEARBOX.get()))
                    .where('d', blocks(GTOBlocks.AMPROSIUM_PIPE_CASING.get()))
                    .where(' ', any())
                    .build())
            .workableCasingRenderer(GTCEu.id("block/casings/solid/machine_casing_sturdy_hsse"), GTCEu.id("block/multiblock/gcym/large_centrifuge"))
            .register();

    public static final MultiblockMachineDefinition ADVANCED_RARE_EARTH_CENTRIFUGAL = multiblock("advanced_rare_earth_centrifugal", "进阶稀土离心机", ElectricMultiblockMachine::new)
            .nonYAxisRotation()
            .recipeTypes(GTORecipeTypes.RARE_EARTH_CENTRIFUGAL_RECIPES)
            .parallelizableTooltips()
            .laserTooltips()
            .parallelizableOverclock()
            .block(GTOBlocks.SPS_CASING)
            .pattern(definition -> FactoryBlockPattern.start(RelativeDirection.FRONT, RelativeDirection.UP, RelativeDirection.RIGHT)
                    .aisle("                        ", "                        ", "                        ", "                        ", "                        ", "                        ", "                        ", "                        ", "                        ", "                        ", "                        ", "                        ", "                        ")
                    .aisle("   AAAAAAA              ", "     B                  ", "     B                  ", "   CCCCC                ", "     B                  ", "     B                  ", "   CCCCC                ", "     B                  ", "     B                  ", "                        ", "                        ", "                        ", "                        ")
                    .aisle("  AADDDDDAA             ", "                        ", "                        ", "  C     C               ", "                        ", "                        ", "  C     C               ", "                        ", "                        ", "                        ", "                        ", "                        ", "                        ")
                    .aisle(" AADDDDDDDA             ", "  B  D  B               ", "  B  E  B               ", " CB EEE BC              ", "  B EEE B               ", "  B EEE B               ", " CB EEE BC              ", "  B EEE B               ", "  B  E  B               ", "                        ", "                        ", "                        ", "                        ")
                    .aisle("AADDDDDDDDA             ", "     D                  ", "   EEEEE                ", "C  EEEEE  C             ", "   E F E                ", "   E F E                ", "C  E F E  C             ", "   EEEEE                ", "   EEEEE                ", "                        ", "                        ", "                        ", "                        ")
                    .aisle("ADDDDDDDDDAA            ", "    DDD                 ", "   EEEEE                ", "C EEGGGEE C             ", "  E H H E               ", "  E H H E               ", "C E H H E C             ", "  EEGGGEE               ", "   EEEEE                ", "    DDD                 ", "                        ", "                        ", "                        ")
                    .aisle("ADDDDDDDDDDAAA  AAAAA   ", "B DDDDDDD B             ", "B EEEEEE  B             ", "C EEGGGEE C             ", "B EF G FE B             ", "B EF G FE B             ", "C EF G FE C             ", "B EEGGGEE B             ", "B EEEGEEE B             ", "    D D                 ", "    IAI                 ", "                        ", "                        ")
                    .aisle("ADDDDDDDDDDDDAAAADDDAA  ", "    DDD          B      ", "   EEEEE         B      ", "C EEGGGEE C    CCCCC    ", "  E H H E        B      ", "  E H H E        B      ", "C E H H E C    CCCCC    ", "  EEGGGEE        B      ", "   EEEEE         B      ", "    DAD                 ", "    IAI                 ", "                        ", "                        ")
                    .aisle("ADDDDDDDDDDDDDADDDDDDA  ", "     D                  ", "   EEEEE                ", "C  EEEEE  C   C     C   ", "   E F E                ", "   E F E                ", "C  E F E  C   C     C   ", "   EEEEE                ", "   EEEEE                ", "                        ", "    IAI                 ", "    IAI                 ", "                        ")
                    .aisle("AAADDDDDDDDDDDDDDDDDDAb ", "  B  D  B     B  D  B   ", "  B  E  B     B  E  B   ", " CB EEE BC   CB EEE BC  ", "  B EEE B     B EEE B   ", "  B EEE B     B EEE B   ", " CB EEE BC   CB EEE BC  ", "  B EEE B     B EEE B   ", "  B  E  B     B  E  B   ", "                        ", "                        ", "    IAI                 ", "                        ")
                    .aisle("  AADDDDDDDDDDDDDDDDDDb ", "                 D      ", "               EEEEE    ", "  C     C   C  EEEEE  C ", "               E F E    ", "               E F E    ", "  C     C   C  E F E  C ", "               EEEEE    ", "               EEEEE    ", "                        ", "                        ", "    IAI                 ", "                        ")
                    .aisle("   ADDDDDDDDDDDDDDDDDDAb", "     B   A      DDD   Ab", "     B   A     EEEEE  Ab", "   CCCCC A  C EEGGGEE C ", "     B   A    E H H E   ", "     B   A    E H H E   ", "   CCCCC A  C E H H E C ", "     B   A    EEGGGEE   ", "     B   A     EEEEE    ", "         A      DDD     ", "         A     III      ", "    IAAAAAIIIIII        ", "     DDDDDDDD           ")
                    .aisle("   ADDDDDDDDDDDDDDDDDDAb", "        AAA B DDDDDDD B~", "        AAA B EEEEEE  Bb", "        AAA C EEGGGEE C ", "        AAA B EF G FE B ", "        AAA B EF G FE B ", "        AAA C EF G FE C ", "        AAA B EEGGGEE B ", "        AAA B EEEGEEE B ", "        AAA     AGD     ", "        AAA    AAA      ", "    IIIIAAAAAAAA        ", "     DDDDDDDD           ")
                    .aisle("   ADDDDDDDDDDDDDDDDDDAb", "     B   A      DDD   Ab", "     B   A     EEEEE  Ab", "   CCCCC A  C EEGGGEE C ", "     B   A    E H H E   ", "     B   A    E H H E   ", "   CCCCC A  C E H H E C ", "     B   A    EEGGGEE   ", "     B   A     EEEEE    ", "         A      DDD     ", "         A     III      ", "    IAAAAAIIIIII        ", "     DDDDDDDD           ")
                    .aisle("  AADDDDDDDDDDDDDDDDDDb ", "                 D      ", "               EEEEE    ", "  C     C   C  EEEEE  C ", "               E F E    ", "               E F E    ", "  C     C   C  E F E  C ", "               EEEEE    ", "               EEEEE    ", "                        ", "                        ", "    IAI                 ", "                        ")
                    .aisle("AAADDDDDDDDDDDDDDDDDDAb ", "  B  D  B     B  D  B   ", "  B  E  B     B  E  B   ", " CB EEE BC   CB EEE BC  ", "  B EEE B     B EEE B   ", "  B EEE B     B EEE B   ", " CB EEE BC   CB EEE BC  ", "  B EEE B     B EEE B   ", "  B  E  B     B  E  B   ", "                        ", "                        ", "    IAI                 ", "                        ")
                    .aisle("ADDDDDDDDDDDDDADDDDDDA  ", "     D                  ", "   EEEEE                ", "C  EEEEE  C   C     C   ", "   E F E                ", "   E F E                ", "C  E F E  C   C     C   ", "   EEEEE                ", "   EEEEE                ", "                        ", "    IAI                 ", "    IAI                 ", "                        ")
                    .aisle("ADDDDDDDDDDDDAAAADDDAA  ", "    DDD          B      ", "   EEEEE         B      ", "C EEGGGEE C    CCCCC    ", "  E H H E        B      ", "  E H H E        B      ", "C E H H E C    CCCCC    ", "  EEGGGEE        B      ", "   EEEEE         B      ", "    DAD                 ", "    IAI                 ", "                        ", "                        ")
                    .aisle("ADDDDDDDDDDAAA  AAAAA   ", "B DDDDDDD B             ", "B EEEEEE  B             ", "C EEGGGEE C             ", "B EF G FE B             ", "B EF G FE B             ", "C EF G FE C             ", "B EEGGGEE B             ", "B EEEGEEE B             ", "    D D                 ", "    IAI                 ", "                        ", "                        ")
                    .aisle("ADDDDDDDDDAA            ", "    DDD                 ", "   EEEEE                ", "C EEGGGEE C             ", "  E H H E               ", "  E H H E               ", "C E H H E C             ", "  EEGGGEE               ", "   EEEEE                ", "    DDD                 ", "                        ", "                        ", "                        ")
                    .aisle("AADDDDDDDDA             ", "     D                  ", "   EEEEE                ", "C  EEEEE  C             ", "   E F E                ", "   E F E                ", "C  E F E  C             ", "   EEEEE                ", "   EEEEE                ", "                        ", "                        ", "                        ", "                        ")
                    .aisle(" AADDDDDDDA             ", "  B  D  B               ", "  B  E  B               ", " CB EEE BC              ", "  B EEE B               ", "  B EEE B               ", " CB EEE BC              ", "  B EEE B               ", "  B  E  B               ", "                        ", "                        ", "                        ", "                        ")
                    .aisle("  AADDDDDAA             ", "                        ", "                        ", "  C     C               ", "                        ", "                        ", "  C     C               ", "                        ", "                        ", "                        ", "                        ", "                        ", "                        ")
                    .aisle("   AAAAAAA              ", "     B                  ", "     B                  ", "   CCCCC                ", "     B                  ", "     B                  ", "   CCCCC                ", "     B                  ", "     B                  ", "                        ", "                        ", "                        ", "                        ")
                    .where('~', controller(blocks(definition.get())))
                    .where('A', blocks(GTOBlocks.SPS_CASING.get()))
                    .where('B', blocks(GTOBlocks.DEGENERATE_RHENIUM_CONSTRAINED_CASING.get()))
                    .where('C', blocks(GTOBlocks.ADVANCED_FUSION_COIL.get()))
                    .where('D', blocks(GTOBlocks.HYPER_MECHANICAL_CASING.get()))
                    .where('E', blocks(GTBlocks.CASING_HSSE_STURDY.get()))
                    .where('F', blocks(GTOBlocks.HYPER_CORE.get()))
                    .where('G', blocks(GTOBlocks.AMPROSIUM_GEARBOX.get()))
                    .where('H', blocks(GTOBlocks.AMPROSIUM_PIPE_CASING.get()))
                    .where('I', blocks(ChemicalHelper.getBlock(TagPrefix.frameGt, GTMaterials.HastelloyX)))
                    .where('b', blocks(GTOBlocks.SPS_CASING.get())
                            .or(GTOPredicates.autoLaserAbilities(definition.getRecipeTypes()))
                            .or(abilities(PARALLEL_HATCH).setMaxGlobalLimited(1))
                            .or(abilities(MAINTENANCE).setExactLimit(1)))
                    .where(' ', any())
                    .build())
            .workableCasingRenderer(GTOCore.id("block/casings/sps_casing"), GTCEu.id("block/multiblock/gcym/large_centrifuge"))
            .register();

    public static final MultiblockMachineDefinition SPS_CRAFTING = multiblock("sps_crafting", "超临界合成机", ElectricMultiblockMachine::new)
            .allRotation()
            .recipeTypes(GTORecipeTypes.TRANSCENDING_CRAFTING_RECIPES)
            .perfectOCTooltips()
            .perfectOverclock()
            .block(GTBlocks.FUSION_CASING_MK2)
            .pattern(definition -> FactoryBlockPattern.start()
                    .aisle("bbbbbbb", "bcccccb", "bcfffcb", "bcfffcb", "bcfffcb", "bcccccb", "bbbbbbb")
                    .aisle("bcccccb", "c     c", "c     c", "c     c", "c     c", "c     c", "bcccccb")
                    .aisle("bcccccb", "c ddd c", "f ddd f", "f ddd f", "f ddd f", "c ddd c", "bcccccb")
                    .aisle("bcccccb", "c ded c", "f ded f", "f dgd f", "f ded f", "c ded c", "bcccccb")
                    .aisle("bcccccb", "c ddd c", "f ddd f", "f ddd f", "f ddd f", "c ddd c", "bcccccb")
                    .aisle("bcccccb", "c     c", "c     c", "c     c", "c     c", "c     c", "bcccccb")
                    .aisle("bbbbbbb", "bccaccb", "bcfffcb", "bcfffcb", "bcfffcb", "bcccccb", "bbbbbbb")
                    .where('a', controller(blocks(definition.get())))
                    .where('b', blocks(GTOBlocks.SPS_CASING.get()))
                    .where('c', blocks(GTBlocks.FUSION_CASING_MK2.get())
                            .setMinGlobalLimited(100)
                            .or(autoAbilities(definition.getRecipeTypes()))
                            .or(abilities(MAINTENANCE).setExactLimit(1)))
                    .where('d', blocks(Blocks.CRYING_OBSIDIAN))
                    .where('e', blocks(Blocks.REINFORCED_DEEPSLATE))
                    .where('f', blocks(GTBlocks.FUSION_GLASS.get()))
                    .where('g', blocks(GTOBlocks.MAGIC_CORE.get()))
                    .where(' ', air())
                    .build())
            .workableCasingRenderer(GTCEu.id("block/casings/fusion/fusion_casing_mk2"), GTCEu.id("block/multiblock/assembly_line"))
            .register();

    public static final MultiblockMachineDefinition ADVANCED_SPS_CRAFTING = multiblock("advanced_sps_crafting", "进阶超临界合成机", ElectricMultiblockMachine::new)
            .nonYAxisRotation()
            .recipeTypes(GTORecipeTypes.TRANSCENDING_CRAFTING_RECIPES)
            .parallelizableTooltips()
            .perfectOCTooltips()
            .laserTooltips()
            .parallelizablePerfectOverclock()
            .block(GTBlocks.FUSION_CASING_MK2)
            .pattern(definition -> FactoryBlockPattern.start(RelativeDirection.FRONT, RelativeDirection.UP, RelativeDirection.RIGHT)
                    .aisle("            AAAA AAAA           ", "            ABBA ABBA           ", "            ABBA ABBA           ", "                                ", "                                ", "                                ", "                                ", "                                ", "                                ", "                                ", "                                ", "                                ", "                                ", "                                ", "                                ", "                                ", "                                ")
                    .aisle("            AAAA AAAA           ", "            ABBA ABBA           ", "            ABBA ABBA           ", "            ABBA ABBA           ", "                                ", "                                ", "                                ", "                                ", "                                ", "                                ", "                                ", "                                ", "                                ", "                                ", "                                ", "                                ", "                                ")
                    .aisle("          CCCCCCCCCCCCC         ", "          DDDDDDDDDDDDD         ", "           CABBA ABBAC          ", "            ABBA ABBA           ", "            ABBA ABBA           ", "            CCCCCCCCC           ", "                                ", "                                ", "                                ", "                                ", "                                ", "                                ", "                                ", "                                ", "                                ", "                                ", "                                ")
                    .aisle("         CCCCCCCCCCCCCCC        ", "         DDEABBBBBBBAEDD        ", "          CEABBA ABBAEC         ", "           EABBA ABBAE          ", "           EABBA ABBAE          ", "            CBBCCCBBC           ", "                                ", "                                ", "                                ", "                                ", "                                ", "                                ", "                                ", "                                ", "                                ", "                                ", "                                ")
                    .aisle("        CCCCCCCCCCCCCCCCC       ", "        DDAAABBBBBBBAAADD       ", "         CAAABFBBBFBAAAC        ", "          AAABFBBBFBAAA         ", "           AABBBBBBBAA          ", "            CBBCCCBBC           ", "                                ", "                                ", "                                ", "                                ", "                                ", "                                ", "                                ", "                                ", "                                ", "                                ", "                                ")
                    .aisle("       CCCCCCCCCCCCCCCCCCC      ", "       DD AAABBBBBBBAAA DD      ", "        C AEFB  G  BFEA C       ", "          AGFB     BFGA         ", "          AAAB BBB BAAA         ", "             BBCCCBB            ", "                                ", "                                ", "                                ", "                                ", "                                ", "                                ", "                                ", "                                ", "                                ", "                                ", "                                ")
                    .aisle("       CCCCCCCCCCCCCCCCCCC      ", "       D  AAABBBBBBBAAA  D      ", "       C  AEFB  G  BFEA  C      ", "          AGFB     BFGA         ", "          AAABBBBBBBAAA         ", "               AAA              ", "                                ", "                                ", "                                ", "                                ", "                                ", "                                ", "                                ", "                                ", "                                ", "                                ", "                                ")
                    .aisle("      CCCCCCCCCCCCCCCCCCCCC     ", "      DD  AAABBBBBBBAAA  DD     ", "       C  AEFBBBGBBBFEA  C      ", "          AGFBBBBBBBFGA         ", "          AAA  AAA  AAA         ", "                                ", "                                ", "                                ", "                                ", "                                ", "                                ", "                                ", "                                ", "                                ", "                                ", "                                ", "                                ")
                    .aisle("      CCCCCCCCCCCCCCCCCCCCC     ", "      D   AAA  AAA  AAA   D     ", "      C   AAA  AGA  AAA   C     ", "          AGA  AAA  AGA         ", "           AA       AA          ", "                                ", "                                ", "                                ", "                                ", "                                ", "                                ", "                                ", "                                ", "                                ", "                                ", "                                ", "                                ")
                    .aisle("     CCCCCCCCCCCCCCCCCCCCCCC    ", "     DD                   DD    ", "      C         G         C     ", "           G    G    G          ", "                G               ", "                                ", "                                ", "                                ", "                                ", "                                ", "                                ", "                                ", "                                ", "                                ", "                                ", "                                ", "                                ")
                    .aisle("     CCCCCCCCCCCCCCCCCCCCCCC    ", "     D AAA             AAA D    ", "     C AAA             AAA C    ", "       HHH G         G HHH      ", "       HHH      G      HHH      ", "       AAA             AAA      ", "                                ", "                                ", "                                ", "                                ", "                                ", "                                ", "                                ", "                                ", "                                ", "                                ", "                                ")
                    .aisle("    CCCCCCCCCCCCCCCCCCCCCCCCC   ", "    DDAAAAA           AAAAADD   ", "     CAFEFIIIIIIIIIIIIIFEFAC    ", "      HF FHG         GHF FH     ", "      HFEFH     G     HFEFH     ", "      AAAAA           AAAAA     ", "                                ", "                                ", "                                ", "                                ", "                                ", "                                ", "                                ", "                                ", "                                ", "                                ", "                                ")
                    .aisle("    CCCCCCCCCCCCCCCCCCCCCCCCC   ", "    D AAAAA           AAAAA D   ", "    C AEEEA  I     I  AEEEA C   ", "      H J HG         GH J H     ", "      HEEEH     G     HEEEH     ", "      AAEAA           AAEAA     ", "                                ", "                                ", "                                ", "                                ", "                                ", "                                ", "                                ", "                                ", "                                ", "                                ", "                                ")
                    .aisle("    CCCCCCCCCCCCCCCCCCCCCCCCC   ", "    D AAAAA    C C    AAAAA D   ", "    C AFEFIIII C C IIIIFEFA C   ", "      HF FHG   C C   GHF FH     ", "      HFEFH    CGC    HFEFH     ", "      AAAAA    C C    AAAAA     ", "               C C              ", "                                ", "                                ", "                                ", "                                ", "                                ", "                                ", "                                ", "                                ", "                                ", "                                ")
                    .aisle("   CCCCCCCCCCCCCCCCCCCCCCCCCCC  ", "   DD  AAA   KKKEKKK   AAA  DD  ", "    C  AAA   BBBBBBB   AAA  C   ", "       HHH G BHBBBHB G HHH      ", "       HHH   BHBGBHB   HHH      ", "       AAA   BBBBBBB   AAA      ", "             KKKKKKK            ", "               CBC              ", "                B               ", "                                ", "                                ", "                                ", "                                ", "                                ", "                                ", "                                ", "                                ")
                    .aisle("   CCCCCCCCCCCCCCCCCCCCCCCCCCC  ", "   D        KAAAEAAAK        D  ", "   C        BB     BB        C  ", "           GBB     BBG          ", "            BB     BB           ", "            BB     BB           ", "            KK  E  KK           ", "             BBBBBBB            ", "              BBBBB             ", "              HHBHH             ", "              HHBHH             ", "              HHBHH             ", "              HHBHH             ", "              BBBBB             ", "                E               ", "                                ", "                                ")
                    .aisle("   CCCCCCCCCCCCCCCCCCCCCCCCCCC  ", "   D       KAAAAEAAAAK       D  ", "   C       BB       BB       C  ", "           GB       BG          ", "           BB       BB          ", "           BB       BB          ", "           KK   E   KK          ", "            BB     BB           ", "             BB   BB            ", "             HH   HH            ", "             HH   HH            ", "             HH   HH            ", "             HH   HH            ", "             BB B BB            ", "              BBBBB             ", "                E               ", "                                ")
                    .aisle("  CCCCCCCCCCCCCCCCCCCCCCCCCCCCC ", "  DD      KAAAAAEAAAAAK      DD ", "   C      BB         BB      C  ", "          BG         GB         ", "          BB         BB         ", "          BB         BB         ", "          KK    E    KK         ", "           BB       BB          ", "            BB     BB           ", "            HH LLL HH           ", "            HH  L  HH           ", "            HH  L  HH           ", "            HH LLL HH           ", "            BB     BB           ", "             BBBBBBB            ", "              AAEAA             ", "                                ")
                    .aisle(" ACCCCCCCCCCCCCCCCCCCCCCCCCCCCCA", " ADAAAACC KAAAAAEAAAAAK CCAAAADA", " AAAAAAAAAB   F   F   BAAAAAAAAA", "       AAAB   FFFFF   BAAA      ", "        AAB   F   F   BAA       ", "        AAB   FFFFF   BAA       ", "         AK   F E F   KA        ", "         AAB  FFFFF  BAA        ", "           BB       BB          ", "           HH L L L HH          ", "           HH       HH          ", "           HH       HH          ", "           HH L L L HH          ", "           BB       BB          ", "            BB     BB           ", "             AAAKAAA            ", "                                ")
                    .aisle("  MCCCCCCCCCCCCCCCCCCCCCCCCCCCMA", "  MMMMMMM KAAAAAEAAAAAK MMMMMMMA", " ACCCCCCC B           B CCCCCCCA", "   AAAANN B   F   F   B NNAAAA  ", "       NN B           B NN      ", "        N B   F   F   B N       ", "        NAK     E     KAN       ", "        NAAB  F   F  BAAN       ", "         AAB         BAA        ", "           H L  L  L H          ", "           H         H          ", "           H         H          ", "           H L  L  L H          ", "           B         B          ", "            BB     BB           ", "             AAEKEAA            ", "               AAA              ")
                    .aisle("  MCCCCCCCCCCCCCCCCCCCCCCCCCCCMA", "  MMMMMMM EEEEEEJEEEEEE MMMMMMM~", " ACCCCCCC B     J     B CCCCCCCA", "  AAEEENN B   F J F   B NNEEEAA ", "       NN B     J     B NN      ", "       NN B   F J F   B NN      ", "       NNAEEEEEEJEEEEEEANN      ", "        NABB  F J F  BBAN       ", "        NABB    J    BBAN       ", "           B LLLJLLL B          ", "           B L  J  L B          ", "           B L  J  L B          ", "           B LLLJLLL B          ", "           BB   J   BB          ", "           EBB  K  BBE          ", "            EEKKKKKEE           ", "               AAA              ")
                    .aisle("  MCCCCCCCCCCCCCCCCCCCCCCCCCCCMA", "  MMMMMMM KAAAAAEAAAAAK MMMMMMMA", " ACCCCCCC B           B CCCCCCCA", "   AAAANN B   F   F   B NNAAAA  ", "       NN B           B NN      ", "        N B   F   F   B N       ", "        NAK     E     KAN       ", "        NAAB  F   F  BAAN       ", "         AAB         BAA        ", "           H L  L  L H          ", "           H         H          ", "           H         H          ", "           H L  L  L H          ", "           B         B          ", "            BB     BB           ", "             AAEKEAA            ", "               AAA              ")
                    .aisle(" ACCCCCCCCCCCCCCCCCCCCCCCCCCCCCA", " ADAAAACC KAAAAAEAAAAAK CCAAAADA", " AAAAAAAAAB   F   F   BAAAAAAAAA", "       AAAB   FFFFF   BAAA      ", "        AAB   F   F   BAA       ", "        AAB   FFFFF   BAA       ", "         AK   F E F   KA        ", "         AAB  FFFFF  BAA        ", "           BB       BB          ", "           HH L L L HH          ", "           HH       HH          ", "           HH       HH          ", "           HH L L L HH          ", "           BB       BB          ", "            BB     BB           ", "             AAAKAAA            ", "                                ")
                    .aisle("  CCCCCCCCCCCCCCCCCCCCCCCCCCCCC ", "  DD      KAAAAAEAAAAAK      DD ", "   C      BB         BB      C  ", "          BG         GB         ", "          BB         BB         ", "          BB         BB         ", "          KK    E    KK         ", "           BB       BB          ", "            BB     BB           ", "            HH LLL HH           ", "            HH  L  HH           ", "            HH  L  HH           ", "            HH LLL HH           ", "            BB     BB           ", "             BBBBBBB            ", "              AAEAA             ", "                                ")
                    .aisle("   CCCCCCCCCCCCCCCCCCCCCCCCCCC  ", "   D       KAAAAEAAAAK       D  ", "   C       BB       BB       C  ", "           GB       BG          ", "           BB       BB          ", "           BB       BB          ", "           KK   E   KK          ", "            BB     BB           ", "             BB   BB            ", "             HH   HH            ", "             HH   HH            ", "             HH   HH            ", "             HH   HH            ", "             BB B BB            ", "              BBBBB             ", "                E               ", "                                ")
                    .aisle("   CCCCCCCCCCCCCCCCCCCCCCCCCCC  ", "   D        KAAAEAAAK        D  ", "   C        BB     BB        C  ", "           GBB     BBG          ", "            BB     BB           ", "            BB     BB           ", "            KK  E  KK           ", "             BBBBBBB            ", "              BBBBB             ", "              HHBHH             ", "              HHBHH             ", "              HHBHH             ", "              HHBHH             ", "              BBBBB             ", "                E               ", "                                ", "                                ")
                    .aisle("   CCCCCCCCCCCCCCCCCCCCCCCCCCC  ", "   DD  AAA   KKKEKKK   AAA  DD  ", "    C  AAA   BBBBBBB   AAA  C   ", "       HHH G BHBBBHB G HHH      ", "       HHH   BHBBBHB   HHH      ", "       AAA   BBBBBBB   AAA      ", "             KKKKKKK            ", "               CBC              ", "                B               ", "                                ", "                                ", "                                ", "                                ", "                                ", "                                ", "                                ", "                                ")
                    .aisle("    CCCCCCCCCCCCCCCCCCCCCCCCC   ", "    D AAAAA    C C    AAAAA D   ", "    C AFEFIIII C C IIIIFEFA C   ", "      HF FHG   C C   GHF FH     ", "      HFEFH    CGC    HFEFH     ", "      AAAAA    C C    AAAAA     ", "               C C              ", "                                ", "                                ", "                                ", "                                ", "                                ", "                                ", "                                ", "                                ", "                                ", "                                ")
                    .aisle("    CCCCCCCCCCCCCCCCCCCCCCCCC   ", "    D AAAAA           AAAAA D   ", "    C AEEEA  I     I  AEEEA C   ", "      H J HG         GH J H     ", "      HEEEH     G     HEEEH     ", "      AAEAA           AAEAA     ", "                                ", "                                ", "                                ", "                                ", "                                ", "                                ", "                                ", "                                ", "                                ", "                                ", "                                ")
                    .aisle("    CCCCCCCCCCCCCCCCCCCCCCCCC   ", "    DDAAAAA           AAAAADD   ", "     CAFEFAIIIIIIIIIIIIFEFAC    ", "      HF FHG         GHF FH     ", "      HFEFH     G     HFEFH     ", "      AAAAA           AAAAA     ", "                                ", "                                ", "                                ", "                                ", "                                ", "                                ", "                                ", "                                ", "                                ", "                                ", "                                ")
                    .aisle("     CCCCCCCCCCCCCCCCCCCCCCC    ", "     D AAA             AAA D    ", "     C AAA             AAA C    ", "       HHH G         G HHH      ", "       HHH      G      HHH      ", "       AAA             AAA      ", "                                ", "                                ", "                                ", "                                ", "                                ", "                                ", "                                ", "                                ", "                                ", "                                ", "                                ")
                    .aisle("     CCCCCCCCCCCCCCCCCCCCCCC    ", "     DD                   DD    ", "      C         G         C     ", "           G    G    G          ", "                G               ", "                                ", "                                ", "                                ", "                                ", "                                ", "                                ", "                                ", "                                ", "                                ", "                                ", "                                ", "                                ")
                    .aisle("      CCCCCCCCCCCCCCCCCCCCC     ", "      D   AAA  AAA  AAA   D     ", "      C   AAA  AGA  AAA   C     ", "          AGA  AAA  AGA         ", "           AA       AA          ", "                                ", "                                ", "                                ", "                                ", "                                ", "                                ", "                                ", "                                ", "                                ", "                                ", "                                ", "                                ")
                    .aisle("      CCCCCCCCCCCCCCCCCCCCC     ", "      DD  AAABBBBBBBAAA  DD     ", "       C  AEFBBBGBBBFEA  C      ", "          AGFBBBBBBBFGA         ", "          AAA  AAA  AAA         ", "                                ", "                                ", "                                ", "                                ", "                                ", "                                ", "                                ", "                                ", "                                ", "                                ", "                                ", "                                ")
                    .aisle("       CCCCCCCCCCCCCCCCCCC      ", "       D  AAABBBBBBBAAA  D      ", "       C  AEFB  G  BFEA  C      ", "          AGFB     BFGA         ", "          AAABBBBBBBAAA         ", "               AAA              ", "                                ", "                                ", "                                ", "                                ", "                                ", "                                ", "                                ", "                                ", "                                ", "                                ", "                                ")
                    .aisle("       CCCCCCCCCCCCCCCCCCC      ", "       DD AAABBBBBBBAAA DD      ", "        C AEFB  G  BFEA C       ", "          AGFB     BFGA         ", "          AAAB BBB BAAA         ", "             BBCCCBB            ", "                                ", "                                ", "                                ", "                                ", "                                ", "                                ", "                                ", "                                ", "                                ", "                                ", "                                ")
                    .aisle("        CCCCCCCCCCCCCCCCC       ", "        DDAAABBBBBBBAAADD       ", "         CAAABFBBBFBAAAC        ", "          AAABFBBBFBAAA         ", "           AABBBBBBBAA          ", "            CBBCCCBBC           ", "                                ", "                                ", "                                ", "                                ", "                                ", "                                ", "                                ", "                                ", "                                ", "                                ", "                                ")
                    .aisle("         CCCCCCCCCCCCCCC        ", "         DDEABBBBBBBAEDD        ", "          CEABBA ABBAEC         ", "           EABBA ABBAE          ", "           EABBA ABBAE          ", "            CBBCCCBBC           ", "                                ", "                                ", "                                ", "                                ", "                                ", "                                ", "                                ", "                                ", "                                ", "                                ", "                                ")
                    .aisle("          CCCCCCCCCCCCC         ", "          DDDDDDDDDDDDD         ", "           CABBA ABBAC          ", "            ABBA ABBA           ", "            ABBA ABBA           ", "            CCCCCCCCC           ", "                                ", "                                ", "                                ", "                                ", "                                ", "                                ", "                                ", "                                ", "                                ", "                                ", "                                ")
                    .aisle("            AAAA AAAA           ", "            ABBA ABBA           ", "            ABBA ABBA           ", "            ABBA ABBA           ", "                                ", "                                ", "                                ", "                                ", "                                ", "                                ", "                                ", "                                ", "                                ", "                                ", "                                ", "                                ", "                                ")
                    .aisle("            AAAA AAAA           ", "            ABBA ABBA           ", "            ABBA ABBA           ", "                                ", "                                ", "                                ", "                                ", "                                ", "                                ", "                                ", "                                ", "                                ", "                                ", "                                ", "                                ", "                                ", "                                ")
                    .where('~', controller(blocks(definition.get())))
                    .where('A', blocks(GTOBlocks.SPS_CASING.get())
                            .setMinGlobalLimited(800)
                            .or(GTOPredicates.autoLaserAbilities(definition.getRecipeTypes()))
                            .or(abilities(PARALLEL_HATCH).setMaxGlobalLimited(1))
                            .or(abilities(MAINTENANCE).setExactLimit(1)))
                    .where('B', blocks(GTOBlocks.FUSION_CASING_MK4.get()))
                    .where('C', blocks(GTOBlocks.HYPER_MECHANICAL_CASING.get()))
                    .where('D', blocks(GTOBlocks.IRIDIUM_CASING.get()))
                    .where('E', blocks(GTOBlocks.AMPROSIUM_ACTIVE_CASING.get()))
                    .where('F', blocks(Blocks.CRYING_OBSIDIAN))
                    .where('G', blocks(GTOBlocks.ACCELERATED_PIPELINE.get()))
                    .where('H', blocks(GTBlocks.FUSION_GLASS.get()))
                    .where('I', blocks(GCYMBlocks.MOLYBDENUM_DISILICIDE_COIL_BLOCK.get()))
                    .where('J', blocks(GTOBlocks.MAGIC_CORE.get()))
                    .where('K', blocks(GTOBlocks.AMPROSIUM_CASING.get()))
                    .where('L', blocks(GTOBlocks.FUSION_COIL_MK2.get()))
                    .where('M', blocks(GTOBlocks.AMPROSIUM_PIPE_CASING.get()))
                    .where('N', blocks(GTOBlocks.HIGH_PRESSURE_RESISTANT_CASING.get()))
                    .where(' ', any())
                    .build())
            .workableCasingRenderer(GTCEu.id("block/casings/fusion/fusion_casing_mk2"), GTCEu.id("block/multiblock/assembly_line"))
            .register();

    public static final MultiblockMachineDefinition MATTER_FABRICATOR = multiblock("matter_fabricator", "物质生成机", ElectricMultiblockMachine::new)
            .allRotation()
            .recipeTypes(GTORecipeTypes.MATTER_FABRICATOR_RECIPES)
            .parallelizableTooltips()
            .laserTooltips()
            .parallelizableOverclock()
            .block(GTBlocks.HIGH_POWER_CASING)
            .pattern(definition -> FactoryBlockPattern.start()
                    .aisle(" CCCCDDDDDCCCC ", "EFFFFDGGGDFFFFE", "EFFFFDHHHDFFFFE", "EFFFFDGGGDFFFFE", " CCCCDDDDDCCCC ")
                    .aisle("EFFFFDGGGDFFFFE", "F I IIIIIII I F", "F I I     I I F", "F I IIIIIII I F", "EFFFFDGGGDFFFFE")
                    .aisle("EFFFFDHHHDFFFFE", "F I I     I I F", "FJJJJJJJJJJJJJF", "F I I     I I F", "EFFFFDHHHDFFFFE")
                    .aisle("EFFFFDGGGDFFFFE", "F I IIIIIII I F", "F I I     I I F", "F I IIIIIII I F", "EFFFFDGGGDFFFFE")
                    .aisle(" CCCCDDDDDCCCC ", "EFFFFDGGGDFFFFE", "EFFFFDHHHDFFFFE", "EFFFFDGGGDFFFFE", " CCCCDDDDDCCCC ")
                    .aisle("               ", "   AAA   AAA   ", "   ABA   AAA   ", "   AAA   AAA   ", "               ")
                    .where('B', controller(blocks(definition.get())))
                    .where('C', blocks(ChemicalHelper.getBlock(TagPrefix.frameGt, GTMaterials.Naquadria)))
                    .where('D', blocks(GTBlocks.MACHINE_CASING_UHV.get()))
                    .where('E', blocks(GTOBlocks.NAQUADAH_ALLOY_CASING.get()))
                    .where('F', blocks(GTBlocks.HIGH_POWER_CASING.get()))
                    .where('G', blocks(GTBlocks.FILTER_CASING.get()))
                    .where('H', blocks(GCYMBlocks.ELECTROLYTIC_CELL.get()))
                    .where('I', blocks(GTBlocks.SUPERCONDUCTING_COIL.get()))
                    .where('J', blocks(GTOBlocks.AMPROSIUM_PIPE_CASING.get()))
                    .where('A', blocks(GTBlocks.HIGH_POWER_CASING.get())
                            .or(GTOPredicates.autoLaserAbilities(definition.getRecipeTypes()))
                            .or(abilities(PARALLEL_HATCH).setMaxGlobalLimited(1))
                            .or(abilities(MAINTENANCE).setExactLimit(1)))
                    .where(' ', any())
                    .build())
            .workableCasingRenderer(GTCEu.id("block/casings/hpca/high_power_casing"), GTCEu.id("block/multiblock/fusion_reactor"))
            .register();

    public static final MultiblockMachineDefinition VOID_FLUID_DRILLING_RIG = multiblock("void_fluid_drilling_rig", "虚空流体钻机", VoidFluidDrillingRigMachine::new)
            .nonYAxisRotation()
            .tooltipsText("需要最低30720EU/t的功率", "Requires a minimum power of 30,720EU/t")
            .tooltipsText("按维度和电路值输出流体", "Outputs fluids based on the dimension and circuit value")
            .recipeTypes(GTORecipeTypes.DUMMY_RECIPES)
            .alwaysTryModifyRecipe(true)
            .block(GTBlocks.CASING_HSSE_STURDY)
            .pattern(definition -> FactoryBlockPattern.start(RelativeDirection.BACK, RelativeDirection.UP, RelativeDirection.LEFT)
                    .aisle("ABBBBA ", "AAAAAA ", " C C   ", " C C   ", " C C   ", " C C   ", "       ", "       ")
                    .aisle("B   BBB", "A   DDD", "    DDD", "    DDD", " C CDDD", " EEE   ", "       ", "       ")
                    .aisle("B FGBBB", "H IGDDD", "  IGD D", "  IGD D", "  IGD D", " EIEDDD", "  I    ", "  I    ")
                    .aisle("B   BBB", "A   DDD", "    DDD", "    DDD", " C CDDD", " EEE   ", "       ", "       ")
                    .aisle("ABBBBA ", "AAAAAA ", " C C   ", " C C   ", " C C   ", " C C   ", "       ", "       ")
                    .where('B', blocks(GTOBlocks.COBALT_OXIDE_CERAMIC_STRONG_THERMALLY_CONDUCTIVE_MECHANICAL_BLOCK.get()))
                    .where('C', blocks(GTBlocks.CASING_HSSE_STURDY.get()))
                    .where('D', blocks(GTBlocks.CASING_STAINLESS_CLEAN.get()))
                    .where('E', blocks(ChemicalHelper.getBlock(TagPrefix.frameGt, GTMaterials.HSSG)))
                    .where('F', blocks(GTBlocks.CASING_TUNGSTENSTEEL_GEARBOX.get()))
                    .where('G', blocks(GTBlocks.CASING_TUNGSTENSTEEL_PIPE.get()))
                    .where('H', controller(blocks(definition.get())))
                    .where('I', blocks(GTBlocks.CASING_TUNGSTENSTEEL_ROBUST.get()))
                    .where('A', blocks(GTBlocks.CASING_HSSE_STURDY.get())
                            .or(abilities(INPUT_ENERGY).setMaxGlobalLimited(2).setMinGlobalLimited(1))
                            .or(abilities(GTOPartAbility.ITEMS_INPUT).setExactLimit(1))
                            .or(abilities(EXPORT_FLUIDS).setExactLimit(1))
                            .or(abilities(MAINTENANCE).setExactLimit(1)))
                    .where(' ', any())
                    .build())
            .workableCasingRenderer(GTCEu.id("block/casings/solid/machine_casing_sturdy_hsse"), GTCEu.id("block/multiblock/fluid_drilling_rig"))
            .register();

    public static final MultiblockMachineDefinition VOID_MINER = multiblock("void_miner", "虚空采矿机", VoidMinerMachine::new)
            .nonYAxisRotation()
            .tooltipsText("需要输入1B钻井液和最低1920EU/t的功率", "Requires 1B drilling fluid and a minimum power of 1920EU/t")
            .tooltipsText("按维度随机选取4分矿石输出，电压等级决定最大输出数量，电流决定并行数", "Randomly selects 4 types of ores output based on the dimension, with the voltage level determining the maximum output quantity and the current determining the parallels")
            .recipeTypes(GTORecipeTypes.DUMMY_RECIPES)
            .alwaysTryModifyRecipe(true)
            .block(GTBlocks.CASING_TUNGSTENSTEEL_ROBUST)
            .pattern(definition -> FactoryBlockPattern.start(RelativeDirection.FRONT, RelativeDirection.UP, RelativeDirection.RIGHT)
                    .aisle(" AAAAA ", " BBBBB ", "  C C  ", "  C C  ", "  CCC  ", "       ")
                    .aisle("AAA AAA", "BCD DCB", "B DED B", "B D D B", " CD DC ", "  C C  ")
                    .aisle("AA   AA", "B  F  B", "  FEF  ", "   F   ", "       ", "  C C  ")
                    .aisle("AA   AA", "B     G", "   E   ", "       ", "       ", "  C C  ")
                    .aisle("AA   AA", "B  F  B", "  FEF  ", "   F   ", "       ", "  C C  ")
                    .aisle("AAA AAA", "BCD DCB", "B DED B", "B D D B", " CD DC ", "  C C  ")
                    .aisle(" AAAAA ", " BBBBB ", "  C C  ", "  C C  ", "  CCC  ", "       ")
                    .where('A', blocks(GTOBlocks.TITANIUM_NITRIDE_CERAMIC_IMPACT_RESISTANT_MECHANICAL_BLOCK.get()))
                    .where('C', blocks(GTBlocks.CASING_TUNGSTENSTEEL_ROBUST.get()))
                    .where('D', blocks(ChemicalHelper.getBlock(TagPrefix.frameGt, GTMaterials.StainlessSteel)))
                    .where('E', blocks(GTBlocks.MACHINE_CASING_HV.get()))
                    .where('F', blocks(GTBlocks.CASING_STAINLESS_STEEL_GEARBOX.get()))
                    .where('G', controller(blocks(definition.get())))
                    .where('B', blocks(GTBlocks.CASING_TUNGSTENSTEEL_ROBUST.get())
                            .or(abilities(INPUT_ENERGY).setMaxGlobalLimited(2).setMinGlobalLimited(1))
                            .or(abilities(IMPORT_FLUIDS).setExactLimit(1))
                            .or(abilities(EXPORT_ITEMS).setExactLimit(1))
                            .or(abilities(MAINTENANCE).setExactLimit(1)))
                    .where(' ', any())
                    .build())
            .workableCasingRenderer(GTCEu.id("block/casings/solid/machine_casing_robust_tungstensteel"), GTCEu.id("block/multiblock/large_miner"))
            .register();

    public static final MultiblockMachineDefinition LARGE_VOID_MINER = multiblock("large_void_miner", "大型虚空采矿厂", ElectricMultiblockMachine::new)
            .nonYAxisRotation()
            .recipeTypes(GTORecipeTypes.LARGE_VOID_MINER_RECIPES)
            .recipeTypes(GTORecipeTypes.RANDOM_ORE_RECIPES)
            .tooltips(NewDataAttributes.EMPTY_WITH_BAR.create(
                    h -> h.addLines("工作模式", "Operating Modes", StyleBuilder::setGold),
                    c -> c.addLines(
                            NewDataAttributes.EMPTY_WITH_POINT.createBuilder(
                                    x -> x.addLines("精准模式:", "Precision Mode:", StyleBuilder::setBold),
                                    p -> p,
                                    StyleBuilder::setOneTab),
                            NewDataAttributes.EMPTY_WITH_POINT.createBuilder(
                                    x -> x.addLines("消耗精华采集指定矿脉", "Consumes resources to collect specified veins", StyleBuilder::setAqua),
                                    p -> p,
                                    StyleBuilder::setTwoTabs),
                            NewDataAttributes.EMPTY_WITH_POINT.createBuilder(
                                    x -> x.addLines("随机模式:", "Random Mode:", StyleBuilder::setBold),
                                    p -> p,
                                    StyleBuilder::setOneTab),
                            NewDataAttributes.EMPTY_WITH_POINT.createBuilder(
                                    x -> x.addLines("消耗10KB的钻井液", "Consumes 10KB of drilling fluid", StyleBuilder::setAqua),
                                    p -> p,
                                    StyleBuilder::setTwoTabs),
                            NewDataAttributes.EMPTY_WITH_POINT.createBuilder(
                                    x -> x.addLines("耗时更长随机采集所有矿石", "Longer duration to randomly collect all ores", StyleBuilder::setAqua),
                                    p -> p,
                                    StyleBuilder::setTwoTabs),
                            NewDataAttributes.EMPTY_WITH_POINT.createBuilder(
                                    x -> x.addLines("注意: 确保输出空间足够", "Note: Ensure enough output space", StyleBuilder::setRed),
                                    p -> p,
                                    StyleBuilder::setTwoTabs))))
            .recipeModifier((machine, recipe) -> {
                if (((ElectricMultiblockMachine) machine).getRecipeType() == GTORecipeTypes.RANDOM_ORE_RECIPES) {
                    return RecipeModifierFunction.overclocking(machine, ParallelLogic.accurateParallel(machine, recipe, 1 << ((((ElectricMultiblockMachine) machine).getTier() - GTValues.ZPM) << 1)));
                }
                return RecipeModifierFunction.overclocking(machine, recipe);
            })
            .block(GTBlocks.CASING_TUNGSTENSTEEL_ROBUST)
            .pattern(definition -> FactoryBlockPattern.start()
                    .aisle("bbbbbbbbb", "bbbbbbbbb", "b       b", "b       b", "b       b", "bbbbbbbbb", "bcccccccb", "bcccccccb", "b       b", "b       b")
                    .aisle("b       b", "b       b", "         ", "         ", "         ", "b   d   b", "c  ddd  c", "c  ddd  c", "   ddd   ", "         ")
                    .aisle("b       b", "b       b", "         ", "    d    ", "   ddd   ", "b  ddd  b", "c dd dd c", "c d   d c", "  d   d  ", "         ")
                    .aisle("b   d   b", "b   d   b", "   ddd   ", "   d d   ", "  dd dd  ", "b d   d b", "cdd   ddc", "cd     dc", " d     d ", "         ")
                    .aisle("b  d d  b", "b  d d  b", "   d d   ", "  d   d  ", "  d   d  ", "bdd   ddb", "cd     dc", "cd     dc", " d     d ", "         ")
                    .aisle("b   d   b", "b   d   b", "   ddd   ", "   d d   ", "  dd dd  ", "b d   d b", "cdd   ddc", "cd     dc", " d     d ", "         ")
                    .aisle("b       b", "b       b", "         ", "    d    ", "   ddd   ", "b  ddd  b", "c dd dd c", "c d   d c", "  d   d  ", "         ")
                    .aisle("b       b", "b       b", "         ", "         ", "         ", "b   d   b", "c  ddd  c", "c  ddd  c", "   ddd   ", "         ")
                    .aisle("bbbbbbbbb", "bbbbabbbb", "b       b", "b       b", "b       b", "bbbbbbbbb", "bcccccccb", "bcccccccb", "b       b", "b       b")
                    .where('a', controller(blocks(definition.get())))
                    .where('b', blocks(GTBlocks.CASING_TUNGSTENSTEEL_ROBUST.get())
                            .setMinGlobalLimited(110)
                            .or(autoAbilities(definition.getRecipeTypes()))
                            .or(abilities(MAINTENANCE).setExactLimit(1)))
                    .where('c', blocks(ChemicalHelper.getBlock(TagPrefix.frameGt, GTMaterials.Ultimet)))
                    .where('d', blocks(GTBlocks.CASING_TITANIUM_STABLE.get()))
                    .where(' ', any())
                    .build())
            .workableCasingRenderer(GTCEu.id("block/casings/solid/machine_casing_robust_tungstensteel"), GTCEu.id("block/multiblock/large_miner"))
            .register();

    public static final MultiblockMachineDefinition CHEMICAL_PLANT = multiblock("chemical_plant", "化工厂", CoilMultiblockMachine.createCoilMachine(false, false))
            .allRotation()
            .recipeTypes(GTORecipeTypes.CHEMICAL)
            .tooltips(NewDataAttributes.EMPTY_WITH_BAR.create(
                    h -> h.addLines("线圈效率加成", "Coil Efficiency Bonus", StyleBuilder::setGold),
                    c -> c.addLines(
                            NewDataAttributes.EMPTY_WITH_POINT.createBuilder(
                                    x -> x.addLines("线圈等级每高出白铜一级", "Each coil tier above Bronze", StyleBuilder::setWhite),
                                    p -> p,
                                    StyleBuilder::setOneTab),
                            NewDataAttributes.EMPTY_WITH_POINT.createBuilder(
                                    x -> x.addLines("能耗与时间减少5%", "Reduces energy consumption and duration by 5%", StyleBuilder::setGreen),
                                    p -> p,
                                    StyleBuilder::setOneTab))))
            .parallelizableTooltips()
            .perfectOCTooltips()
            .recipeModifier(RecipeModifierFunction.coilReductionOverclock(0.25))
            .block(GTBlocks.CASING_PTFE_INERT)
            .pattern(definition -> FactoryBlockPattern.start()
                    .aisle("b   b", "bbbbb", "b   b", "bbbbb", "b   b")
                    .aisle("bbbbb", "bcccb", "bdddb", "bcccb", "bbbbb")
                    .aisle("b   b", "bdddb", "bcccb", "bdddb", "b   b")
                    .aisle("bbbbb", "bcccb", "bdddb", "bcccb", "bbbbb")
                    .aisle("b   b", "abbbb", "b   b", "bbbbb", "b   b")
                    .where('a', controller(blocks(definition.get())))
                    .where('b', blocks(GTBlocks.CASING_PTFE_INERT.get())
                            .setMinGlobalLimited(60)
                            .or(abilities(GTOPartAbility.CATALYST_HATCH).setMaxGlobalLimited(1))
                            .or(abilities(PARALLEL_HATCH).setMaxGlobalLimited(1))
                            .or(GTOPredicates.autoAccelerateAbilities(definition.getRecipeTypes()))
                            .or(abilities(MAINTENANCE).setExactLimit(1)))
                    .where('c', heatingCoils())
                    .where('d', blocks(GTBlocks.CASING_POLYTETRAFLUOROETHYLENE_PIPE.get()))
                    .where(' ', any())
                    .build())
            .additionalDisplay(CHEMICAL_PLANT_DISPLAY)
            .workableCasingRenderer(GTCEu.id("block/casings/solid/machine_casing_inert_ptfe"), GTCEu.id("block/machines/chemical_reactor"))
            .register();

    public static final MultiblockMachineDefinition DECAY_HASTENER = multiblock("decay_hastener", "衰变加速器", ElectricMultiblockMachine::new)
            .allRotation()
            .recipeTypes(GTORecipeTypes.DECAY_HASTENER_RECIPES)
            .parallelizableTooltips()
            .parallelizableOverclock()
            .block(GTOBlocks.HYPER_MECHANICAL_CASING)
            .pattern(definition -> FactoryBlockPattern.start()
                    .aisle("AAAAA", "ABBBA", "ADDDA", "AEEEA", "AFFFA", "AEEEA", "ADDDA", "AEEEA", "AFFFA", "AEEEA", "ADDDA", "ABBBA", "AAAAA")
                    .aisle("A   A", "BEEEB", "DGGGD", "EGGGE", "FGGGF", "EGGGE", "DGGGD", "EGGGE", "FGGGF", "EGGGE", "DGGGD", "BEEEB", "A   A")
                    .aisle("A   A", "BEEEB", "DGHGD", "EGHGE", "FGHGF", "EGHGE", "DGHGD", "EGHGE", "FGHGF", "EGHGE", "DGHGD", "BEEEB", "A   A")
                    .aisle("A   A", "BEEEB", "DGGGD", "EGGGE", "FGGGF", "EGGGE", "DGGGD", "EGGGE", "FGGGF", "EGGGE", "DGGGD", "BEEEB", "A   A")
                    .aisle("AAAAA", "ABCBA", "ADDDA", "AEEEA", "AFFFA", "AEEEA", "ADDDA", "AEEEA", "AFFFA", "AEEEA", "ADDDA", "ABBBA", "AAAAA")
                    .where('A', blocks(GTOBlocks.FISSION_REACTOR_CASING.get()))
                    .where('C', controller(blocks(definition.get())))
                    .where('D', blocks(GTBlocks.SUPERCONDUCTING_COIL.get()))
                    .where('E', blocks(GTOBlocks.HYPER_MECHANICAL_CASING.get()))
                    .where('F', blocks(ChemicalHelper.getBlock(TagPrefix.frameGt, GTMaterials.BlackSteel)))
                    .where('G', blocks(GTBlocks.FUSION_CASING.get()))
                    .where('H', blocks(GTBlocks.HERMETIC_CASING_UV.get()))
                    .where('B', blocks(GTOBlocks.HYPER_MECHANICAL_CASING.get())
                            .or(abilities(PARALLEL_HATCH).setMaxGlobalLimited(1))
                            .or(autoAbilities(definition.getRecipeTypes()))
                            .or(abilities(MAINTENANCE).setExactLimit(1)))
                    .where(' ', any())
                    .build())
            .workableCasingRenderer(GTOCore.id("block/casings/hyper_mechanical_casing"), GTCEu.id("block/multiblock/data_bank"))
            .register();

    public static final MultiblockMachineDefinition RECYCLER = multiblock("recycler", "回收机", CustomParallelMultiblockMachine.createParallel(m -> 1L << Math.max(0, (2 * (m.getTier() - 4))), true))
            .allRotation()
            .recipeTypes(GTORecipeTypes.RECYCLER_RECIPES)
            .specialParallelizableTooltips()
            .tooltips(NewDataAttributes.ALLOW_PARALLEL_NUMBER.create(
                    h -> h.addLines("自EV起，每升一级电压，获得的并行x4", "From EV, every voltage tier increase grants x4 parallelism"),
                    c -> c.addCommentLines("公式 : 2^(max(0, (2 * (tier - 4)))), 算去吧", "Formula: 2^(max(0, (2 * (tier - 4)))), do the math")))
            .overclock()
            .block(GTBlocks.STEEL_HULL)
            .pattern(definition -> FactoryBlockPattern.start(RelativeDirection.RIGHT, RelativeDirection.UP, RelativeDirection.BACK)
                    .aisle("DDDDD", "DDGDD", "EEEEE", "EEEEE")
                    .aisle("DEEED", "D   D", "E   E", "EFFFE")
                    .aisle("DEEED", "D   D", "EEEEE", "EEEEE")
                    .aisle("AAAAA", "ACCCA", "AAAAA", "CAAAC")
                    .aisle("AAAAA", "B   B", "A   A", "CAAAC")
                    .aisle("AAAAA", "B   B", "A   A", "CAAAC")
                    .aisle("AAAAA", "B   B", "A   A", "CAAAC")
                    .aisle("AAAAA", "ABBBA", "AAAAA", "     ")
                    .where('A', blocks(GTBlocks.CASING_STEEL_SOLID.get()))
                    .where('B', blocks(GTBlocks.FIREBOX_STEEL.get()))
                    .where('C', blocks(ChemicalHelper.getBlock(TagPrefix.frameGt, GTMaterials.StainlessSteel)))
                    .where('E', blocks(GTBlocks.STEEL_HULL.get()))
                    .where('F', blocks(GTBlocks.CASING_GRATE.get()))
                    .where('G', controller(blocks(definition.get())))
                    .where('D', blocks(GTBlocks.STEEL_HULL.get())
                            .or(autoAbilities(definition.getRecipeTypes()))
                            .or(abilities(MAINTENANCE).setExactLimit(1)))
                    .where(' ', any())
                    .build())
            .workableCasingRenderer(GTCEu.id("block/casings/steam/steel/side"), GTCEu.id("block/multiblock/gcym/large_maceration_tower"))
            .afterWorking(m -> {
                if (m.getRecipeLogic().getLastRecipe() != null && m.getRecipeLogic().getLastRecipe().data.getBoolean("isCustom")) {
                    m.getRecipeLogic().markLastRecipeDirty();
                }
            })
            .register();

    public static final MultiblockMachineDefinition MASS_FABRICATOR = multiblock("mass_fabricator", "质量发生器", ElectricMultiblockMachine::new)
            .allRotation()
            .recipeTypes(GTORecipeTypes.MASS_FABRICATOR_RECIPES)
            .parallelizableTooltips()
            .perfectOCTooltips()
            .parallelizablePerfectOverclock()
            .block(GTBlocks.MACHINE_CASING_UHV)
            .pattern(definition -> FactoryBlockPattern.start()
                    .aisle("bbbbb", " c c ", " c c ", " c c ", "bbbbb")
                    .aisle("bbbbb", "cdfdc", "cdfdc", "cdfdc", "bbbbb")
                    .aisle("bbbbb", " e e ", " e e ", " e e ", "bfffb")
                    .aisle("bbbbb", " e e ", " e e ", " e e ", "bfffb")
                    .aisle("bbbbb", " e e ", " e e ", " e e ", "bfffb")
                    .aisle("bbbbb", " e e ", " e e ", " e e ", "bfffb")
                    .aisle("bbbbb", "cdfdc", "cdfdc", "cdfdc", "bbbbb")
                    .aisle("bbabb", " c c ", " c c ", " c c ", "bbbbb")
                    .where('a', controller(blocks(definition.get())))
                    .where('b', blocks(GTBlocks.MACHINE_CASING_UHV.get())
                            .or(abilities(IMPORT_ITEMS).setMaxGlobalLimited(1).setPreviewCount(1))
                            .or(abilities(IMPORT_FLUIDS).setMaxGlobalLimited(1).setPreviewCount(1))
                            .or(abilities(EXPORT_FLUIDS).setMaxGlobalLimited(1).setPreviewCount(1))
                            .or(abilities(INPUT_ENERGY).setMaxGlobalLimited(16).setPreviewCount(16))
                            .or(abilities(PARALLEL_HATCH).setMaxGlobalLimited(1))
                            .or(abilities(MAINTENANCE).setExactLimit(1)))
                    .where('c', blocks(GTBlocks.CASING_POLYTETRAFLUOROETHYLENE_PIPE.get()))
                    .where('d', blocks(GTOBlocks.HYPER_CORE.get()))
                    .where('e', blocks(GTBlocks.HERMETIC_CASING_UHV.get()))
                    .where('f', blocks(GCYMBlocks.HEAT_VENT.get()))
                    .build())
            .workableCasingRenderer(GTCEu.id("block/casings/voltage/uhv/side"), GTCEu.id("block/multiblock/gcym/large_electrolyzer"))
            .register();

    public static final MultiblockMachineDefinition ADVANCED_MASS_FABRICATOR = multiblock("advanced_mass_fabricator", "进阶质量发生器", ElectricMultiblockMachine::new)
            .allRotation()
            .recipeTypes(GTORecipeTypes.MASS_FABRICATOR_RECIPES)
            .eutMultiplierTooltips(0.8)
            .durationMultiplierTooltips(0.5)
            .parallelizableTooltips()
            .perfectOCTooltips()
            .laserTooltips()
            .recipeModifiers(RecipeModifierFunction.HATCH_PARALLEL, RecipeModifierFunction.overclocking(0.25, 0.8, 0.5))
            .block(GTBlocks.MACHINE_CASING_UXV)
            .pattern(definition -> FactoryBlockPattern.start(RelativeDirection.BACK, RelativeDirection.UP, RelativeDirection.LEFT)
                    .aisle("AAAAAAAAAA AAAAAAAAAA", "AAFFFFFFAA AAFFFFFFAA", "AAAAAAAAAA AAAAAAAAAA", "AAAAAAAAAA AAAAAAAAAA", "AAFFFFFFAA AAFFFFFFAA", "AAAAAAAAAA AAAAAAAAAA", "                     ", "AAAAAAAAAA AAAAAAAAAA", "AAFFFFFFAA AAFFFFFFAA", "AAAAAAAAAA AAAAAAAAAA", "AAAAAAAAAA AAAAAAAAAA", "AAFFFFFFAA AAFFFFFFAA", "AAAAAAAAAA AAAAAAAAAA")
                    .aisle("AAAAAAAAAA AAAAAAAAAA", "BDDDDDDDDDDDDDDDDDDDB", "BDDDDDDDD   DDDDDDDDB", "BDDDDDDDD   DDDDDDDDB", "BDDDDDDDDDDDDDDDDDDDB", "CDDDDDDDDA ADDDDDDDDC", " DDDDDDDD   DDDDDDDD ", "CDDDDDDDDA ADDDDDDDDC", "BDDDDDDDDDDDDDDDDDDDB", "BDDDDDDDD   DDDDDDDDB", "BDDDDDDDD   DDDDDDDDB", "BDDDDDDDDDDDDDDDDDDDB", "AAAAAAAAAA AAAAAAAAAA")
                    .aisle("AAAAAAAAAA AAAAAAAAAA", "BDDDDDDDD   DDDDDDDDB", "B                   B", "B                   B", "BDDDDDDDD   DDDDDDDDB", "C        A A        C", " EEEEEEEEEEEEEEEEEEE ", "C        A A        C", "BDDDDDDDD   DDDDDDDDB", "B                   B", "B                   B", "BDDDDDDDD   DDDDDDDDB", "AAAAAAAAAA AAAAAAAAAA")
                    .aisle("AAAAAAAAAA AAAAAAAAAA", "BDDDDDDDD   DDDDDDDDB", "B                   B", "B                   B", "BDDDDDDDD   DDDDDDDDB", "C        A A        C", " EEEEEEEEEEEEEEEEEEE ", "C        A A        C", "BDDDDDDDD   DDDDDDDDB", "B                   B", "B                   B", "BDDDDDDDD   DDDDDDDDB", "AAAAAAAAAA AAAAAAAAAA")
                    .aisle("AAAAAAAAAA AAAAAAAAAA", "BDDDDDDDDDDDDDDDDDDDB", "BDDDDDDDD   DDDDDDDDB", "BDDDDDDDD   DDDDDDDDB", "BDDDDDDDDDDDDDDDDDDDB", "CDDDDDDDDA ADDDDDDDDC", " DDDDDDDD   DDDDDDDD ", "CDDDDDDDDA ADDDDDDDDC", "BDDDDDDDDDDDDDDDDDDDB", "BDDDDDDDD   DDDDDDDDB", "BDDDDDDDD   DDDDDDDDB", "BDDDDDDDDDDDDDDDDDDDB", "AAAAAAAAAA AAAAAAAAAA")
                    .aisle("AAAAAAAAAA AAAAAAAAAA", "CDDDDDDDDA ADDDDDDDDC", "C        A A        C", "C        A A        C", "CDDDDDDDDA ADDDDDDDDC", "CAAAAAAAAA AAAAAAAAAC", "C                    ", "CAAAAAAAAA AAAAAAAAAC", "CDDDDDDDDA ADDDDDDDDC", "C        A A        C", "C        A A        C", "CDDDDDDDDA ADDDDDDDDC", "AAAAAAAAAA AAAAAAAAAA")
                    .aisle("                     ", " DDDDDDDD   DDDDDDDD ", " EEEEEEEEEEEEEEEEEEE ", " EEEEEEEEEEEEEEEEEEE ", " DDDDDDDD   DDDDDDDD ", "C                    ", "G                    ", "C                    ", " DDDDDDDD   DDDDDDDD ", " EEEEEEEEEEEEEEEEEEE ", " EEEEEEEEEEEEEEEEEEE ", " DDDDDDDD   DDDDDDDD ", "                     ")
                    .aisle("AAAAAAAAAA AAAAAAAAAA", "CDDDDDDDDA ADDDDDDDDC", "C        A A        C", "C        A A        C", "CDDDDDDDDA ADDDDDDDDC", "CAAAAAAAAA AAAAAAAAAC", "C                    ", "CAAAAAAAAA AAAAAAAAAC", "CDDDDDDDDA ADDDDDDDDC", "C        A A        C", "C        A A        C", "CDDDDDDDDA ADDDDDDDDC", "AAAAAAAAAA AAAAAAAAAA")
                    .aisle("AAAAAAAAAA AAAAAAAAAA", "BDDDDDDDDDDDDDDDDDDDB", "BDDDDDDDD   DDDDDDDDB", "BDDDDDDDD   DDDDDDDDB", "BDDDDDDDDDDDDDDDDDDDB", "CDDDDDDDDA ADDDDDDDDC", " DDDDDDDD   DDDDDDDD ", "CDDDDDDDDA ADDDDDDDDC", "BDDDDDDDDDDDDDDDDDDDB", "BDDDDDDDD   DDDDDDDDB", "BDDDDDDDD   DDDDDDDDB", "BDDDDDDDDDDDDDDDDDDDB", "AAAAAAAAAA AAAAAAAAAA")
                    .aisle("AAAAAAAAAA AAAAAAAAAA", "BDDDDDDDD   DDDDDDDDB", "B                   B", "B                   B", "BDDDDDDDD   DDDDDDDDB", "C        A A        C", " EEEEEEEEEEEEEEEEEEE ", "C        A A        C", "BDDDDDDDD   DDDDDDDDB", "B                   B", "B                   B", "BDDDDDDDD   DDDDDDDDB", "AAAAAAAAAA AAAAAAAAAA")
                    .aisle("AAAAAAAAAA AAAAAAAAAA", "BDDDDDDDD   DDDDDDDDB", "B                   B", "B                   B", "BDDDDDDDD   DDDDDDDDB", "C        A A        C", " EEEEEEEEEEEEEEEEEEE ", "C        A A        C", "BDDDDDDDD   DDDDDDDDB", "B                   B", "B                   B", "BDDDDDDDD   DDDDDDDDB", "AAAAAAAAAA AAAAAAAAAA")
                    .aisle("AAAAAAAAAA AAAAAAAAAA", "BDDDDDDDDDDDDDDDDDDDB", "BDDDDDDDD   DDDDDDDDB", "BDDDDDDDD   DDDDDDDDB", "BDDDDDDDDDDDDDDDDDDDB", "CDDDDDDDDA ADDDDDDDDC", " DDDDDDDD   DDDDDDDD ", "CDDDDDDDDA ADDDDDDDDC", "BDDDDDDDDDDDDDDDDDDDB", "BDDDDDDDD   DDDDDDDDB", "BDDDDDDDD   DDDDDDDDB", "BDDDDDDDDDDDDDDDDDDDB", "AAAAAAAAAA AAAAAAAAAA")
                    .aisle("AAAAAAAAAA AAAAAAAAAA", "AAFFFFFFAA AAFFFFFFAA", "AAAAAAAAAA AAAAAAAAAA", "AAAAAAAAAA AAAAAAAAAA", "AAFFFFFFAA AAFFFFFFAA", "AAAAAAAAAA AAAAAAAAAA", "                     ", "AAAAAAAAAA AAAAAAAAAA", "AAFFFFFFAA AAFFFFFFAA", "AAAAAAAAAA AAAAAAAAAA", "AAAAAAAAAA AAAAAAAAAA", "AAFFFFFFAA AAFFFFFFAA", "AAAAAAAAAA AAAAAAAAAA")
                    .where('A', blocks(GTBlocks.MACHINE_CASING_UXV.get()))
                    .where('B', blocks(GTOBlocks.RHENIUM_REINFORCED_ENERGY_GLASS.get()))
                    .where('C', blocks(GTBlocks.MACHINE_CASING_UXV.get())
                            .or(GTOPredicates.autoLaserAbilities(definition.getRecipeTypes()))
                            .or(abilities(MAINTENANCE).setExactLimit(1)))
                    .where('D', blocks(GTOBlocks.TITANSTEEL_COIL_BLOCK.get()))
                    .where('E', blocks(GTOBlocks.HOLLOW_CASING.get()))
                    .where('F', blocks(GTOBlocks.RESTRAINT_DEVICE.get()))
                    .where('G', controller(blocks(definition.get())))
                    .where(' ', any())
                    .build())
            .workableCasingRenderer(GTCEu.id("block/casings/voltage/uxv/side"), GTCEu.id("block/multiblock/fusion_reactor"))
            .register();

    public static final MultiblockMachineDefinition PRECISION_ASSEMBLER = multiblock("precision_assembler", "精密组装机", PrecisionAssemblerMachine::new)
            .allRotation()
            .recipeTypes(GTORecipeTypes.PRECISION_ASSEMBLER_RECIPES)
            .recipeTypes(GTRecipeTypes.ASSEMBLER_RECIPES)
            .tooltips(NewDataAttributes.RUNTIME_REQUIREMENT.create(
                    c -> c.addLines("外壳等级决定配方等级上限",
                            "The machine casing tier determines the upper limit of recipe tier")))
            .tooltips(NewDataAttributes.ALLOW_PARALLEL_NUMBER.create(
                    h -> h.addLines("由玻璃等级决定", "Determined by glass tier"),
                    c -> c.addCommentLines(
                            "高等级玻璃可以提供更多的并行数量",
                            "Higher tier glass provides more parallelism")))
            .laserTooltips()
            .recipeModifier(RecipeModifierFunction::laserLossOverclocking)
            .block(GTOBlocks.OXIDATION_RESISTANT_HASTELLOY_N_MECHANICAL_CASING)
            .pattern(definition -> FactoryBlockPattern.start()
                    .aisle("bbbbbbbbb", "d       d", "d       d", "d       d", "bbbbbbbbb")
                    .aisle("bAAAAAAAb", "bcccccccb", "bcccccccb", "bcccccccb", "bbbbbbbbb")
                    .aisle("bAAAAAAAb", "b-------b", "b-------b", "b-------b", "bbbbbbbbb")
                    .aisle("bAAAAAAAb", "bcccccccb", "bcccccccb", "bcccccccb", "bbbbbbbbb")
                    .aisle("bbbbabbbb", "d       d", "d       d", "d       d", "bbbbbbbbb")
                    .where('a', controller(blocks(definition.get())))
                    .where('b', blocks(GTOBlocks.OXIDATION_RESISTANT_HASTELLOY_N_MECHANICAL_CASING.get())
                            .setMinGlobalLimited(70)
                            .or(GTOPredicates.autoLaserAbilities(definition.getRecipeTypes()))
                            .or(abilities(MAINTENANCE).setExactLimit(1)))
                    .where('c', GTOPredicates.glass())
                    .where('d', blocks(ChemicalHelper.getBlock(TagPrefix.frameGt, GTOMaterials.HastelloyN)))
                    .where('A', GTOPredicates.machineCasing())
                    .where('-', air())
                    .where(' ', any())
                    .build())
            .workableCasingRenderer(GTOCore.id("block/casings/oxidation_resistant_hastelloy_n_mechanical_casing"), GTCEu.id("block/multiblock/gcym/large_assembler"))
            .register();

    public static final MultiblockMachineDefinition FISHING_GROUND = multiblock("fishing_ground", "渔场", FishingGroundMachine::new)
            .nonYAxisRotation()
            .recipeTypes(GTORecipeTypes.FISHING_GROUND_RECIPES)
            .parallelizableTooltips()
            .parallelizableOverclock()
            .block(GTOBlocks.ALUMINIUM_BRONZE_CASING)
            .pattern(definition -> FactoryBlockPattern.start(RelativeDirection.RIGHT, RelativeDirection.UP, RelativeDirection.BACK)
                    .aisle("    AAAAA    ", "    AAFAA    ", "    BBBBB    ", "             ")
                    .aisle("   BBBBBBB   ", "   BCCCCCB   ", "   BB E BB   ", "             ")
                    .aisle("  BBBBBBBBB  ", "  BCCCCCCCB  ", "  BB  E  BB  ", "             ")
                    .aisle(" BBBBBBBBBBB ", " BCCCCCCCCCB ", " BB   E   BB ", "             ")
                    .aisle("ABBBBBBBBBBBA", "ACCCCCCCCCCCA", "BB    E    BB", "             ")
                    .aisle("ABBBBBBBBBBBA", "ACCCCBEBCCCCA", "B    BEB    B", "     BBB     ")
                    .aisle("ABBBBBBBBBBBA", "ACCCCEDECCCCA", "BEEEEEDEEEEEB", "     BBB     ")
                    .aisle("ABBBBBBBBBBBA", "ACCCCBEBCCCCA", "B    BDB    B", "     BBB     ")
                    .aisle("ABBBBBBBBBBBA", "ACCCCCCCCCCCA", "BB    D    BB", "             ")
                    .aisle(" BBBBBBBBBBB ", " BCCCCCCCCCB ", " BB   D   BB ", "             ")
                    .aisle("  BBBBBBBBB  ", "  BCCCCCCCB  ", "  BB  D  BB  ", "             ")
                    .aisle("   BBBBBBB   ", "   BCCCCCB   ", "   BB D BB   ", "             ")
                    .aisle("    AAAAA    ", "    AAAAA    ", "    BBBBB    ", "             ")
                    .where('A', blocks(GTOBlocks.ALUMINIUM_BRONZE_CASING.get())
                            .or(autoAbilities(definition.getRecipeTypes()))
                            .or(abilities(PARALLEL_HATCH).setMaxGlobalLimited(1))
                            .or(abilities(MAINTENANCE).setExactLimit(1)))
                    .where('B', blocks(GTOBlocks.ALUMINIUM_BRONZE_CASING.get()))
                    .where('C', fluids(Fluids.WATER))
                    .where('D', blocks(GTBlocks.CASING_STEEL_PIPE.get()))
                    .where('E', blocks(ChemicalHelper.getBlock(TagPrefix.frameGt, GTMaterials.StainlessSteel)))
                    .where('F', controller(blocks(definition.get())))
                    .where(' ', any())
                    .build())
            .workableCasingRenderer(GTOCore.id("block/casings/aluminium_bronze_casing"), GTCEu.id("block/multiblock/gcym/large_assembler"))
            .register();

    public static final MultiblockMachineDefinition LAVA_FURNACE = multiblock("lava_furnace", "熔岩炉", ElectricMultiblockMachine::new)
            .allRotation()
            .recipeTypes(GTORecipeTypes.LAVA_FURNACE_RECIPES)
            .tooltips(NewDataAttributes.EMPTY_WITH_BAR.create(
                    h -> h.addLines("熔岩生成说明", "Lava Generation Details", StyleBuilder::setGold),
                    c -> c.addLines(
                            NewDataAttributes.EMPTY_WITH_POINT.createBuilder(
                                    x -> x.addLines("每提供一个任意类型的圆石或石头", "Each provided piece of any type of cobblestone or stone", StyleBuilder::setWhite),
                                    p -> p,
                                    StyleBuilder::setOneTab),
                            NewDataAttributes.EMPTY_WITH_POINT.createBuilder(
                                    x -> x.addLines("可输出1B熔岩", "can output 1B of lava.", StyleBuilder::setGreen),
                                    p -> p,
                                    StyleBuilder::setOneTab))))
            .overclock()
            .block(GTBlocks.CASING_BRONZE_BRICKS)
            .pattern(definition -> FactoryBlockPattern.start()
                    .aisle("CCC", "DDD", "DDD")
                    .aisle("CCC", "D D", "DMD")
                    .aisle("CCC", "DAD", "DDD")
                    .where('A', controller(blocks(definition.get())))
                    .where('D', blocks(GTBlocks.CASING_BRONZE_BRICKS.get())
                            .or(autoAbilities(definition.getRecipeTypes())))
                    .where('M', abilities(MUFFLER))
                    .where('C', blocks(GTBlocks.FIREBOX_BRONZE.get()))
                    .where(' ', air())
                    .build())
            .workableCasingRenderer(GTCEu.id("block/casings/solid/machine_casing_bronze_plated_bricks"), GTCEu.id("block/multiblock/steam_oven"))
            .register();

    public static final MultiblockMachineDefinition LARGE_GAS_COLLECTOR = multiblock("large_gas_collector", "大型集气室", CustomParallelMultiblockMachine.createParallel(m -> 100000, true))
            .noneRotation()
            .recipeTypes(GTORecipeTypes.LARGE_GAS_COLLECTOR_RECIPES)
            .overclock()
            .block(GTBlocks.CASING_STEEL_SOLID)
            .pattern(definition -> FactoryBlockPattern.start()
                    .aisle("aaaaa", "abbba", "abbba", "abbba", "aaaaa")
                    .aisle("aaaaa", "bcccb", "bcccb", "bcccb", "abbba")
                    .aisle("aaaaa", "bcccb", "bcecb", "bcccb", "abdba")
                    .aisle("aaaaa", "bcccb", "bcccb", "bcccb", "abbba")
                    .aisle("aaaaa", "abbba", "abbba", "abbba", "aaaaa")
                    .where('d', controller(blocks(definition.get())))
                    .where('a', blocks(GTBlocks.CASING_STEEL_SOLID.get())
                            .setMinGlobalLimited(40)
                            .or(autoAbilities(definition.getRecipeTypes()))
                            .or(abilities(MAINTENANCE).setExactLimit(1)))
                    .where('c', blocks(GTBlocks.CASING_TUNGSTENSTEEL_PIPE.get()))
                    .where('b', blocks(GTBlocks.CASING_GRATE.get()))
                    .where('e', blocks(GTBlocks.HERMETIC_CASING_IV.get()))
                    .build())
            .workableCasingRenderer(GTCEu.id("block/casings/solid/machine_casing_solid_steel"), GTCEu.id("block/machines/gas_collector"))
            .register();

    public static final MultiblockMachineDefinition ENGRAVING_LASER_PLANT = multiblock("engraving_laser_plant", "激光蚀刻工厂", ElectricMultiblockMachine::new)
            .nonYAxisRotation()
            .recipeTypes(GTORecipeTypes.PRECISION_LASER_ENGRAVER_RECIPES)
            .recipeTypes(GTRecipeTypes.LASER_ENGRAVER_RECIPES)
            .recipeTypes(GTORecipeTypes.LASER_WELDER_RECIPES)
            .tooltipsText("运行激光焊接配方时速度x5", "Running the Laser Welder formula at speed x5.")
            .specialParallelizableTooltips()
            .tooltips(NewDataAttributes.ALLOW_PARALLEL_NUMBER.create(h -> h.addLines("仅精密激光模式不支持", "Only the precision laser mode does not support")))
            .perfectOCTooltips()
            .recipeModifiers((machine, recipe) -> {
                if (machine instanceof ElectricMultiblockMachine workableElectricMultiblockMachine) {
                    if (workableElectricMultiblockMachine.getRecipeType() == GTRecipeTypes.LASER_ENGRAVER_RECIPES) return RecipeModifierFunction.hatchParallel(workableElectricMultiblockMachine, recipe);
                    if (workableElectricMultiblockMachine.getRecipeType() == GTORecipeTypes.LASER_WELDER_RECIPES) {
                        recipe.duration = recipe.duration / 5;
                        return RecipeModifierFunction.hatchParallel(workableElectricMultiblockMachine, recipe);
                    }
                }
                return recipe;
            }, RecipeModifierFunction.PERFECT_OVERCLOCKING)
            .block(GTOBlocks.IRIDIUM_CASING)
            .pattern(definition -> FactoryBlockPattern.start(RelativeDirection.RIGHT, RelativeDirection.UP, RelativeDirection.BACK)
                    .aisle("       aaaaaaa       ", "       aaaaaaa       ", "       aaa~aaa       ", "       aaaaaaa       ", "        aaaaa        ", "                     ", "                     ", "                     ", "                     ", "                     ", "                     ", "                     ")
                    .aisle("        AAAAA        ", "        JDIDJ        ", "        A   A        ", "         AAA         ", "          B          ", "                     ", "                     ", "                     ", "                     ", "                     ", "                     ", "                     ")
                    .aisle("        AAAAA        ", "        JDIDJ        ", "        A   A        ", "         AAA         ", "          B          ", "                     ", "                     ", "                     ", "                     ", "                     ", "                     ", "                     ")
                    .aisle("   AAA  AAAAA  AAA   ", "   FAF  JDIDJ  FAF   ", "   FAF  A   A  FAF   ", "   FAF   AAA   FAF   ", "   FAF    B    FAF   ", "   FAF         FAF   ", "   AAA         AAA   ", "                     ", "                     ", "                     ", "                     ", "                     ")
                    .aisle("  AAAAA AAAAA AAAAA  ", "  FMDMF JDIDJ FBDBF  ", "  FM MF A   A FB BF  ", "  FM MF  AAA  FB BF  ", "  FM MF   B   FB BF  ", "  FMDMF       FBDBF  ", "  ABBBA       ABBBA  ", "   AAA         AAA   ", "                     ", "                     ", "                     ", "                     ")
                    .aisle("  AAAAA AAAAA AAAAA  ", "  ADDDA JDIDJ ADDDA  ", "  A I A A   A A I A  ", "  A I A  AAA  A I A  ", "  A I A   B   A I A  ", "  ADDDA       ADDDA  ", "  ABBBA       ABBBA  ", "   AAA         AAA   ", "                     ", "                     ", "                     ", "                     ")
                    .aisle("  AAAAA AAAAA AAAAA  ", "  FMDMF JDIDJ FBDBF  ", "  FM MF A   A FB BF  ", "  FM MF  AAA  FB BF  ", "  FM MF   B   FB BF  ", "  FMDMF       FBDBF  ", "  ABBBA       ABBBA  ", "   AAA         AAA   ", "                     ", "                     ", "                     ", "                     ")
                    .aisle("   AAA  AAAAA  AAA   ", "   FAF  JDIDJ  FAF   ", "   FAF  A   A  FAF   ", "   FAF   AAA   FAF   ", "   FAF    B    FAF   ", "   FAF         FAF   ", "   AAA         AAA   ", "                     ", "                     ", "                     ", "                     ", "                     ")
                    .aisle("       AAAAAAA       ", "       JADIDAJ       ", "       AABBBAA       ", "    I   AAAAA   I    ", "         AAA         ", "         AAA         ", "                     ", "                     ", "                     ", "                     ", "                     ", "                     ")
                    .aisle(" AAA   AAAAAAA   AAA ", " AKA   JDBBBDJ   ALA ", " AKA   ABDDDBA   ALA ", " AKAI  AABBBAA  IALA ", " AKA    AAAAA    ALA ", " AAA    AAHAA    AAA ", "         AHA         ", "         AHA         ", "         AHA         ", "         AHA         ", "         AAA         ", "                     ")
                    .aisle("AAAAA AAAAAAAAA AAAAA", "ABBBA JDB   BDJ ABBBA", "ACDCA ABD I DBA ACDCA", "ACDCA  AB   BA  ACDCA", "ABBBA  AAAAAAA  ABBBA", "AHHHA  AAD DAA  ALLLA", " AAA    AD DA    AAA ", "        AD DA        ", "        AD DA        ", "        AAAAA        ", "        ABBBA        ", "         BBB         ")
                    .aisle("AAAAA AAAAAAAAA AAAAA", "ABBBA JDB I BDJ ABBBA", "AD DA ABDIIIDBA AD DA", "AD DAIIAB I BAIIAD DA", "ABBBA  AAAAAAA  ABBBA", "AHHHA  AH I HA  ALLLA", " AAACCCCH I HCCCCAAA ", "        H I H        ", "        H I H        ", "        HAAAH        ", "        ABBBA        ", "         BBB         ")
                    .aisle("AAAAA AAAAAAAAA AAAAA", "ABBBA JDB   BDJ ABBBA", "ACDCA ABD I DBA ACDCA", "ACDCA  AB   BA  ACDCA", "ABBBA  AAAAAAA  ABBBA", "AHHHA  AAD DAA  ALLLA", " AAA    AD DA    AAA ", "        AD DA        ", "        AD DA        ", "        AAAAA        ", "        ABBBA        ", "         BBB         ")
                    .aisle(" AAA   AAAAAAA   AAA ", " AKA   JDBBBDJ   ALA ", " AKA   ABDDDBA   ALA ", " AKAI  AABBBAA  IALA ", " AKA    AAAAA    ALA ", " AAA    AAHAA    AAA ", "         AHA         ", "         AHA         ", "         AHA         ", "         AHA         ", "         AAA         ", "                     ")
                    .aisle("       AAAAAAA       ", "       JJDDDJJ       ", "       AABBBAA       ", "    I   AAAAA   I    ", "         AAA         ", "         AAA         ", "          C          ", "                     ", "                     ", "                     ", "                     ", "                     ")
                    .aisle("   AAA   AAA   AAA   ", "   FAF   JJJ   FAF   ", "   FAF   AAA   FAF   ", "   FAF    I    FAF   ", "   FAF         FAF   ", "   FAF         FAF   ", "   AAA    C    AAA   ", "                     ", "                     ", "                     ", "                     ", "                     ")
                    .aisle("  AAAAA       AAAAA  ", "  FHDHF       FEDEF  ", "  FH HF       FE EF  ", "  FH HF   I   FE EF  ", "  FH HF       FE EF  ", "  FHDHF       FEDEF  ", "  ABBBA   C   ABBBA  ", "   AAA         AAA   ", "                     ", "                     ", "                     ", "                     ")
                    .aisle("  AAAAA  AAA  AAAAA  ", "  ADDDA  AAA  ADDDA  ", "  A I A  AAA  A I A  ", "  A I AIIAAAIIA I A  ", "  A I A  AAA  A I A  ", "  ADDDA  AAA  ADDDA  ", "  ABBBA   C   ABBBA  ", "   AAA         AAA   ", "                     ", "                     ", "                     ", "                     ")
                    .aisle("  AAAAA AAAAA AAAAA  ", "  FHDHF ABBBA FEDEF  ", "  FH HF ACDCA FE EF  ", "  FH HF ACDCA FE EF  ", "  FH HF ABBBA FE EF  ", "  FHDHF AEEEA FEDEF  ", "  ABBBA  AAA  ABBBA  ", "   AAA         AAA   ", "                     ", "                     ", "                     ", "                     ")
                    .aisle("   AAA  AAAAA  AAA   ", "   FAF  GBBBG  FAF   ", "   FAF  GD DG  FAF   ", "   FAF  GD DG  FAF   ", "   FAF  GBBBG  FAF   ", "   FAF  AEEEA  FAF   ", "   AAA   AAA   AAA   ", "                     ", "                     ", "                     ", "                     ", "                     ")
                    .aisle("        AAAAA        ", "        ABBBA        ", "        ACDCA        ", "        ACDCA        ", "        ABBBA        ", "        AEEEA        ", "         AAA         ", "                     ", "                     ", "                     ", "                     ", "                     ")
                    .aisle("         AAA         ", "         AAA         ", "         AAA         ", "         AAA         ", "         AAA         ", "         AAA         ", "                     ", "                     ", "                     ", "                     ", "                     ", "                     ")
                    .where('~', controller(blocks(definition.get())))
                    .where('A', blocks(GTOBlocks.IRIDIUM_CASING.get()))
                    .where('B', blocks(GTBlocks.HIGH_POWER_CASING.get()))
                    .where('C', blocks(ChemicalHelper.getBlock(TagPrefix.frameGt, GTMaterials.Neutronium)))
                    .where('D', blocks(GTOBlocks.AMPROSIUM_GEARBOX.get()))
                    .where('E', blocks(GTOBlocks.COMPONENT_ASSEMBLY_LINE_CASING_UV.get()))
                    .where('F', blocks(GTBlocks.FUSION_GLASS.get()))
                    .where('G', blocks(GCYMBlocks.HEAT_VENT.get()))
                    .where('H', blocks(GTBlocks.HERMETIC_CASING_UHV.get()))
                    .where('I', blocks(GTOBlocks.AMPROSIUM_PIPE_CASING.get()))
                    .where('J', blocks(GTBlocks.FILTER_CASING_STERILE.get()))
                    .where('K', blocks(GTOBlocks.ADVANCED_COMPRESSED_FUSION_COIL.get()))
                    .where('L', blocks(GCYMBlocks.ELECTROLYTIC_CELL.get()))
                    .where('M', blocks(GTOBlocks.MOLECULAR_CASING.get()))
                    .where('a', blocks(GTOBlocks.IRIDIUM_CASING.get())
                            .or(abilities(PARALLEL_HATCH).setMaxGlobalLimited(1))
                            .or(abilities(IMPORT_ITEMS).setPreviewCount(1))
                            .or(abilities(IMPORT_FLUIDS).setPreviewCount(1))
                            .or(abilities(INPUT_ENERGY).setMaxGlobalLimited(2).setPreviewCount(1))
                            .or(abilities(MAINTENANCE).setExactLimit(1))
                            .or(abilities(EXPORT_ITEMS).setPreviewCount(1))
                            .or(abilities(COMPUTATION_DATA_RECEPTION).setExactLimit(1)))
                    .where(' ', any())
                    .build())
            .workableCasingRenderer(GTOCore.id("block/casings/iridium_casing"), GTCEu.id("block/multiblock/gcym/large_engraving_laser"))
            .register();

    public static final MultiblockMachineDefinition MAGNETIC_CONFINEMENT_DIMENSIONALITY_SHOCK_DEVICE = multiblock("magnetic_confinement_dimensionality_shock_device", "磁约束维度震荡装置", ElectricMultiblockMachine::new)
            .allRotation()
            .recipeTypes(GTORecipeTypes.DIMENSIONALLY_TRANSCENDENT_MIXER_RECIPES)
            .recipeTypes(GTRecipeTypes.MIXER_RECIPES)
            .tooltipsText("运行搅拌机配方时耗时倍数为0.1", "Time multiplication factor for running the mixer recipe is 0.1")
            .parallelizableTooltips()
            .perfectOCTooltips()
            .laserTooltips()
            .recipeModifiers((machine, recipe) -> {
                if (machine instanceof ElectricMultiblockMachine workableElectricMultiblockMachine && workableElectricMultiblockMachine.getRecipeType() == GTRecipeTypes.MIXER_RECIPES) {
                    recipe.duration = recipe.duration / 10;
                    return recipe;
                }
                return recipe;
            }, RecipeModifierFunction.HATCH_PARALLEL, RecipeModifierFunction.PERFECT_OVERCLOCKING)
            .block(GTOBlocks.MOLECULAR_CASING)
            .pattern(definition -> MultiBlockFileReader.start(definition, RelativeDirection.FRONT, RelativeDirection.UP, RelativeDirection.RIGHT)
                    .where('~', controller(blocks(definition.get())))
                    .where('A', blocks(GTOBlocks.MOLECULAR_CASING.get()))
                    .where('B', blocks(ChemicalHelper.getBlock(TagPrefix.frameGt, GTMaterials.HastelloyX)))
