package com.gtocore.common.data.machines;

import com.gtocore.api.pattern.GTOPredicates;
import com.gtocore.client.renderer.machine.DimensionalFocusEngravingArrayRenderer;
import com.gtocore.common.data.GTOBlocks;
import com.gtocore.common.data.GTORecipeTypes;

import com.gtolib.GTOCore;
import com.gtolib.api.machine.multiblock.CoilCrossRecipeMultiblockMachine;
import com.gtolib.utils.MultiBlockFileReader;

import com.gregtechceu.gtceu.GTCEu;
import com.gregtechceu.gtceu.api.machine.MultiblockMachineDefinition;
import com.gregtechceu.gtceu.api.pattern.FactoryBlockPattern;
import com.gregtechceu.gtceu.api.pattern.util.RelativeDirection;
import com.gregtechceu.gtceu.common.data.GCYMBlocks;
import com.gregtechceu.gtceu.common.data.GTBlocks;

import static com.gregtechceu.gtceu.api.machine.multiblock.PartAbility.*;
import static com.gregtechceu.gtceu.api.pattern.Predicates.*;
import static com.gtolib.utils.register.MachineRegisterUtils.multiblock;

public final class MultiBlockE {

    public static void init() {}

    public static final MultiblockMachineDefinition DIMENSIONAL_FOCUS_ENGRAVING_ARRAY = multiblock("dimensional_focus_engraving_array", "维度聚焦激光蚀刻阵列", CoilCrossRecipeMultiblockMachine::createCoilParallel)
            .nonYAxisRotation()
            .recipeTypes(GTORecipeTypes.DIMENSIONAL_FOCUS_ENGRAVING_ARRAY_RECIPES)
            .coilParallelTooltips()
            .laserTooltips()
            .multipleRecipesTooltips()
            .block(GCYMBlocks.CASING_LASER_SAFE_ENGRAVING)
            .pattern(definition -> MultiBlockFileReader.start(definition, RelativeDirection.BACK, RelativeDirection.UP, RelativeDirection.RIGHT)
                    .where('I', controller(blocks(definition.get())))
                    .where('A', blocks(GTOBlocks.DIMENSIONALLY_TRANSCENDENT_CASING.get()))
                    .where('B', blocks(GTBlocks.FUSION_GLASS.get()))
                    .where('C', blocks(GTOBlocks.DIMENSION_INJECTION_CASING.get()))
                    .where('D', blocks(GTOBlocks.MOLECULAR_COIL.get()))
                    .where('E', blocks(GTOBlocks.CONTAINMENT_FIELD_GENERATOR.get()))
                    .where('F', blocks(GTOBlocks.IMPROVED_SUPERCONDUCTOR_COIL.get()))
                    .where('G', blocks(GCYMBlocks.CASING_LASER_SAFE_ENGRAVING.get()))
                    .where('a', blocks(GCYMBlocks.CASING_LASER_SAFE_ENGRAVING.get())
                            .or(GTOPredicates.autoThreadLaserAbilities(definition.getRecipeTypes()))
                            .or(abilities(MAINTENANCE).setExactLimit(1))
                            .or(abilities(OPTICAL_DATA_RECEPTION).setExactLimit(1))
                            .or(abilities(COMPUTATION_DATA_RECEPTION).setExactLimit(1)))
                    .where('H', heatingCoils())
                    .where(' ', any())
                    .build())
            .renderer(DimensionalFocusEngravingArrayRenderer::new)
            .hasTESR(true)
            .register();

    public static final MultiblockMachineDefinition STAR_ULTIMATE_MATERIAL_FORGE_FACTORY = multiblock("star_ultimate_material_forge_factory", "恒星终极物质锻造工厂", CoilCrossRecipeMultiblockMachine.createParallel(false, false, m -> Integer.MAX_VALUE))
            .allRotation()
            .recipeTypes(GTORecipeTypes.ULTIMATE_MATERIAL_FORGE_RECIPES)
            .laserTooltips()
            .multipleRecipesTooltips()
            .block(GTOBlocks.MOLECULAR_CASING)
            .pattern(definition -> FactoryBlockPattern.start()
                    .aisle("                                                             ", "                                                             ", "                                                             ", "                                                             ", "                                                             ", "                                                             ", "                           AAAAAAA                           ", "                          AAAAAAAAA                          ", "                          AAAAAAAAA                          ", "                          AAAAAAAAA                          ", "                           AAAAAAA                           ", "                                                             ", "                                                             ", "                                                             ", "                                                             ", "                                                             ", "                                                             ")
                    .aisle("                                                             ", "                                                             ", "                                                             ", "                                                             ", "                                                             ", "                            AAAAA                            ", "                          AAAAAAAAA                          ", "                       AAAAAAAAAAAAAAA                       ", "                       AAABBBBBBBBBAAA                       ", "                       AAAAAAAAAAAAAAA                       ", "                       AAAAAAAAAAAAAAA                       ", "                            AAAAA                            ", "                                                             ", "                                                             ", "                                                             ", "                                                             ", "                                                             ")
                    .aisle("                                                             ", "                                                             ", "                                                             ", "                                                             ", "                                                             ", "                           AAAAAAA                           ", "                       AAAAAAAAAAAAAAA                       ", "                    AAAAAABBBBBBBBBAAAAAA                    ", "                    AAABBBBBBBBBBBBBBBAAA                    ", "                    AAAAAABBBBBBBBBAAAAAA                    ", "                    AAAAAAAAAAAAAAAAAAAAA                    ", "                           AAAAAAA                           ", "                                                             ", "                                                             ", "                                                             ", "                                                             ", "                                                             ")
                    .aisle("                                                             ", "                                                             ", "                                                             ", "                                                             ", "                                                             ", "                           AAAAAAA                           ", "                    AAAAAAAAAAAAAAAAAAAAA                    ", "                  AAAAABBBCCCCCCCCCBBBAAAAA                  ", "                  AABBBBBBBBBBBBBBBBBBBBBAA                  ", "                  AAAAABBBCCCCCCCCCBBBAAAAA                  ", "                  AAAAAAAAAAAAAAAAAAAAAAAAA                  ", "                           AAAAAAA                           ", "                                                             ", "                                                             ", "                                                             ", "                                                             ", "                                                             ")
                    .aisle("                                                             ", "                                                             ", "                                                             ", "                                                             ", "                                                             ", "                            AAAAA                            ", "                  AAAAAAAAAAAAAAAAAAAAAAAAA                  ", "                AAAABBBCCCAAADDDAAACCCBBBAAAA                ", "                AABBBBBBBBAAADEDAAABBBBBBBBAA                ", "                AAAABBBCCCAAADDDAAACCCBBBAAAA                ", "                AAAAAAAAAAAAAAAAAAAAAAAAAAAAA                ", "                            AAAAA                            ", "                                                             ", "                                                             ", "                                                             ", "                                                             ", "                                                             ")
                    .aisle("                                                             ", "                                                             ", "                                                             ", "                                                             ", "                                                             ", "                                                             ", "                AAAAAAA     AAAAA     AAAAAAA                ", "              AAAABBCCC    AADDDAA    CCCBBAAAA              ", "              AABBBBBBB    AADEDAA    BBBBBBBAA              ", "              AAAABBCCC    AADDDAA    CCCBBAAAA              ", "              AAAAAAAAA     AAAAA     AAAAAAAAA              ", "                                                             ", "                                                             ", "                                                             ", "                                                             ", "                                                             ", "                                                             ")
                    .aisle("                                                             ", "                                                             ", "                                                             ", "                                                             ", "                                                             ", "                                                             ", "              AAAAAA                     AAAAAA              ", "             AAABBCC         DDD         CCBBAAA             ", "             ABBBBBB         DED         BBBBBBA             ", "             AAABBCC         DDD         CCBBAAA             ", "             AAAAAAA                     AAAAAAA             ", "                                                             ", "                                                             ", "                                                             ", "                                                             ", "                                                             ", "                                                             ")
                    .aisle("                                                             ", "                                                             ", "                                                             ", "                                                             ", "                                                             ", "                                                             ", "             AAAAA                         AAAAA             ", "            AABBCC           DDD           CCBBAA            ", "            ABBBBB           DED           BBBBBA            ", "            AABBCC           DDD           CCBBAA            ", "            AAAAAA                         AAAAAA            ", "                                                             ", "                                                             ", "                                                             ", "                                                             ", "                                                             ", "                                                             ")
                    .aisle("                                                             ", "                                                             ", "                                                             ", "                                                             ", "                                                             ", "                                                             ", "            AAAA                             AAAA            ", "           AABCC             DDD             CCBAA           ", "           ABBBB             DED             BBBBA           ", "           AABCC             DDD             CCBAA           ", "           AAAAA                             AAAAA           ", "                                                             ", "                                                             ", "                                                             ", "                                                             ", "                                                             ", "                                                             ")
                    .aisle("                                                             ", "                                                             ", "                                                             ", "                                                             ", "                                                             ", "                                                             ", "           AAA                                 AAA           ", "          AABC               DDD               CBAA          ", "          ABBB               DED               BBBA          ", "          AABC               DDD               CBAA          ", "          AAAA                                 AAAA          ", "                                                             ", "                                                             ", "                                                             ", "                                                             ", "                                                             ", "                                                             ")
                    .aisle("                                                             ", "                                                             ", "                                                             ", "                                                             ", "                                                             ", "                                                             ", "          AAA                                   AAA          ", "         AABC                DDD                CBAA         ", "         ABBB                DED                BBBA         ", "         AABC                DDD                CBAA         ", "         AAAA                                   AAAA         ", "                                                             ", "                                                             ", "                                                             ", "                                                             ", "                                                             ", "                                                             ")
                    .aisle("                                                             ", "                                                             ", "                                                             ", "                                                             ", "                                                             ", "                                                             ", "         AAA                                     AAA         ", "        AABC                 DDD                 CBAA        ", "        ABBB                 DED                 BBBA        ", "        AABC                 DDD                 CBAA        ", "        AAAA                                     AAAA        ", "                                                             ", "                                                             ", "                                                             ", "                                                             ", "                                                             ", "                                                             ")
                    .aisle("                                                             ", "                                                             ", "                                                             ", "                                                             ", "                                                             ", "                                                             ", "        AAA                                       AAA        ", "       AABC                  DDD                  CBAA       ", "       ABBB                  DED                  BBBA       ", "       AABC                  DDD                  CBAA       ", "       AAAA                                       AAAA       ", "                                                             ", "                                                             ", "                                                             ", "                                                             ", "                                                             ", "                                                             ")
                    .aisle("                                                             ", "                                                             ", "                                                             ", "                                                             ", "                                                             ", "                                                             ", "       AAA                                         AAA       ", "      AABC                   DDD                   CBAA      ", "      ABBB                   DED                   BBBA      ", "      AABC                   DDD                   CBAA      ", "      AAAA                                         AAAA      ", "                                                             ", "                                                             ", "                                                             ", "                                                             ", "                                                             ", "                                                             ")
                    .aisle("                                                             ", "                                                             ", "                                                             ", "                                                             ", "                                                             ", "                                                             ", "      AAA                                           AAA      ", "     AABC                    DDD                    CBAA     ", "     ABBB                    DED                    BBBA     ", "     AABC                    DDD                    CBAA     ", "     AAAA                                           AAAA     ", "                                                             ", "                                                             ", "                                                             ", "                                                             ", "                                                             ", "                                                             ")
                    .aisle("                                                             ", "                                                             ", "                                                             ", "                                                             ", "                                                             ", "                                                             ", "      AAA                                           AAA      ", "     AABC                    DDD                    CBAA     ", "     ABBB                    DED                    BBBA     ", "     AABC                    DDD                    CBAA     ", "     AAAA                                           AAAA     ", "                                                             ", "                                                             ", "                                                             ", "                                                             ", "                                                             ", "                                                             ")
                    .aisle("                                                             ", "                                                             ", "                                                             ", "                                                             ", "                                                             ", "                                                             ", "     AAA                                             AAA     ", "    AABC                     DDD                     CBAA    ", "    ABBB                     DED                     BBBA    ", "    AABC                     DDD                     CBAA    ", "    AAAA                                             AAAA    ", "                                                             ", "                                                             ", "                                                             ", "                                                             ", "                                                             ", "                                                             ")
                    .aisle("                                                             ", "                                                             ", "                                                             ", "                                                             ", "                                                             ", "                                                             ", "     AAA                                             AAA     ", "    AABC                     DDD                     CBAA    ", "    ABBB                     DED                     BBBA    ", "    AABC                     DDD                     CBAA    ", "    AAAA                                             AAAA    ", "                                                             ", "                                                             ", "                                                             ", "                                                             ", "                                                             ", "                                                             ")
                    .aisle("                                                             ", "                                                             ", "                                                             ", "                                                             ", "                                                             ", "                                                             ", "    AAA                     FAAAF                     AAA    ", "   AABC                     ADDDA                     CBAA   ", "   ABBB                     ADEDA                     BBBA   ", "   AABC                     ADDDA                     CBAA   ", "   AAAA                     FAAAF                     AAAA   ", "                                                             ", "                                                             ", "                                                             ", "                                                             ", "                                                             ", "                                                             ")
                    .aisle("                                                             ", "                                                             ", "                                                             ", "                                                             ", "                                                             ", "                            FAAAF                            ", "    AAA                    F GGG F                    AAA    ", "   AABC                    AGDDDGA                    CBAA   ", "   ABBB                    AGDEDGA                    BBBA   ", "   AABC                    AGDDDGA                    CBAA   ", "   AAAA                    F GGG F                    AAAA   ", "                            FAAAF                            ", "                                                             ", "                                                             ", "                                                             ", "                                                             ", "                                                             ")
                    .aisle("                                                             ", "                                                             ", "                                                             ", "                                                             ", "                            FAAAF                            ", "                           F     F                           ", "   AAA                    F  GGG  F                    AAA   ", "  AABC                    A GDDDG A                    CBAA  ", "  ABBB                    A GDEDG A                    BBBA  ", "  AABC                    A GDDDG A                    CBAA  ", "  AAAA                    F  GGG  F                    AAAA  ", "                           F     F                           ", "                            FAAAF                            ", "                                                             ", "                                                             ", "                                                             ", "                                                             ")
                    .aisle("                                                             ", "                                                             ", "                                                             ", "                            FAAAF                            ", "                           F     F                           ", "                          F       F                          ", "   AAA                   F   GGG   F                   AAA   ", "  AABC                   A  GDDDG  A                   CBAA  ", "  ABBB                   A  GDEDG  A                   BBBA  ", "  AABC                   A  GDDDG  A                   CBAA  ", "  AAAA                   F   GGG   F                   AAAA  ", "                          F       F                          ", "                           F     F                           ", "                            FAAAF                            ", "                                                             ", "                                                             ", "                                                             ")
                    .aisle("                                                             ", "                                                             ", "                            FAAAF                            ", "                           F     F                           ", "                          F       F                          ", "                         F         F                         ", "   AAA                  F    GGG    F                  AAA   ", "  AABC                  A   GDDDG   A                  CBAA  ", "  ABBB                  A   GDEDG   A                  BBBA  ", "  AABC                  A   GDDDG   A                  CBAA  ", "  AAAA                  F    GGG    F                  AAAA  ", "                         F         F                         ", "                          F       F                          ", "                           F     F                           ", "                            FAAAF                            ", "                                                             ", "                                                             ")
                    .aisle("                                                             ", "                            FAAAF                            ", "                           F     F                           ", "                          F       F                          ", "                         F         F                         ", "                        F           F                        ", "  AAA                  F     GGG     F                  AAA  ", " AABC                  A    GDDDG    A                  CBAA ", " ABBB                  A    GDEDG    A                  BBBA ", " AABC                  A    GDDDG    A                  CBAA ", " AAAA                  F     GGG     F                  AAAA ", "                        F           F                        ", "                         F         F                         ", "                          F       F                          ", "                           F     F                           ", "                            FAAAF                            ", "                                                             ")
                    .aisle("                            AAAAA                            ", "                           FA   AF                           ", "                          F       F                          ", "                         F         F                         ", "                        F           F                        ", "                       F             F                       ", "  AAA                 F      GGG      F                 AAA  ", " AABC                 A     GDDDG     A                 CBAA ", " ABBB                 A     GDEDG     A                 BBBA ", " AABC                 A     GDDDG     A                 CBAA ", " AAAA                 F      GGG      F                 AAAA ", "                       F             F                       ", "                        F           F                        ", "                         F         F                         ", "                          F       F                          ", "                           FAA  AF                           ", "                            AAAAA                            ")
                    .aisle("                           AAAAAAA                           ", "                          FA     AF                          ", "                         F         F                         ", "                        F           F                        ", "                       F             F                       ", "                      F      GGG      F                      ", "  AAA                F      GGGGG      F                AAA  ", " AABC                A     GGDDDGG     A                CBAA ", " ABBB                A     GGDEDGG     A                BBBA ", " AABC                A     GGDDDGG     A                CBAA ", " AAAA                F      GGGGG      F                AAAA ", "                      F      GGG      F                      ", "                       F             F                       ", "                        F           F                        ", "                         F         F                         ", "                          FA     AF                          ", "                           AAAAAAA                           ")
                    .aisle("                          AAAAAAAAA                          ", "                         FAA     AAF                         ", "                        F  AGGGGGA  F                        ", "                       F   GGGGGGG   F                       ", "                      F    GGGGGGG    F                      ", "                     F     GGGGGGG     F                     ", " AAAA               F      GGGGGGG      F               AAAA ", "AABCA               A     GGGDDDGGG     A               ACBAA", "ABBBA               A     GGGDEDGGG     A               ABBBA", "AABCA               A     GGGDDDGGG     A               ACBAA", " AAAA               F      GGGGGGG      F               AAAA ", "                     F     GGGGGGG     F                     ", "                      F    GGGGGGG    F                      ", "                       F   GGGGGGG   F                       ", "                        F  AGGGGGA  F                        ", "                         FAA     AAF                         ", "                          AAAAAAAAA                          ")
                    .aisle("                         AAAAAAAAAAA                         ", "                        FAA       AAF                        ", "                       F  AGGGGGGGA  F                       ", "                      F   GG     GG   F                      ", "                     F    GG     GG    F                     ", "  AA                F     GG     GG     F                AA  ", "AAAAA              F      GG     GG      F              AAAAA", "AABCAA             A     GG       GG     A             AACBAA", "ABBBAA             A     GG   E   GG     A             AABBBA", "AABCAA             A     GG       GG     A             AACBAA", "AAAAA              F      GG     GG      F              AAAAA", "  AA                F     GG     GG     F                AA  ", "                     F    GG     GG    F                     ", "                      F   GG     GG   F                      ", "                       F  AGGGGGGGA  F                       ", "                        FAA       AAF                        ", "                         AAAAAAAAAAA                         ")
                    .aisle("                        AAAAAAAAAAAAA                        ", "                       FA           AF                       ", "                      F   GGGGGGGGG   F                      ", "                     F    G       G    F                     ", "                    F     G       G     F                    ", " AAAA              F      G       G      F              AAAA ", "AAAAAA            F      GG       GG      F            AAAAAA", "AABCAA            AGGGGGGGG       GGGGGGGGA            AACBAA", "ABBBAA            AGGGGGGGG   E   GGGGGGGGA            AABBBA", "AABCAA            AGGGGGGGG       GGGGGGGGA            AACBAA", "AAAAAA            F      GG       GG      F            AAAAAA", " AAAA              F      G       G      F              AAAA ", "                    F     G       G     F                    ", "                     F    G       G    F                     ", "                      F   GGGGGGGGG   F                      ", "                       FA           AF                       ", "                        AAAAAAAAAAAAA                        ")
                    .aisle("                        AAAAAAAAAAAAA                        ", "                       A             A                       ", "                      A   GGGGGGGGG   A                      ", "                     A    G       G    A                     ", "                    A     G       G     A                    ", " AAAA              A     GG       GG     A              AAAA ", "AAAAAA            AGGGGGGGG       GGGGGGGGA            AAAAAA", "AABCDDDDDDDDDDDDDDDDDDDDDDD       DDDDDDDDDDDDDDDDDDDDDDDCBAA", "ABBBDDDDDDDDDDDDDDDDDDDDDDD   E   DDDDDDDDDDDDDDDDDDDDDDDBBBA", "AABCDDDDDDDDDDDDDDDDDDDDDDD       DDDDDDDDDDDDDDDDDDDDDDDCBAA", "AAAAAA            AGGGGGGGG       GGGGGGGGA            AAAAAA", " AAAA              A     GG       GG     A              AAAA ", "                    A     G       G     A                    ", "                     A    G       G    A                     ", "                      A   GGGGGGGGG   A                      ", "                       A            AA                       ", "                        AAAAAAAAAAAAA                        ")
                    .aisle("                        AAAAAAAAAAAAA                        ", "                       A             A                       ", "                      A   GGGGGGGGG   A                      ", "                     A    G       G    A                     ", "                    A     G       G     A                    ", " AAAA              A     GG       GG     A              AAAA ", "AAAAAA            AGGGGGGGG       GGGGGGGGA            AAAAAA", "AABCDDDDDDDDDDDDDDDDDDDDDDD       DDDDDDDDDDDDDDDDDDDDDDDCBAA", "ABBBEEEEEEEEEEEEEEEEEEEEEEEEEEEEEEEEEEEEEEEEEEEEEEEEEEEEEBBBA", "AABCDDDDDDDDDDDDDDDDDDDDDDD       DDDDDDDDDDDDDDDDDDDDDDDCBAA", "AAAAAA            AGGGGGGGG       GGGGGGGGA            AAAAAA", " AAAA              A     GG       GG     A              AAAA ", "                    A     G       G     A                    ", "                     A    G       G    A                     ", "                      A   GGGGGGGGG   A                      ", "                       A            AA                       ", "                        AAAAAAAAAAAAA                        ")
                    .aisle("                        AAAAAAAAAAAAA                        ", "                       A             A                       ", "                      A   GGGGGGGGG   A                      ", "                     A    G       G    A                     ", "                    A     G       G     A                    ", " AAAA              A     GG       GG     A              AAAA ", "AAAAAA            AGGGGGGGG       GGGGGGGGA            AAAAAA", "AABCDDDDDDDDDDDDDDDDDDDDDDD       DDDDDDDDDDDDDDDDDDDDDDDCBAA", "ABBBDDDDDDDDDDDDDDDDDDDDDDD   E   DDDDDDDDDDDDDDDDDDDDDDDBBBA", "AABCDDDDDDDDDDDDDDDDDDDDDDD       DDDDDDDDDDDDDDDDDDDDDDDCBAA", "AAAAAA            AGGGGGGGG       GGGGGGGGA            AAAAAA", " AAAA              A     GG       GG     A              AAAA ", "                    A     G       G     A                    ", "                     A    G       G    A                     ", "                      A   GGGGGGGGG   A                      ", "                       A            AA                       ", "                        AAAAAAAAAAAAA                        ")
                    .aisle("                        AAAAAAAAAAAAA                        ", "                       FA           AF                       ", "                      F   GGGGGGGGG   F                      ", "                     F    G       G    F                     ", "                    F     G       G     F                    ", " AAAA              F      G       G      F              AAAA ", "AAAAAA            F      GG       GG      F            AAAAAA", "AABCAA            AGGGGGGGG       GGGGGGGGA            AACBAA", "ABBBAA            AGGGGGGGG   E   GGGGGGGGA            AABBBA", "AABCAA            AGGGGGGGG       GGGGGGGGA            AACBAA", "AAAAAA            F      GG       GG      F            AAAAAA", " AAAA              F      G       G      F              AAAA ", "                    F     G       G     F                    ", "                     F    G       G    F                     ", "                      F   GGGGGGGGG   F                      ", "                       FA           AF                       ", "                        AAAAAAAAAAAAA                        ")
                    .aisle("                         AAAAAAAAAAA                         ", "                        FAA       AAF                        ", "                       F  AGGGGGGGA  F                       ", "                      F   GG     GG   F                      ", "                     F    GG     GG    F                     ", "  AA                F     GG     GG     F                AA  ", "AAAAA              F      GG     GG      F              AAAAA", "AABCAA             A     GG       GG     A             AACBAA", "ABBBAA             A     GG   E   GG     A             AABBBA", "AABCAA             A     GG       GG     A             AACBAA", "AAAAA              F      GG     GG      F              AAAAA", "  AA                F     GG     GG     F                AA  ", "                     F    GG     GG    F                     ", "                      F   GG     GG   F                      ", "                       F  AGGGGGGGA  F                       ", "                        FAA       AAF                        ", "                         AAAAAAAAAAA                         ")
                    .aisle("                          AAAAAAAAA                          ", "                         FAA     AAF                         ", "                        F  AGGGGGA  F                        ", "                       F   GGGGGGG   F                       ", "                      F    GGGGGGG    F                      ", "                     F     GGGGGGG     F                     ", " AAAA               F      GGGGGGG      F               AAAA ", "AABCA               A     GGGDDDGGG     A               ACBAA", "ABBBA               A     GGGDEDGGG     A               ABBBA", "AABCA               A     GGGDDDGGG     A               ACBAA", " AAAA               F      GGGGGGG      F               AAAA ", "                     F     GGGGGGG     F                     ", "                      F    GGGGGGG    F                      ", "                       F   GGGGGGG   F                       ", "                        F  AGGGGGA  F                        ", "                         FAA     AAF                         ", "                          AAAAAAAAA                          ")
                    .aisle("                           AAAAAAA                           ", "                          FA     AF                          ", "                         F         F                         ", "                        F           F                        ", "                       F             F                       ", "                      F      GGG      F                      ", "  AAA                F      GGGGG      F                AAA  ", " AABC                A     GGDDDGG     A                CBAA ", " ABBB                A     GGDEDGG     A                BBBA ", " AABC                A     GGDDDGG     A                CBAA ", " AAAA                F      GGGGG      F                AAAA ", "                      F      GGG      F                      ", "                       F             F                       ", "                        F           F                        ", "                         F         F                         ", "                          FA     AF                          ", "                           AAAAAAA                           ")
                    .aisle("                            AAAAA                            ", "                           FA   AF                           ", "                          F       F                          ", "                         F         F                         ", "                        F           F                        ", "                       F             F                       ", "  AAA                 F      GGG      F                 AAA  ", " AABC                 A     GDDDG     A                 CBAA ", " ABBB                 A     GDEDG     A                 BBBA ", " AABC                 A     GDDDG     A                 CBAA ", " AAAA                 F      GGG      F                 AAAA ", "                       F             F                       ", "                        F           F                        ", "                         F         F                         ", "                          F       F                          ", "                           FA   AF                           ", "                            AAAAA                            ")
                    .aisle("                                                             ", "                            FAAAF                            ", "                           F     F                           ", "                          F       F                          ", "                         F         F                         ", "                        F           F                        ", "  AAA                  F     GGG     F                  AAA  ", " AABC                  A    GDDDG    A                  CBAA ", " ABBB                  A    GDEDG    A                  BBBA ", " AABC                  A    GDDDG    A                  CBAA ", " AAAA                  F     GGG     F                  AAAA ", "                        F           F                        ", "                         F         F                         ", "                          F       F                          ", "                           F     F                           ", "                            FAAAF                            ", "                                                             ")
                    .aisle("                                                             ", "                                                             ", "                            FAAAF                            ", "                           F     F                           ", "                          F       F                          ", "                         F         F                         ", "   AAA                  F    GGG    F                  AAA   ", "  AABC                  A   GDDDG   A                  CBAA  ", "  ABBB                  A   GDEDG   A                  BBBA  ", "  AABC                  A   GDDDG   A                  CBAA  ", "  AAAA                  F    GGG    F                  AAAA  ", "                         F         F                         ", "                          F       F                          ", "                           F     F                           ", "                            FAAAF                            ", "                                                             ", "                                                             ")
                    .aisle("                                                             ", "                                                             ", "                                                             ", "                            FAAAF                            ", "                           F     F                           ", "                          F       F                          ", "   AAA                   F   GGG   F                   AAA   ", "  AABC                   A  GDDDG  A                   CBAA  ", "  ABBB                   A  GDEDG  A                   BBBA  ", "  AABC                   A  GDDDG  A                   CBAA  ", "  AAAA                   F   GGG   F                   AAAA  ", "                          F       F                          ", "                           F     F                           ", "                            FAAAF                            ", "                                                             ", "                                                             ", "                                                             ")
                    .aisle("                                                             ", "                                                             ", "                                                             ", "                                                             ", "                            FAAAF                            ", "                           F     F                           ", "   AAA                    F  GGG  F                    AAA   ", "  AABC                    A GDDDG A                    CBAA  ", "  ABBB                    A GDEDG A                    BBBA  ", "  AABC                    A GDDDG A                    CBAA  ", "  AAAA                    F  GGG  F                    AAAA  ", "                           F     F                           ", "                            FAAAF                            ", "                                                             ", "                                                             ", "                                                             ", "                                                             ")
                    .aisle("                                                             ", "                                                             ", "                                                             ", "                                                             ", "                                                             ", "                            FAAAF                            ", "    AAA                    F GGG F                    AAA    ", "   AABC                    AGDDDGA                    CBAA   ", "   ABBB                    AGDEDGA                    BBBA   ", "   AABC                    AGDDDGA                    CBAA   ", "   AAAA                    F GGG F                    AAAA   ", "                            FAAAF                            ", "                                                             ", "                                                             ", "                                                             ", "                                                             ", "                                                             ")
                    .aisle("                                                             ", "                                                             ", "                                                             ", "                                                             ", "                                                             ", "                                                             ", "    AAA                     FAAAF                     AAA    ", "   AABC                     ADDDA                     CBAA   ", "   ABBB                     ADEDA                     BBBA   ", "   AABC                     ADDDA                     CBAA   ", "   AAAA                     FAAAF                     AAAA   ", "                                                             ", "                                                             ", "                                                             ", "                                                             ", "                                                             ", "                                                             ")
                    .aisle("                                                             ", "                                                             ", "                                                             ", "                                                             ", "                                                             ", "                                                             ", "     AAA                                             AAA     ", "    AABC                     DDD                     CBAA    ", "    ABBB                     DED                     BBBA    ", "    AABC                     DDD                     CBAA    ", "    AAAA                                             AAAA    ", "                                                             ", "                                                             ", "                                                             ", "                                                             ", "                                                             ", "                                                             ")
                    .aisle("                                                             ", "                                                             ", "                                                             ", "                                                             ", "                                                             ", "                                                             ", "     A A                                             AAA     ", "    AABC                     DDD                     CBAA    ", "    ABBB                     DED                     BBBA    ", "    AABC                     DDD                     CBAA    ", "    AAAA                                             AAAA    ", "                                                             ", "                                                             ", "                                                             ", "                                                             ", "                                                             ", "                                                             ")
                    .aisle("                                                             ", "                                                             ", "                                                             ", "                                                             ", "                                                             ", "                                                             ", "      AAA                                           AAA      ", "     AABC                    DDD                    CBAA     ", "     ABBB                    DED                    BBBA     ", "     AABC                    DDD                    CBAA     ", "     AAAA                                           AAAA     ", "                                                             ", "                                                             ", "                                                             ", "                                                             ", "                                                             ", "                                                             ")
                    .aisle("                                                             ", "                                                             ", "                                                             ", "                                                             ", "                                                             ", "                                                             ", "      AAA                                           AAA      ", "     AABC                    DDD                    CBAA     ", "     ABBB                    DED                    BBBA     ", "     AABC                    DDD                    CBAA     ", "     AAAA                                           AAAA     ", "                                                             ", "                                                             ", "                                                             ", "                                                             ", "                                                             ", "                                                             ")
                    .aisle("                                                             ", "                                                             ", "                                                             ", "                                                             ", "                                                             ", "                                                             ", "       AAA                                         AAA       ", "      AABC                   DDD                   CBAA      ", "      ABBB                   DED                   BBBA      ", "      AABC                   DDD                   CBAA      ", "      AAAA                                         AAAA      ", "                                                             ", "                                                             ", "                                                             ", "                                                             ", "                                                             ", "                                                             ")
                    .aisle("                                                             ", "                                                             ", "                                                             ", "                                                             ", "                                                             ", "                                                             ", "        AAA                                       AAA        ", "       AABC                  DDD                  CBAA       ", "       ABBB                  DED                  BBBA       ", "       AABC                  DDD                  CBAA       ", "       AAAA                                       AAAA       ", "                                                             ", "                                                             ", "                                                             ", "                                                             ", "                                                             ", "                                                             ")
                    .aisle("                                                             ", "                                                             ", "                                                             ", "                                                             ", "                                                             ", "                                                             ", "         AAA                                     AAA         ", "        AABC                 DDD                 CBAA        ", "        ABBB                 DED                 BBBA        ", "        AABC                 DDD                 CBAA        ", "        AAAA                                     AAAA        ", "                                                             ", "                                                             ", "                                                             ", "                                                             ", "                                                             ", "                                                             ")
                    .aisle("                                                             ", "                                                             ", "                                                             ", "                                                             ", "                                                             ", "                                                             ", "          AAA                                   AAA          ", "         AABC                DDD                CBAA         ", "         ABBB                DED                BBBA         ", "         AABC                DDD                CBAA         ", "         AAAA                                   AAAA         ", "                                                             ", "                                                             ", "                                                             ", "                                                             ", "                                                             ", "                                                             ")
                    .aisle("                                                             ", "                                                             ", "                                                             ", "                                                             ", "                                                             ", "                                                             ", "           AAA                                 AAA           ", "          AABC               DDD               CBAA          ", "          ABBB               DED               BBBA          ", "          AABC               DDD               CBAA          ", "          AAAA                                 AAAA          ", "                                                             ", "                                                             ", "                                                             ", "                                                             ", "                                                             ", "                                                             ")
                    .aisle("                                                             ", "                                                             ", "                                                             ", "                                                             ", "                                                             ", "                                                             ", "            AAAA                             AAAA            ", "           AABCC             DDD             CCBAA           ", "           ABBBB             DED             BBBBA           ", "           AABCC             DDD             CCBAA           ", "           AAAAA                             AAAAA           ", "                                                             ", "                                                             ", "                                                             ", "                                                             ", "                                                             ", "                                                             ")
                    .aisle("                                                             ", "                                                             ", "                                                             ", "                                                             ", "                                                             ", "                                                             ", "             AAAAA                         AAAAA             ", "            AABBCC           DDD           CCBBAA            ", "            ABBBBB           DED           BBBBBA            ", "            AABBCC           DDD           CCBBAA            ", "            AAAAAA                         AAAAAA            ", "                                                             ", "                                                             ", "                                                             ", "                                                             ", "                                                             ", "                                                             ")
                    .aisle("                                                             ", "                                                             ", "                                                             ", "                                                             ", "                                                             ", "                                                             ", "              AAAAAA                     AAAAAA              ", "             AAABBCC         DDD         CCBBAAA             ", "             ABBBBBB         DED         BBBBBBA             ", "             AAABBCC         DDD         CCBBAAA             ", "             AAAAAAA                     AAAAAAA             ", "                                                             ", "                                                             ", "                                                             ", "                                                             ", "                                                             ", "                                                             ")
                    .aisle("                                                             ", "                                                             ", "                                                             ", "                                                             ", "                                                             ", "                                                             ", "                AAAAAAA     AAAAA     AAAAAAA                ", "              AAAABBCCC    AADDDAA    CCCBBAAAA              ", "              AABBBBBBB    AADEDAA    BBBBBBBAA              ", "              AAAABBCCC    AADDDAA    CCCBBAAAA              ", "              AAAAAAAAA     AAAAA     AAAAAAAAA              ", "                                                             ", "                                                             ", "                                                             ", "                                                             ", "                                                             ", "                                                             ")
                    .aisle("                                                             ", "                                                             ", "                                                             ", "                                                             ", "                                                             ", "                            AAAAA                            ", "                  AAAAAAAAAAAAAAAAAAAAAAAAA                  ", "                AAAABBBCCCAAADDDAAACCCBBBAAAA                ", "                AABBBBBBBBAAADEDAAABBBBBBBBAA                ", "                AAAABBBCCCAAADDDAAACCCBBBAAAA                ", "                AAAAAAAAAAAAAAAAAAAAAAAAAAAAA                ", "                            AAAAA                            ", "                                                             ", "                                                             ", "                                                             ", "                                                             ", "                                                             ")
                    .aisle("                                                             ", "                                                             ", "                                                             ", "                                                             ", "                                                             ", "                           AAAAAAA                           ", "                    AAAAAAAAAAAAAAAAAAAAA                    ", "                  AAAAABBBCCCCCCCCCBBBAAAAA                  ", "                  AABBBBBBBBBBBBBBBBBBBBBAA                  ", "                  AAAAABBBCCCCCCCCCBBBAAAAA                  ", "                  AAAAAAAAAAAAAAAAAAAAAAAAA                  ", "                           AAAAAAA                           ", "                                                             ", "                                                             ", "                                                             ", "                                                             ", "                                                             ")
                    .aisle("                                                             ", "                                                             ", "                                                             ", "                                                             ", "                                                             ", "                           AAAAAAA                           ", "                       AAAAAAAAAAAAAAA                       ", "                    AAAAAABBBBBBBBBAAAAAA                    ", "                    AAABBBBBBBBBBBBBBBAAA                    ", "                    AAAAAABBBBBBBBBAAAAAA                    ", "                    AAAAAAAAAAAAAAAAAAAAA                    ", "                           AAAAAAA                           ", "                                                             ", "                                                             ", "                                                             ", "                                                             ", "                                                             ")
                    .aisle("                                                             ", "                                                             ", "                                                             ", "                                                             ", "                                                             ", "                            AAAAA                            ", "                          AAAAAAAAA                          ", "                       AAAAAAAAAAAAAAA                       ", "                       AAABBBBBBBBBAAA                       ", "                       AAAAAAAAAAAAAAA                       ", "                       AAAAAAAAAAAAAAA                       ", "                            AAAAA                            ", "                                                             ", "                                                             ", "                                                             ", "                                                             ", "                                                             ")
                    .aisle("                                                             ", "                                                             ", "                                                             ", "                                                             ", "                                                             ", "                                                             ", "                           IIIIIII                           ", "                          IIIIIIIII                          ", "                          IIII~IIII                          ", "                          IIIIIIIII                          ", "                           IIIIIII                           ", "                                                             ", "                                                             ", "                                                             ", "                                                             ", "                                                             ", "                                                             ").where('~', controller(blocks(definition.get())))
                    .where('A', blocks(GTOBlocks.MOLECULAR_CASING.get()))
                    .where('I', blocks(GTOBlocks.MOLECULAR_CASING.get()).or(GTOPredicates.autoThreadLaserAbilities(definition.getRecipeTypes())))
                    .where('B', blocks(GTOBlocks.MOLECULAR_COIL.get()))
                    .where('C', blocks(GTOBlocks.CONTAINMENT_FIELD_GENERATOR.get()))
                    .where('D', blocks(GTBlocks.HIGH_POWER_CASING.get()))
                    .where('E', blocks(GTOBlocks.HOLLOW_CASING.get()))
                    .where('F', blocks(GTOBlocks.FORCE_FIELD_GLASS.get()))
                    .where('G', blocks(GTOBlocks.ULTIMATE_STELLAR_CONTAINMENT_CASING.get()))
                    .where(' ', any())
                    .build())
            .workableCasingRenderer(GTOCore.id("block/casings/molecular_casing"), GTCEu.id("block/multiblock/fusion_reactor"))
            .register();
}
