package com.gtocore.common.data.machines;

import com.gtocore.api.pattern.GTOPredicates;
import com.gtocore.common.data.GTOBlocks;
import com.gtocore.common.data.GTOMaterials;
import com.gtocore.common.data.GTORecipeTypes;
import com.gtocore.common.machine.multiblock.electric.processing.CompoundExtremeCoolingMachine;

import com.gtolib.GTOCore;
import com.gtolib.api.machine.multiblock.CoilCrossRecipeMultiblockMachine;
import com.gtolib.api.machine.multiblock.CrossRecipeMultiblockMachine;
import com.gtolib.api.machine.multiblock.CustomParallelMultiblockMachine;
import com.gtolib.api.machine.multiblock.ElectricMultiblockMachine;
import com.gtolib.api.recipe.modifier.RecipeModifierFunction;
import com.gtolib.utils.MachineUtils;
import com.gtolib.utils.MultiBlockFileReader;

import com.gregtechceu.gtceu.GTCEu;
import com.gregtechceu.gtceu.api.data.chemical.ChemicalHelper;
import com.gregtechceu.gtceu.api.data.tag.TagPrefix;
import com.gregtechceu.gtceu.api.machine.MultiblockMachineDefinition;
import com.gregtechceu.gtceu.api.pattern.FactoryBlockPattern;
import com.gregtechceu.gtceu.api.pattern.MultiblockShapeInfo;
import com.gregtechceu.gtceu.api.pattern.util.RelativeDirection;
import com.gregtechceu.gtceu.common.data.*;

import java.util.ArrayList;
import java.util.List;

import static com.gregtechceu.gtceu.api.machine.multiblock.PartAbility.*;
import static com.gregtechceu.gtceu.api.pattern.Predicates.*;
import static com.gtolib.utils.register.MachineRegisterUtils.multiblock;

public final class MultiBlockF {

    public static void init() {}

    public static final MultiblockMachineDefinition SUPER_BLAST_SMELTER = multiblock("super_blast_smelter", "超级冶炼炉", CoilCrossRecipeMultiblockMachine.createHatchParallel(true))
            .nonYAxisRotation()
            .tooltipsKey("gtceu.machine.electric_blast_furnace.tooltip.2")
            .parallelizableTooltips()
            .laserTooltips()
            .multipleRecipesTooltips()
            .recipeTypes(GTRecipeTypes.BLAST_RECIPES)
            .recipeTypes(GCYMRecipeTypes.ALLOY_BLAST_RECIPES)
            .block(GCYMBlocks.CASING_HIGH_TEMPERATURE_SMELTING)
            .pattern(definition -> FactoryBlockPattern.start(RelativeDirection.FRONT, RelativeDirection.UP, RelativeDirection.RIGHT)
                    .aisle("    AAAAAAAAAAAAAAA    ", "    AAAAAAAAAAAAAAA    ", "      AA       AA      ", "      AA       AA      ", "      AA       AA      ", "      AA       AA      ", "                       ", "                       ", "                       ", "                       ", "                       ", "                       ", "                       ", "                       ", "                       ", "                       ", "                       ", "                       ", "                       ", "                       ", "                       ", "                       ", "                       ", "                       ", "                       ", "                       ", "                       ", "                       ", "                       ", "                       ", "                       ", "                       ", "                       ", "                       ", "                       ", "                       ", "                       ", "                       ", "                       ", "                       ", "                       ", "                       ", "                       ")
                    .aisle("   AAAAAAAAAAAAAAAAA   ", "   AAAAAAAAAAAAAAAAA   ", "      AA  AAA  AA      ", "      AA  AAA  AA      ", "      AA  AAA  AA      ", "      AA  AAA  AA      ", "      AA       AA      ", "      AA       AA      ", "      AA       AA      ", "      AA       AA      ", "                       ", "                       ", "                       ", "                       ", "                       ", "                       ", "                       ", "                       ", "                       ", "                       ", "                       ", "                       ", "                       ", "                       ", "                       ", "                       ", "                       ", "                       ", "                       ", "                       ", "                       ", "                       ", "                       ", "                       ", "                       ", "                       ", "                       ", "                       ", "                       ", "                       ", "                       ", "                       ", "                       ")
                    .aisle("  AAAAAAAAAAAAAAAAAAA  ", "  AAAAAAAAAAAAAAAAAAA  ", "      AA  AAA  AA      ", "      AA  AAA  AA      ", "      AA  AAA  AA      ", "      AA  AAA  AA      ", "      AA  AAA  AA      ", "      AA  AAA  AA      ", "      AA  AAA  AA      ", "      AA       AA      ", "      AA       AA      ", "      AA       AA      ", "      AA       AA      ", "                       ", "                       ", "                       ", "                       ", "                       ", "                       ", "                       ", "                       ", "                       ", "                       ", "                       ", "                       ", "                       ", "                       ", "                       ", "                       ", "                       ", "                       ", "                       ", "                       ", "                       ", "                       ", "                       ", "                       ", "                       ", "                       ", "                       ", "                       ", "                       ", "                       ")
                    .aisle(" AAAAAAAAAAAAAAAAAAAAA ", " AAAAAAAAAAAAAAAAAAAAA ", "   ABBBBBBBBBBBBBBBA   ", "   ACCCCCCCCCCCCCCCA   ", "   ABBBBBBBBBBBBBBBA   ", "   AAAAAAAAAAAAAAAAA   ", "    A AA  AAA  AA A    ", "    A AA  AAA  AA A    ", "    A AA  AAA  AA A    ", "    AAAAAAAAAAAAAAA    ", "      AA       AA      ", "      AA       AA      ", "      AA       AA      ", "      AA       AA      ", "      AA       AA      ", "      AA       AA      ", "      AA       AA      ", "                       ", "                       ", "                       ", "                       ", "                       ", "                       ", "                       ", "                       ", "                       ", "                       ", "                       ", "                       ", "                       ", "                       ", "                       ", "                       ", "                       ", "                       ", "                       ", "                       ", "                       ", "                       ", "         AAAAA         ", "         AAAAA         ", "         DDDDD         ", "                       ")
                    .aisle("AAAAAAAAAAAAAAAAAAAAAAa", "AAAAAAAAAAAAAAAAAAAAAAa", "   BEEEEEEEEEEEEEEEB   ", "   CFFFFFFFGFFFFFFFC   ", "   BHHHHHHHHHHHHHHHB   ", "   AAAAAAAAAAAAAAAAA   ", "    ABBBBBBBBBBBBBAA   ", "    AIIIIIIIIIIIIIAA   ", "    ABBBBBBBBBBBBBAA   ", "   AAAAAAAAAAAAAAAAA   ", "     AAAAAAAAAAAAA     ", "     AAAAAAAAAAAAA     ", "     AAA       AAA     ", "     AAA       AAA     ", "     AAA       AAA     ", "     AAAAAAAAAAAAA     ", "     AAAAAAAAAAAAA     ", "    JJJJJJJJJJJJJJJ    ", "        JAAAAAJ        ", "        J     J        ", "        JAAAAAJ        ", "        J     J        ", "        JAAAAAJ        ", "        J     J        ", "        JAAAAAJ        ", "        J     J        ", "        JAAAAAJ        ", "                       ", "                       ", "         AAAAA         ", "         AAAAA         ", "                       ", "         AAAAA         ", "                       ", "         AAAAA         ", "                       ", "         AAAAA         ", "                       ", "         AAAAA         ", "      AAAAAAAAAAA      ", "      AAAAAAAAAAA      ", "      DDD D D DDD      ", "                       ")
                    .aisle("AAAAAAAAAAAAAAAAAAAAAAa", "AAAAAAAAAAAAAAAAAAAAAAa", "   BEEEEEEEEEEEEEEEB   ", "   CFFFFFFFGFFFFFFFC   ", "   BHHHHHHHHHHHHHHHB   ", "   AAKKKKKKKKKKKKKAA   ", "    BLLLLLLLLLLLLLB    ", "    IMMMMMMNMMMMMMI    ", "    BOOOOOOOOOOOOOB    ", "   AAPPPPPPPPPPPPPAA   ", "    AAAAAAAAAAAAAAA    ", "    AAQQQQQQQQQQQAA    ", "    AAQQQQQQQQQQQAA    ", "    AABBBBBBBBBBBAA    ", "    AAQQQQQQQQQQQAA    ", "    AAQQQQQQQQQQQAA    ", "    AAAAAAAAAAAAAAA    ", "    J AAAAAAAAAAA J    ", "      AAAAAAAAAAA      ", "      A  QQQQQ  A      ", "      AAAAAAAAAAA      ", "      A  QQQQQ  A      ", "      AAAAAAAAAAA      ", "      A  QQQQQ  A      ", "      AAAAAAAAAAA      ", "      A  QQQQQ  A      ", "      AAAAAAAAAAA      ", "      AAAAAAAAAAA      ", "         DDDDD         ", "        AA   AA        ", "        AAQQQAA        ", "          QQQ          ", "        AAQQQAA        ", "          QQQ          ", "        AAQQQAA        ", "          QQQ          ", "        AAQQQAA        ", "          QQQ          ", "        AAQQQAA        ", "     AAAAAAAAAAAAA     ", "     AAAAAAAAAAAAA     ", "     D   RD DR   D     ", "                       ")
                    .aisle("AAAAAAAAAAAAAAAAAAAAAAa", "AAAAAAAAAAAAAAAAAAAAAAa", "AAABEEEEEEEEEEEEEEEBAAA", "AAACFFFFFFFGFFFFFFFCAAA", "AAABHHHHHHHHHHHHHHHBAAA", "AAAAAKKKKKKKKKKKKKAAAAA", " AAABLLLLLLLLLLLLLBAAA ", " AAAIMMMMMMNMMMMMMIAAA ", " AAABOOOOOOOOOOOOOBAAA ", " AAAAPPPPPPPPPPPPPAAAA ", "  AAAA           AAAA  ", "  AAAQ           QAAA  ", "  AAAQQ         QQAAA  ", "   AABQ         QBAA   ", "   AAQQ         QQAA   ", "   AAQQ         QQAA   ", "   AAAQ         QAAA   ", "    JAAAAAAAAAAAAAJ    ", "     AAQQQQQQQQQAA     ", "     AAQQQQQQQQQAA     ", "     AAQQQQQQQQQAA     ", "     AAQQQQQQQQQAA     ", "     AAQQQQQQQQQAA     ", "     AAQQQQQQQQQAA     ", "     AAQQQQQQQQQAA     ", "     AAQQQQQQQQQAA     ", "     AAQQQQQQQQQAA     ", "     AAAAAAAAAAAAA     ", "      J DD   DD J      ", "      JAA     AAJ      ", "      JAAQ   QAAJ      ", "      J  Q   Q  J      ", "      JAAQ   QAAJ      ", "      J  Q   Q  J      ", "      JAAQ   QAAJ      ", "      J  Q   Q  J      ", "      JAAQ   QAAJ      ", "      J  Q   Q  J      ", "      JAAQ   QAAJ      ", "    AAAAAAAAAAAAAAA    ", "    AAAAAAAAAAAAAAA    ", "    D   JJJJJJJ   D    ", "         R   R         ")
                    .aisle("AAAAAAAAAAAAAAAAAAAAAAa", "AAAAAAAAAAAAAAAAAAAAAAa", "AAABEEEEEEEEEEEEEEEBAAA", "AAACFFFFFFFGFFFFFFFCAAA", "AAABHHHHHHHHHHHHHHHBAAA", "AAAAAKKKKKKKKKKKKKAAAAA", " AAABLLLLLLLLLLLLLBAAA ", " AAAIMMMMMMNMMMMMMIAAA ", " AAABOOOOOOOOOOOOOBAAA ", " AAAAPPPPPPPPPPPPPAAAA ", "  AAAA           AAAA  ", "  AAAQ           QAAA  ", "  AAAQ           QAAA  ", "   AAB           BAA   ", "   AAQ           QAA   ", "   AAQ           QAA   ", "   AAA           AAA   ", "    JAAQ       QAAJ    ", "     AQ         QA     ", "      Q         Q      ", "     AQ         QA     ", "      Q         Q      ", "     AQ         QA     ", "      Q         Q      ", "     AQ         QA     ", "      Q         Q      ", "     AQQQ     QQQA     ", "     AA         AA     ", "       DD     DD       ", "      AA       AA      ", "      AAQ     QAA      ", "        Q     Q        ", "      AAQ     QAA      ", "        Q     Q        ", "      AAQ     QAA      ", "        Q     Q        ", "      AAQ     QAA      ", "        Q     Q        ", "      AAQ     QAA      ", "    AAAAA     AAAAA    ", "    AAAAA     AAAAA    ", "    D  JJJJJJJJJ  D    ", "         R   R         ")
                    .aisle("AAAAAAAAAAAAAAAAAAAAAAa", "AAAAAAAAAAAAAAAAAAAAAAa", "   BEEEEEEEEEEEEEEEB   ", "   CFFFFFFFGFFFFFFFC   ", "   BHHHHHHHHHHHHHHHB   ", "   AAKKKKKKKKKKKKKAA   ", "    BLLLLLLLLLLLLLB    ", "    IMMMMMMNMMMMMMI    ", "    BOOOOOOOOOOOOOB    ", "   AAPPPPPPPPPPPPPAA   ", "    AA           AA    ", "    AQ           QA    ", "     Q           Q     ", "     B           B     ", "     Q           Q     ", "    AQ           QA    ", "    AA           AA    ", "    JAA         AAJ    ", "    JAQ         QAJ    ", "    J Q         Q J    ", "    JAQ         QAJ    ", "    J Q         Q J    ", "    JAQ         QAJ    ", "    J Q         Q J    ", "    JAQ         QAJ    ", "    J Q         Q J    ", "    JAQQQ     QQQAJ    ", "     AA Q     Q AA     ", "      DDQ     QDD      ", "     AA Q     Q AA     ", "     AAQQ     QQAA     ", "       Q       Q       ", "     AAQ       QAA     ", "       Q       Q       ", "     AAQ       QAA     ", "       Q       Q       ", "     AAQ       QAA     ", "       Q       Q       ", "     AAQ       QAA     ", "    AAAA       AAAA    ", "    AAAA       AAAA    ", "    D JJJJJJJJJJJ D    ", "         R   R         ")
                    .aisle("AAAAAAAAAAAAAAAAAAAAAAa", "AAAAAAAAAAAAAAAAAAAAAAa", "   BEEEEEEEEEEEEEEEB   ", "   CFFFFFFFGFFFFFFFC   ", "   BHHHHHHHHHHHHHHHB   ", "   AAKKKKKKKKKKKKKAA   ", "    BLLLLLLLLLLLLLB    ", "    IMMMMMMNMMMMMMI    ", "    BOOOOOOOOOOOOOB    ", "   AAPPPPPPPPPPPPPAA   ", "    AA     P     AA    ", "    AQ     P     QA    ", "     Q     P     Q     ", "     B     P     B     ", "     Q     P     Q     ", "    AQ     P     QA    ", "    AA     P     AA    ", "    JAA    P    AAJ    ", "    AAQ         QAA    ", "     QQ         QQ     ", "    AAQ         QAA    ", "     QQ         QQ     ", "    AAQ         QAA    ", "     QQ         QQ     ", "    AAQ         QAA    ", "     QQ         QQ     ", "    AAQ         QAA    ", "     AA         AA     ", "     DD         DD     ", "    AA           AA    ", "    AAQ         QAA    ", "      Q         Q      ", "    AAQ         QAA    ", "      Q         Q      ", "    AAQ         QAA    ", "      Q         Q      ", "    AAQ         QAA    ", "      Q         Q      ", "    AAQ         QAA    ", "   AAAA         AAAA   ", "   AAAA         AAAA   ", "   D RJJJJJJJJJJJR D   ", "      RRRRRRRRRRR      ")
                    .aisle("AAAAAAAAAAAAAAAAAAAAAAa", "AAAAAAAAAAAAAAAAAAAAAAa", " AABEEEEEEEEEEEEEEEBAA ", " AACFFFFFFFGFFFFFFFCAA ", " AABHHHHHHHHHHHHHHHBAA ", " AAAAKKKKKKKKKKKKKAAAA ", "  AABLLLLLLLLLLLLLBAA  ", "  AAIMMMMMMNMMMMMMIAA  ", "  AABOOOOOOOOOOOOOBAA  ", "   AAPPPPPPPPPPPPPAA   ", "    AA           AA    ", "    AQ           QA    ", "     Q           Q     ", "     B           B     ", "     Q           Q     ", "    AQ           QA    ", "    AA           AA    ", "    JAA    P    AAJ    ", "    AAQ    P    QAA    ", "     QQ    P    QQ     ", "    AAQ    P    QAA    ", "     QQ    P    QQ     ", "    AAQ    P    QAA    ", "     QQ    P    QQ     ", "    AAQ    P    QAA    ", "     QQ    P    QQ     ", "    AAQ    P    QAA    ", "     AA    P    AA     ", "     D     P     D     ", "    A             A    ", "    AQ           QA    ", "     Q           Q     ", "    AQ           QA    ", "     Q           Q     ", "    AQ           QA    ", "     Q           Q     ", "    AQ           QA    ", "     Q           Q     ", "    AQ           QA    ", "   AAAA         AAAA   ", "   AAAA    P    AAAA   ", "   DDDJJJJJSJJJJJDDD   ", "         R   R         ")
                    .aisle("AAAAAAAAAAAAAAAAAAAAAAa", "AAAAAAAAAAAAAAAAAAAAAA~", " AABEEEEEEEEEEEEEEEBAA ", " AACGGGGGGGGGGGGGGGCAA ", " AABHHHHHHHHHHHHHHHBAA ", " AAAAKKKKKKKKKKKKKAAAA ", "  AABLLLLLLLLLLLLLBAA  ", "  AAINNNNNNNNNNNNNIAA  ", "  AABOOOOOOOOOOOOOBAA  ", "   AAPPPPPPPPPPPPPAA   ", "    AA   P P P   AA    ", "    AQ   P P P   QA    ", "     Q   P P P   Q     ", "     B   P P P   B     ", "     Q   P P P   Q     ", "    AQ   P P P   QA    ", "    AA   P P P   AA    ", "    JAA  PPPPP  AAJ    ", "    AAQ   P P   QAA    ", "     QQ   P P   QQ     ", "    AAQ   P P   QAA    ", "     QQ   P P   QQ     ", "    AAQ   P P   QAA    ", "     QQ   P P   QQ     ", "    AAQ   P P   QAA    ", "     QQ   P P   QQ     ", "    AAQ   P P   QAA    ", "     AA   P P   AA     ", "     D    PPP    D     ", "    A      P      A    ", "    AQ     P     QA    ", "     Q     P     Q     ", "    AQ     P     QA    ", "     Q     P     Q     ", "    AQ     P     QA    ", "     Q     P     Q     ", "    AQ     P     QA    ", "     Q     P     Q     ", "    AQ     P     QA    ", "   AAAA    P    AAAA   ", "   AAAA   PPP   AAAA   ", "   D  JJJJSSSJJJJ  D   ", "         R   R         ")
                    .aisle("AAAAAAAAAAAAAAAAAAAAAAa", "AAAAAAAAAAAAAAAAAAAAAAa", " AABEEEEEEEEEEEEEEEBAA ", " AACFFFFFFFGFFFFFFFCAA ", " AABHHHHHHHHHHHHHHHBAA ", " AAAAKKKKKKKKKKKKKAAAA ", "  AABLLLLLLLLLLLLLBAA  ", "  AAIMMMMMMNMMMMMMIAA  ", "  AABOOOOOOOOOOOOOBAA  ", "   AAPPPPPPPPPPPPPAA   ", "    AA           AA    ", "    AQ           QA    ", "     Q           Q     ", "     B           B     ", "     Q           Q     ", "    AQ           QA    ", "    AA           AA    ", "    JAA    P    AAJ    ", "    AAQ    P    QAA    ", "     QQ    P    QQ     ", "    AAQ    P    QAA    ", "     QQ    P    QQ     ", "    AAQ    P    QAA    ", "     QQ    P    QQ     ", "    AAQ    P    QAA    ", "     QQ    P    QQ     ", "    AAQ    P    QAA    ", "     AA    P    AA     ", "     D     P     D     ", "    A             A    ", "    AQ           QA    ", "     Q           Q     ", "    AQ           QA    ", "     Q           Q     ", "    AQ           QA    ", "     Q           Q     ", "    AQ           QA    ", "     Q           Q     ", "    AQ           QA    ", "   AAAA         AAAA   ", "   AAAA    P    AAAA   ", "   DDDJJJJJSJJJJJDDD   ", "         R   R         ")
                    .aisle("AAAAAAAAAAAAAAAAAAAAAAa", "AAAAAAAAAAAAAAAAAAAAAAa", "   BEEEEEEEEEEEEEEEB   ", "   CFFFFFFFGFFFFFFFC   ", "   BHHHHHHHHHHHHHHHB   ", "   AAKKKKKKKKKKKKKAA   ", "    BLLLLLLLLLLLLLB    ", "    IMMMMMMNMMMMMMI    ", "    BOOOOOOOOOOOOOB    ", "   AAPPPPPPPPPPPPPAA   ", "    AA     P     AA    ", "    AQ     P     QA    ", "     Q     P     Q     ", "     B     P     B     ", "     Q     P     Q     ", "    AQ     P     QA    ", "    AA     P     AA    ", "    JAA    P    AAJ    ", "    AAQ         QAA    ", "     QQ         QQ     ", "    AAQ         QAA    ", "     QQ         QQ     ", "    AAQ         QAA    ", "     QQ         QQ     ", "    AAQ         QAA    ", "     QQ         QQ     ", "    AAQ         QAA    ", "     AA         AA     ", "     DD         DD     ", "    AA           AA    ", "    AAQ         QAA    ", "      Q         Q      ", "    AAQ         QAA    ", "      Q         Q      ", "    AAQ         QAA    ", "      Q         Q      ", "    AAQ         QAA    ", "      Q         Q      ", "    AAQ         QAA    ", "   AAAA         AAAA   ", "   AAAA         AAAA   ", "   D RJJJJJJJJJJJR D   ", "      RRRRRRRRRRR      ")
                    .aisle("AAAAAAAAAAAAAAAAAAAAAAa", "AAAAAAAAAAAAAAAAAAAAAAa", "   BEEEEEEEEEEEEEEEB   ", "   CFFFFFFFGFFFFFFFC   ", "   BHHHHHHHHHHHHHHHB   ", "   AAKKKKKKKKKKKKKAA   ", "    BLLLLLLLLLLLLLB    ", "    IMMMMMMNMMMMMMI    ", "    BOOOOOOOOOOOOOB    ", "   AAPPPPPPPPPPPPPAA   ", "    AA           AA    ", "    AQ           QA    ", "     Q           Q     ", "     B           B     ", "     Q           Q     ", "    AQ           QA    ", "    AA           AA    ", "    JAA         AAJ    ", "    JAQ         QAJ    ", "    J Q         Q J    ", "    JAQ         QAJ    ", "    J Q         Q J    ", "    JAQ         QAJ    ", "    J Q         Q J    ", "    JAQ         QAJ    ", "    J Q         Q J    ", "    JAQQQ     QQQAJ    ", "     AA Q     Q AA     ", "      DDQ     QDD      ", "     AA Q     Q AA     ", "     AAQQ     QQAA     ", "       Q       Q       ", "     AAQ       QAA     ", "       Q       Q       ", "     AAQ       QAA     ", "       Q       Q       ", "     AAQ       QAA     ", "       Q       Q       ", "     AAQ       QAA     ", "    AAAA       AAAA    ", "    AAAA       AAAA    ", "    D JJJJJJJJJJJ D    ", "         R   R         ")
                    .aisle("AAAAAAAAAAAAAAAAAAAAAAa", "AAAAAAAAAAAAAAAAAAAAAAa", "AAABEEEEEEEEEEEEEEEBAAA", "AAACFFFFFFFGFFFFFFFCAAA", "AAABHHHHHHHHHHHHHHHBAAA", "AAAAAKKKKKKKKKKKKKAAAAA", " AAABLLLLLLLLLLLLLBAAA ", " AAAIMMMMMMNMMMMMMIAAA ", " AAABOOOOOOOOOOOOOBAAA ", " AAAAPPPPPPPPPPPPPAAAA ", "  AAAA           AAAA  ", "  AAAQ           QAAA  ", "  AAAQ           QAAA  ", "   AAB           BAA   ", "   AAQ           QAA   ", "   AAQ           QAA   ", "   AAA           AAA   ", "    JAAQ       QAAJ    ", "     AQ         QA     ", "      Q         Q      ", "     AQ         QA     ", "      Q         Q      ", "     AQ         QA     ", "      Q         Q      ", "     AQ         QA     ", "      Q         Q      ", "     AQQQ     QQQA     ", "     AA         AA     ", "       DD     DD       ", "      AA       AA      ", "      AAQ     QAA      ", "        Q     Q        ", "      AAQ     QAA      ", "        Q     Q        ", "      AAQ     QAA      ", "        Q     Q        ", "      AAQ     QAA      ", "        Q     Q        ", "      AAQ     QAA      ", "    AAAAA     AAAAA    ", "    AAAAA     AAAAA    ", "    D  JJJJJJJJJ  D    ", "         R   R         ")
                    .aisle("AAAAAAAAAAAAAAAAAAAAAAa", "AAAAAAAAAAAAAAAAAAAAAAa", "AAABEEEEEEEEEEEEEEEBAAA", "AAACFFFFFFFGFFFFFFFCAAA", "AAABHHHHHHHHHHHHHHHBAAA", "AAAAAKKKKKKKKKKKKKAAAAA", " AAABLLLLLLLLLLLLLBAAA ", " AAAIMMMMMMNMMMMMMIAAA ", " AAABOOOOOOOOOOOOOBAAA ", " AAAAPPPPPPPPPPPPPAAAA ", "  AAAA           AAAA  ", "  AAAQ           QAAA  ", "  AAAQQ         QQAAA  ", "   AABQ         QBAA   ", "   AAQQ         QQAA   ", "   AAQQ         QQAA   ", "   AAAQ         QAAA   ", "    JAAAAAAAAAAAAAJ    ", "     AAQQQQQQQQQAA     ", "     AAQQQQQQQQQAA     ", "     AAQQQQQQQQQAA     ", "     AAQQQQQQQQQAA     ", "     AAQQQQQQQQQAA     ", "     AAQQQQQQQQQAA     ", "     AAQQQQQQQQQAA     ", "     AAQQQQQQQQQAA     ", "     AAQQQQQQQQQAA     ", "     AAAAAAAAAAAAA     ", "      J DD   DD J      ", "      JAA     AAJ      ", "      JAAQ   QAAJ      ", "      J  Q   Q  J      ", "      JAAQ   QAAJ      ", "      J  Q   Q  J      ", "      JAAQ   QAAJ      ", "      J  Q   Q  J      ", "      JAAQ   QAAJ      ", "      J  Q   Q  J      ", "      JAAQ   QAAJ      ", "    AAAAAAAAAAAAAAA    ", "    AAAAAAAAAAAAAAA    ", "    D   JJJJJJJ   D    ", "         R   R         ")
                    .aisle("AAAAAAAAAAAAAAAAAAAAAAa", "AAAAAAAAAAAAAAAAAAAAAAa", "   BEEEEEEEEEEEEEEEB   ", "   CFFFFFFFGFFFFFFFC   ", "   BHHHHHHHHHHHHHHHB   ", "   AAKKKKKKKKKKKKKAA   ", "    BLLLLLLLLLLLLLB    ", "    IMMMMMMNMMMMMMI    ", "    BOOOOOOOOOOOOOB    ", "   AAPPPPPPPPPPPPPAA   ", "    AAAAAAAAAAAAAAA    ", "    AAQQQQQQQQQQQAA    ", "    AAQQQQQQQQQQQAA    ", "    AABBBBBBBBBBBAA    ", "    AAQQQQQQQQQQQAA    ", "    AAQQQQQQQQQQQAA    ", "    AAAAAAAAAAAAAAA    ", "    J AAAAAAAAAAA J    ", "      AAAAAAAAAAA      ", "      A  QQQQQ  A      ", "      AAAAAAAAAAA      ", "      A  QQQQQ  A      ", "      AAAAAAAAAAA      ", "      A  QQQQQ  A      ", "      AAAAAAAAAAA      ", "      A  QQQQQ  A      ", "      AAAAAAAAAAA      ", "      AAAAAAAAAAA      ", "         DDDDD         ", "        AA   AA        ", "        AAQQQAA        ", "          QQQ          ", "        AAQQQAA        ", "          QQQ          ", "        AAQQQAA        ", "          QQQ          ", "        AAQQQAA        ", "          QQQ          ", "        AAQQQAA        ", "     AAAAAAAAAAAAA     ", "     AAAAAAAAAAAAA     ", "     D   RD DR   D     ", "                       ")
                    .aisle("AAAAAAAAAAAAAAAAAAAAAAa", "AAAAAAAAAAAAAAAAAAAAAAa", "   BEEEEEEEEEEEEEEEB   ", "   CFFFFFFFGFFFFFFFC   ", "   BHHHHHHHHHHHHHHHB   ", "   AAAAAAAAAAAAAAAAA   ", "   AABBBBBBBBBBBBBAA   ", "   AAIIIIIIIIIIIIIAA   ", "   AABBBBBBBBBBBBBAA   ", "   AAAAAAAAAAAAAAAAA   ", "     AAAAAAAAAAAAA     ", "     AAAAAAAAAAAAA     ", "     AAA       AAA     ", "     AAA       AAA     ", "     AAA       AAA     ", "     AAAAAAAAAAAAA     ", "     AAAAAAAAAAAAA     ", "    JJJJJJJJJJJJJJJ    ", "        JAAAAAJ        ", "        J     J        ", "        JAAAAAJ        ", "        J     J        ", "        JAAAAAJ        ", "        J     J        ", "        JAAAAAJ        ", "        J     J        ", "        JAAAAAJ        ", "                       ", "                       ", "         AAAAA         ", "         AAAAA         ", "                       ", "         AAAAA         ", "                       ", "         AAAAA         ", "                       ", "         AAAAA         ", "                       ", "         AAAAA         ", "      AAAAAAAAAAA      ", "      AAAAAAAAAAA      ", "      DDD D D DDD      ", "                       ")
                    .aisle(" AAAAAAAAAAAAAAAAAAAAA ", " AAAAAAAAAAAAAAAAAAAAA ", "   ABBBBBBBBBBBBBBBA   ", "   ACCCCCCCCCCCCCCCA   ", "   ABBBBBBBBBBBBBBBA   ", "   AAAAAAAAAAAAAAAAA   ", "    A AA  AAA  AA A    ", "    A AA  AAA  AA A    ", "    A AA  AAA  AA A    ", "    AAAAAAAAAAAAAAA    ", "      AA       AA      ", "      AA       AA      ", "      AA       AA      ", "      AA       AA      ", "      AA       AA      ", "      AA       AA      ", "      AA       AA      ", "                       ", "                       ", "                       ", "                       ", "                       ", "                       ", "                       ", "                       ", "                       ", "                       ", "                       ", "                       ", "                       ", "                       ", "                       ", "                       ", "                       ", "                       ", "                       ", "                       ", "                       ", "                       ", "         AAAAA         ", "         AAAAA         ", "         DDDDD         ", "                       ")
                    .aisle("  AAAAAAAAAAAAAAAAAAA  ", "  AAAAAAAAAAAAAAAAAAA  ", "      AA  AAA  AA      ", "      AA  AAA  AA      ", "      AA  AAA  AA      ", "      AA  AAA  AA      ", "      AA  AAA  AA      ", "      AA  AAA  AA      ", "      AA  AAA  AA      ", "      AA       AA      ", "      AA       AA      ", "      AA       AA      ", "      AA       AA      ", "                       ", "                       ", "                       ", "                       ", "                       ", "                       ", "                       ", "                       ", "                       ", "                       ", "                       ", "                       ", "                       ", "                       ", "                       ", "                       ", "                       ", "                       ", "                       ", "                       ", "                       ", "                       ", "                       ", "                       ", "                       ", "                       ", "                       ", "                       ", "                       ", "                       ")
                    .aisle("   AAAAAAAAAAAAAAAAA   ", "   AAAAAAAAAAAAAAAAA   ", "      AA  AAA  AA      ", "      AA  AAA  AA      ", "      AA  AAA  AA      ", "      AA  AAA  AA      ", "      AA       AA      ", "      AA       AA      ", "      AA       AA      ", "      AA       AA      ", "                       ", "                       ", "                       ", "                       ", "                       ", "                       ", "                       ", "                       ", "                       ", "                       ", "                       ", "                       ", "                       ", "                       ", "                       ", "                       ", "                       ", "                       ", "                       ", "                       ", "                       ", "                       ", "                       ", "                       ", "                       ", "                       ", "                       ", "                       ", "                       ", "                       ", "                       ", "                       ", "                       ")
                    .aisle("    AAAAAAAAAAAAAAA    ", "    AAAAAAAAAAAAAAA    ", "      AA       AA      ", "      AA       AA      ", "      AA       AA      ", "      AA       AA      ", "                       ", "                       ", "                       ", "                       ", "                       ", "                       ", "                       ", "                       ", "                       ", "                       ", "                       ", "                       ", "                       ", "                       ", "                       ", "                       ", "                       ", "                       ", "                       ", "                       ", "                       ", "                       ", "                       ", "                       ", "                       ", "                       ", "                       ", "                       ", "                       ", "                       ", "                       ", "                       ", "                       ", "                       ", "                       ", "                       ", "                       ")
                    .where('~', controller(blocks(definition.get())))
                    .where('A', blocks(GCYMBlocks.CASING_HIGH_TEMPERATURE_SMELTING.get()))
                    .where('a', blocks(GCYMBlocks.CASING_HIGH_TEMPERATURE_SMELTING.get())
                            .or(GTOPredicates.autoThreadLaserAbilities(definition.getRecipeTypes()))
                            .or(abilities(PARALLEL_HATCH).setMaxGlobalLimited(1))
                            .or(abilities(MAINTENANCE).setExactLimit(1)))
                    .where('B', blocks(GCYMBlocks.HEAT_VENT.get()))
                    .where('C', blocks(GTBlocks.CASING_ENGINE_INTAKE.get()))
                    .where('D', blocks(GTBlocks.STEEL_HULL.get()))
                    .where('E', blocks(GTBlocks.FIREBOX_BRONZE.get()))
                    .where('F', blocks(GTBlocks.CASING_BRONZE_PIPE.get()))
                    .where('G', blocks(GTBlocks.CASING_POLYTETRAFLUOROETHYLENE_PIPE.get()))
                    .where('H', blocks(GTBlocks.FIREBOX_STEEL.get()))
                    .where('I', blocks(GTBlocks.CASING_EXTREME_ENGINE_INTAKE.get()))
                    .where('J', blocks(GTOBlocks.NAQUADAH_ALLOY_CASING.get()))
                    .where('K', blocks(GTBlocks.CASING_STEEL_PIPE.get()))
                    .where('L', blocks(GTBlocks.FIREBOX_TITANIUM.get()))
                    .where('M', blocks(GTBlocks.CASING_TITANIUM_PIPE.get()))
                    .where('N', blocks(GTOBlocks.AMPROSIUM_PIPE_CASING.get()))
                    .where('O', blocks(GTBlocks.FIREBOX_TUNGSTENSTEEL.get()))
                    .where('P', blocks(GTBlocks.CASING_TUNGSTENSTEEL_PIPE.get()))
                    .where('Q', heatingCoils())
                    .where('R', blocks(ChemicalHelper.getBlock(TagPrefix.frameGt, GTMaterials.Naquadah)))
                    .where('S', abilities(MUFFLER))
                    .where(' ', any())
                    .build())
            .workableCasingRenderer(GTCEu.id("block/casings/gcym/high_temperature_smelting_casing"), GTCEu.id("block/multiblock/gcym/blast_alloy_smelter"))
            .register();

    public static final MultiblockMachineDefinition SUPER_PARTICLE_COLLIDER = multiblock("super_particle_collider", "超级粒子对撞机", ElectricMultiblockMachine::new)
            .allRotation()
            .parallelizableTooltips()
            .laserTooltips()
            .recipeTypes(GTORecipeTypes.SUPER_PARTICLE_COLLIDER_RECIPES)
            .parallelizableOverclock()
            .block(GTOBlocks.LAFIUM_MECHANICAL_CASING)
            .pattern(definition -> FactoryBlockPattern.start()
                    .aisle("                                               ", "                                               ", "                    fcccccf                    ", "                    fcccccf                    ", "                    fcccccf                    ", "                                               ", "                                               ")
                    .aisle("                                               ", "                    fcccccf                    ", "                   cceeeeecc                   ", "                   cceeeeecc                   ", "                   cceeeeecc                   ", "                    fcccccf                    ", "                                               ")
                    .aisle("                    fcccccf                    ", "                   cceeeeecc                   ", "                ccccceeeeeccccc                ", "                cccdddddddddccc                ", "                ccccceeeeeccccc                ", "                   cceeeeecc                   ", "                    fcccccf                    ")
                    .aisle("                    fcccccf                    ", "                ccccceeeeeccccc                ", "              cccccdddddddddccccc              ", "              ccdddddddddddddddcc              ", "              cccccdddddddddccccc              ", "                ccccceeeeeccccc                ", "                    fcccccf                    ")
                    .aisle("                    fcccccf                    ", "              ccccccceeeeeccccccc              ", "            ccccdddcceeeeeccdddcccc            ", "            ccdddddddddddddddddddcc            ", "            ccccdddcceeeeeccdddcccc            ", "              ccccccceeeeeccccccc              ", "                    fcccccf                    ")
                    .aisle("                                               ", "            ccccccc fcccccf ccccccc            ", "           cccddccccceeeeecccccddccc           ", "           cdddddddcceeeeeccdddddddc           ", "           cccddccccceeeeecccccddccc           ", "            ccccccc fcccccf ccccccc            ", "                                               ")
                    .aisle("                                               ", "           ccccc               ccccc           ", "          ccddccccc fcccccf cccccddcc          ", "          cdddddccc fcccccf cccdddddc          ", "          ccddccccc fcccccf cccccddcc          ", "           ccccc               ccccc           ", "                                               ")
                    .aisle("                                               ", "          cccc                   cccc          ", "         ccdcccc               ccccdcc         ", "         cddddcc               ccddddc         ", "         ccdcccc               ccccdcc         ", "          cccc                   cccc          ", "                                               ")
                    .aisle("                                               ", "         ccc                       ccc         ", "        ccdccc                   cccdcc        ", "        cdddcc                   ccdddc        ", "        ccdccc                   cccdcc        ", "         ccc                       ccc         ", "                                               ")
                    .aisle("                                               ", "        ccc                         ccc        ", "       ccdcc                       ccdcc       ", "       cdddc                       cdddc       ", "       ccdcc                       ccdcc       ", "        ccc                         ccc        ", "                                               ")
                    .aisle("                                               ", "       ccc                           ccc       ", "      ccdcc                         ccdcc      ", "      cdddc                         cdddc      ", "      ccdcc                         ccdcc      ", "       ccc                           ccc       ", "                                               ")
                    .aisle("                                               ", "      ccc                             ccc      ", "     ccdcc                           ccdcc     ", "     cdddc                           cdddc     ", "     ccdcc                           ccdcc     ", "      ccc                             ccc      ", "                                               ")
                    .aisle("                                               ", "     ccc                               ccc     ", "    ccdcc                             ccdcc    ", "    cdddc                             cdddc    ", "    ccdcc                             ccdcc    ", "     ccc                               ccc     ", "                                               ")
                    .aisle("                                               ", "     ccc                               ccc     ", "    ccdcc                             ccdcc    ", "    cdddc                             cdddc    ", "    ccdcc                             ccdcc    ", "     ccc                               ccc     ", "                                               ")
                    .aisle("                                               ", "    ccc                                 ccc    ", "   ccdcc                               ccdcc   ", "   cdddc                               cdddc   ", "   ccdcc                               ccdcc   ", "    ccc                                 ccc    ", "                                               ")
                    .aisle("                                               ", "    ccc                                 ccc    ", "   ccdcc                               ccdcc   ", "   cdddc                               cdddc   ", "   ccdcc                               ccdcc   ", "    ccc                                 ccc    ", "                                               ")
                    .aisle("                                               ", "   ccc                                   ccc   ", "  ccdcc                                 ccdcc  ", "  cdddc                                 cdddc  ", "  ccdcc                                 ccdcc  ", "   ccc                                   ccc   ", "                                               ")
                    .aisle("                                               ", "   ccc                                   ccc   ", "  ccdcc                                 ccdcc  ", "  cdddc                                 cdddc  ", "  ccdcc                                 ccdcc  ", "   ccc                                   ccc   ", "                                               ")
                    .aisle("                                               ", "   ccc                                   ccc   ", "  ccdcc                                 ccdcc  ", "  cdddc                                 cdddc  ", "  ccdcc                                 ccdcc  ", "   ccc                                   ccc   ", "                                               ")
                    .aisle("                                               ", "  ccc                                     ccc  ", " ccdcc                                   ccdcc ", " cdddc                                   cdddc ", " ccdcc                                   ccdcc ", "  ccc                                     ccc  ", "                                               ")
                    .aisle("  fff                                     fff  ", " fcccf                                   fcccf ", "fccdccf                                 fccdccf", "fcdddcf                                 fcdddcf", "fccdccf                                 fccdccf", " fcccf                                   fcccf ", "  fff                                     fff  ")
                    .aisle("  ccc                                     ccc  ", " ceeec                                   ceeec ", "ceedeec                                 ceedeec", "cedddec                                 cedddec", "ceedeec                                 ceedeec", " ceeec                                   ceeec ", "  ccc                                     ccc  ")
                    .aisle("  ccc                                     ccc  ", " ceeec                                   ceeec ", "ceedeec                                 ceedeec", "cedddec                                 cedddec", "ceedeec                                 ceedeec", " ceeec                                   ceeec ", "  ccc                                     ccc  ")
                    .aisle("  ccc                                     ccc  ", " ceeec                                   ceeec ", "ceedeec                                 ceedeec", "cedddec                                 cedddec", "ceedeec                                 ceedeec", " ceeec                                   ceeec ", "  ccc                                     ccc  ")
                    .aisle("  ccc                                     ccc  ", " ceeec                                   ceeec ", "ceedeec                                 ceedeec", "cedddec                                 cedddec", "ceedeec                                 ceedeec", " ceeec                                   ceeec ", "  ccc                                     ccc  ")
                    .aisle("  ccc                                     ccc  ", " ceeec                                   ceeec ", "ceedeec                                 ceedeec", "cedddec                                 cedddec", "ceedeec                                 ceedeec", " ceeec                                   ceeec ", "  ccc                                     ccc  ")
                    .aisle("  fff                                     fff  ", " fcccf                                   fcccf ", "fccdccf                                 fccdccf", "fcdddcf                                 fcdddcf", "fccdccf                                 fccdccf", " fcccf                                   fcccf ", "  fff                                     fff  ")
                    .aisle("                                               ", "  ccc                                     ccc  ", " ccdcc                                   ccdcc ", " cdddc                                   cdddc ", " ccdcc                                   ccdcc ", "  ccc                                     ccc  ", "                                               ")
                    .aisle("                                               ", "   ccc                                   ccc   ", "  ccdcc                                 ccdcc  ", "  cdddc                                 cdddc  ", "  ccdcc                                 ccdcc  ", "   ccc                                   ccc   ", "                                               ")
                    .aisle("                                               ", "   ccc                                   ccc   ", "  ccdcc                                 ccdcc  ", "  cdddc                                 cdddc  ", "  ccdcc                                 ccdcc  ", "   ccc                                   ccc   ", "                                               ")
                    .aisle("                                               ", "   ccc                                   ccc   ", "  ccdcc                                 ccdcc  ", "  cdddc                                 cdddc  ", "  ccdcc                                 ccdcc  ", "   ccc                                   ccc   ", "                                               ")
                    .aisle("                                               ", "    ccc                                 ccc    ", "   ccdcc                               ccdcc   ", "   cdddc                               cdddc   ", "   ccdcc                               ccdcc   ", "    ccc                                 ccc    ", "                                               ")
                    .aisle("                                               ", "    ccc                                 ccc    ", "   ccdcc                               ccdcc   ", "   cdddc                               cdddc   ", "   ccdcc                               ccdcc   ", "    ccc                                 ccc    ", "                                               ")
                    .aisle("                                               ", "     ccc                               ccc     ", "    ccdcc                             ccdcc    ", "    cdddc                             cdddc    ", "    ccdcc                             ccdcc    ", "     ccc                               ccc     ", "                                               ")
                    .aisle("                                               ", "     ccc                               ccc     ", "    ccdcc                             ccdcc    ", "    cdddc                             cdddc    ", "    ccdcc                             ccdcc    ", "     ccc                               ccc     ", "                                               ")
                    .aisle("                                               ", "      ccc                             ccc      ", "     ccdcc                           ccdcc     ", "     cdddc                           cdddc     ", "     ccdcc                           ccdcc     ", "      ccc                             ccc      ", "                                               ")
                    .aisle("                                               ", "       ccc                           ccc       ", "      ccdcc                         ccdcc      ", "      cdddc                         cdddc      ", "      ccdcc                         ccdcc      ", "       ccc                           ccc       ", "                                               ")
                    .aisle("                                               ", "        ccc                         ccc        ", "       ccdcc                       ccdcc       ", "       cdddc                       cdddc       ", "       ccdcc                       ccdcc       ", "        ccc                         ccc        ", "                                               ")
                    .aisle("                                               ", "         ccc                       ccc         ", "        ccdccc                   cccdcc        ", "        cdddcc                   ccdddc        ", "        ccdccc                   cccdcc        ", "         ccc                       ccc         ", "                                               ")
                    .aisle("                                               ", "          cccc                   cccc          ", "         ccdcccc               ccccdcc         ", "         cddddcc               ccddddc         ", "         ccdcccc               ccccdcc         ", "          cccc                   cccc          ", "                                               ")
                    .aisle("                                               ", "           ccccc               ccccc           ", "          ccddccccc fcccccf cccccddcc          ", "          cdddddccc fcccccf cccdddddc          ", "          ccddccccc fcccccf cccccddcc          ", "           ccccc               ccccc           ", "                                               ")
                    .aisle("                                               ", "            ccccccc fcccccf ccccccc            ", "           cccddccccceeeeecccccddccc           ", "           cdddddddcceeeeeccdddddddc           ", "           cccddccccceeeeecccccddccc           ", "            ccccccc fcccccf ccccccc            ", "                                               ")
                    .aisle("                    fcccccf                    ", "              ccccccceeeeeccccccc              ", "            ccccdddcceeeeeccdddcccc            ", "            ccdddddddddddddddddddcc            ", "            ccccdddcceeeeeccdddcccc            ", "              ccccccceeeeeccccccc              ", "                    fcccccf                    ")
                    .aisle("                    fcccccf                    ", "                ccccceeeeeccccc                ", "              cccccdddddddddccccc              ", "              ccdddddddddddddddcc              ", "              cccccdddddddddccccc              ", "                ccccceeeeeccccc                ", "                    fcccccf                    ")
                    .aisle("                    fcccccf                    ", "                   cceeeeecc                   ", "                ccccceeeeeccccc                ", "                cccdddddddddccc                ", "                ccccceeeeeccccc                ", "                   cceeeeecc                   ", "                    fcccccf                    ")
                    .aisle("                                               ", "                    fcccccf                    ", "                   cceeeeecc                   ", "                   cceeeeecc                   ", "                   cceeeeecc                   ", "                    fcccccf                    ", "                                               ")
                    .aisle("                                               ", "                                               ", "                    fbbbbbf                    ", "                    fbbabbf                    ", "                    fbbbbbf                    ", "                                               ", "                                               ")
                    .where('a', controller(blocks(definition.get())))
                    .where('b', blocks(GTOBlocks.LAFIUM_MECHANICAL_CASING.get())
                            .or(GTOPredicates.autoLaserAbilities(definition.getRecipeTypes()))
                            .or(abilities(PARALLEL_HATCH).setMaxGlobalLimited(1))
                            .or(abilities(MAINTENANCE).setExactLimit(1)))
                    .where('c', blocks(GTOBlocks.LAFIUM_MECHANICAL_CASING.get()))
                    .where('d', blocks(GTOBlocks.AGGREGATIONE_CORE.get()))
                    .where('d', blocks(GTOBlocks.ACCELERATED_PIPELINE.get()))
                    .where('e', blocks(GTBlocks.SUPERCONDUCTING_COIL.get()))
                    .where('f', blocks(ChemicalHelper.getBlock(TagPrefix.frameGt, GTMaterials.NaquadahEnriched)))
                    .where(' ', any())
                    .build())
            .workableCasingRenderer(GTOCore.id("block/casings/lafium_mechanical_casing"), GTCEu.id("block/multiblock/fusion_reactor"))
            .register();

    public static final MultiblockMachineDefinition COMPOUND_EXTREME_COOLING_UNIT = multiblock("compound_extreme_cooling_unit", "复合式极端冷却装置", CompoundExtremeCoolingMachine::new)
            .allRotation()
            .parallelizableTooltips()
            .laserTooltips()
            .multipleRecipesTooltips()
            .recipeTypes(GTRecipeTypes.VACUUM_RECIPES)
            .recipeTypes(GTORecipeTypes.PLASMA_CONDENSER_RECIPES)
            .block(GTBlocks.CASING_ALUMINIUM_FROSTPROOF)
            .pattern(MachineUtils.EMPTY_PATTERN)
            .shapeInfos(definition -> {
                List<MultiblockShapeInfo> shapeInfos = new ArrayList<>();
                for (int i = 0; i < 2; i++) {
                    shapeInfos.addAll(MachineUtils.getMatchingShapes(false, CompoundExtremeCoolingMachine.getBlockPattern(i, definition)));
                }
                return shapeInfos;
            })
            .workableCasingRenderer(GTCEu.id("block/casings/solid/machine_casing_frost_proof"), GTCEu.id("block/multiblock/vacuum_freezer"))
            .register();

    public static final MultiblockMachineDefinition COMPOUND_DISTILLATION_FRACTIONATOR = multiblock("compound_distillation_fractionator", "复合式蒸馏分馏塔", CrossRecipeMultiblockMachine::createHatchParallel)
            .nonYAxisRotation()
            .parallelizableTooltips()
            .laserTooltips()
            .multipleRecipesTooltips()
            .recipeTypes(GTRecipeTypes.DISTILLATION_RECIPES)
            .recipeTypes(GTORecipeTypes.EVAPORATION_RECIPES)
            .block(GTOBlocks.STRENGTHEN_THE_BASE_BLOCK)
            .pattern(definition -> FactoryBlockPattern.start(RelativeDirection.RIGHT, RelativeDirection.UP, RelativeDirection.BACK)
                    .aisle("   AAAAA   AAAAA   AAAAA   ", "   AAAAA   AABAA   AAAAA   ", "    C C    DDDDD    C C    ", "    C C    D   D    C C    ", "    C C    DDDDD    C C    ", "    C C    D   D    C C    ", "    C C    DDDDD    C C    ", "    EEE    D   D    EEE    ", "           DDDDD           ", "                           ", "                           ", "                           ", "                           ", "                           ", "                           ", "                           ", "                           ", "                           ", "                           ", "                           ", "                           ", "                           ", "                           ", "                           ", "                           ", "                           ", "                           ", "                           ", "                           ", "                           ", "                           ", "                           ", "                           ", "                           ", "                           ", "                           ", "                           ", "                           ")
                    .aisle("  FFFFFFF  FFFFF  FFFFFFF  ", "  FEEEEEF  FGGGF  FEEEEEF  ", "   EEEEE   DDDDD   EEEEE   ", "   EEEEE   D   D   EEEEE   ", "   EEEEE   DDDDD   EEEEE   ", "   EEEEE   D   D   EEEEE   ", "   EEEEE   DDDDD   EEEEE   ", "   EEEEE   D   D   EEEEE   ", "   EEEEE   DDDDD   EEEEE   ", "     C     D   D     C     ", "     C     DDDDD     C     ", "     C               C     ", "     C               C     ", "     C               C     ", "     C               C     ", "     C               C     ", "     C               C     ", "     C               C     ", "     C               C     ", "     C               C     ", "     C               C     ", "     C               C     ", "     C               C     ", "     C               C     ", "     C               C     ", "     C               C     ", "   HHHHH           HHHHH   ", "   HHHHH           HHHHH   ", "   HIIIH           HIIIH   ", "   HIIIH           HIIIH   ", "   HIIIH           HIIIH   ", "   HIIIH           HIIIH   ", "   HHHHH           HHHHH   ", "   HHHHH           HHHHH   ", "                           ", "                           ", "                           ", "                           ")
                    .aisle(" FFFFFFFFF FFFFF FFFFFFFFF ", " FEEEEEEEF FGGGF FEEEEEEEF ", "  EE   EE  DHHHD  EE   EE  ", "  EE   EE  DHHHD  EE   EE  ", "  EE   EE  DHHHD  EE   EE  ", "  EE   EE  DHHHD  EE   EE  ", "  EE   EE  DHHHD  EE   EE  ", "  EE   EE  DHHHD  EE   EE  ", "  EEGGGEE  DDDDD  EEGGGEE  ", "   JJJJJ           JJJJJ   ", "   JJJJJ   DKKKD   JJJJJ   ", "  LLLLLLL  D   D  LLLLLLL  ", "   JJJJJ   DDDDD   JJJJJ   ", "   JJJJJ           JJJJJ   ", "  LLLLLLL         LLLLLLL  ", "   JJJJJ           JJJJJ   ", "   JJJJJ           JJJJJ   ", "  LLLLLLL         LLLLLLL  ", "   JJJJJ           JJJJJ   ", "   JJJJJ           JJJJJ   ", "  LLLLLLL         LLLLLLL  ", "   JJJJJ           JJJJJ   ", "   JJJJJ           JJJJJ   ", "  LLLLLLL         LLLLLLL  ", "   JJJJJ           JJJJJ   ", "   JJJJJ           JJJJJ   ", "  HJJJJJH         HJJJJJH  ", "  H     H         H     H  ", "  H     H         H     H  ", "  H     H         H     H  ", "  H     H         H     H  ", "  H     H         H     H  ", "  H     H         H     H  ", "  HHHHHHH         HHHHHHH  ", "    LLL             LLL    ", "                           ", "                           ", "                           ")
                    .aisle("AFFFFFFFFFFFFFFFFFFFFFFFFFA", "AEEEEEEEEEFFGGGFFEEEEEEEEEA", " EE     EE D   D EE     EE ", " EE     EE D   D EE     EE ", " EE     EE D   D EE     EE ", " EE     EE D   D EE     EE ", " EE     EE D   D EE     EE ", " EE     EE D   D EE     EE ", " EEGGMGGEE DKKKD EEGGMGGEE ", "  JJ   JJ         JJ   JJ  ", "  JJ   JJ  DKKKD  JJ   JJ  ", "  LJ   JL         LJ   JL  ", "  JJ   JJ  DKKKD  JJ   JJ  ", "  JJ   JJ  D   D  JJ   JJ  ", "  LJ   JL  DDDDD  LJ   JL  ", "  JJ   JJ   K K   JJ   JJ  ", "  JJ   JJ   K K   JJ   JJ  ", "  LJ   JL   K K   LJ   JL  ", "  JJ   JJ   K K   JJ   JJ  ", "  JJ   JJ   K K   JJ   JJ  ", "  LJ   JL   K K   LJ   JL  ", "  JJ   JJ   K K   JJ   JJ  ", "  JJ   JJ   K K   JJ   JJ  ", "  LJ   JL   K K   LJ   JL  ", "  JJ   JJ   HHH   JJ   JJ  ", "  JJGGGJJ         JJGGGJJ  ", " HJJ   JJH       HJJ   JJH ", " H       H       H       H ", " H       H       H       H ", " H       H       H       H ", " H       H       H       H ", " H       H       H       H ", " H       H       H       H ", " HHHHHHHHH       HHHHHHHHH ", "   LLLLL           LLLLL   ", "                           ", "                           ", "                           ")
                    .aisle("AFFFFFFFFFFFFFFFFFFFFFFFFFA", "AEEEEEEEEEFFGGGFFEEEEEEEEEA", "CE       E D   D E       EC", "CE       E D   D E       EC", "CE       E D   D E       EC", "CE       E D   D E       EC", "CE       E D   D E       EC", "EE       E D   D E       EE", " EGG M GGE DHHHD EGG M GGE ", "  J     J  HHHHH  J     J  ", "  J     J  HHHHH  J     J  ", "  L     LKKHHHHHKKL     L  ", "  J     J  HHHHH  J     J  ", "  J     J  HHHHH  J     J  ", "  L     LKKHHHHHKKL     L  ", "  J     J  HHHHH  J     J  ", "  J     J  HHHHH  J     J  ", "  L     LKKHHHHHKKL     L  ", "  J     J  HHHHH  J     J  ", "  J     J  HHHHH  J     J  ", "  L     LKKHHHHHKKL     L  ", "  J     J  HHHHH  J     J  ", "  J     J  HHHHH  J     J  ", "  L     LKKHHHHHKKL     L  ", "  J     J  HHHHH  J     J  ", "  JGMMMGJ  K K K  JGMMMGJ  ", " HJ N N JH K K K HJ N N JH ", " H  N N  H K K K H  N N  H ", " I  N N  I K K K I  N N  I ", " I  N N  I K K K I  N N  I ", " I  N N  I K K K I  N N  I ", " I  N N  I K K K I  N N  I ", " H  N N  H K K K H  N N  H ", " HHHHHHHHH K K K HHHHHHHHH ", "  LLKKKLL  K K K  LLKKKLL  ", "   LKKKKKKKKKLKKKKKKKKKL   ", "   LLLLLLLLLLLLLLLLLLLLL   ", "    KKKKKKKKKLKKKKKKKKK    ")
                    .aisle("AFFFFFFFFFFFFFFFFFFFFFFFFFA", "AEEEEEEEEEFFGGGFFEEEEEEEEEA", " E   M   E D   D E   M   E ", " E   M   E D   D E   M   E ", " E   M   E D   D E   M   E ", " E   M   E D   D E   M   E ", " E   M   E D   D E   M   E ", "EE   M   E D   D E   M   EE", " EGMMMMMGE D   D EGMMMMMGE ", " CJ  M  J  H   H  J  M  JC ", " CJ  M  JLLH   HLLJ  M  JC ", " CL  MMMMMMM   MMMMMMM  LC ", " CJ  M  J  H   H  J  M  JC ", " CJ  M  JLLH   HLLJ  M  JC ", " CL  MMMMMMM   MMMMMMM  LC ", " CJ  M  J  H   H  J  M  JC ", " CJ  M  JLLH   HLLJ  M  JC ", " CL  MMMMMMM   MMMMMMM  LC ", " CJ  M  J  H   H  J  M  JC ", " CJ  M  JLLH   HLLJ  M  JC ", " CL  MMMMMMM   MMMMMMM  LC ", " CJ  M  J  H   H  J  M  JC ", " CJ  M  JLLH   HLLJ  M  JC ", " CL  MMMMMMM   MMMMMMM  LC ", " CJ  M  J  HMHMH  J  M  JC ", " CJGMMMGJ   M M   JGMMMGJC ", " HJ     JH  M M  HJ     JH ", " H       H  M M  H       H ", " I       I  M M  I       I ", " I       I  M M  I       I ", " I       I  M M  I       I ", " I       I  M M  I       I ", " H       H  M M  H       H ", " HHHHMHHHH  M M  HHHHMHHHH ", "  LLKMKLL   M M   LLKMKLL  ", "   LKMKKKKKKMLMKKKKKKMKL   ", "   LKMMMMMMMMLMMMMMMMMKL   ", "   LLLLLLLLLLLLLLLLLLLLL   ")
                    .aisle("AFFFFFFFFFFFFFFFFFFFFFFFFFA", "AEEEEEEEEEFFGGGFFEEEEEEEEEA", "CE       E D   D E       EC", "CE       E D   D E       EC", "CE       E D   D E       EC", "CE       E D   D E       EC", "CE       E D   D E       EC", "EE       E D   D E       EE", " EGG M GGE DHHHD EGG M GGE ", "  J     J  HHHHH  J     J  ", "  J     J  HHHHH  J     J  ", "  L     LKKHHHHHKKL     L  ", "  J     J  HHHHH  J     J  ", "  J     J  HHHHH  J     J  ", "  L     LKKHHHHHKKL     L  ", "  J     J  HHHHH  J     J  ", "  J     J  HHHHH  J     J  ", "  L     LKKHHHHHKKL     L  ", "  J     J  HHHHH  J     J  ", "  J     J  HHHHH  J     J  ", "  L     LKKHHHHHKKL     L  ", "  J     J  HHHHH  J     J  ", "  J     J  HHHHH  J     J  ", "  L     LKKHHHHHKKL     L  ", "  J     J  HHHHH  J     J  ", "  JGMMMGJ  K K K  JGMMMGJ  ", " HJ N N JH K K K HJ N N JH ", " H  N N  H K K K H  N N  H ", " I  N N  I K K K I  N N  I ", " I  N N  I K K K I  N N  I ", " I  N N  I K K K I  N N  I ", " I  N N  I K K K I  N N  I ", " H  N N  H K K K H  N N  H ", " HHHHHHHHH K K K HHHHHHHHH ", "  LLKKKLL  K K K  LLKKKLL  ", "   LKKKKKKKKKLKKKKKKKKKL   ", "   LLLLLLLLLLLLLLLLLLLLL   ", "    KKKKKKKKKLKKKKKKKKK    ")
                    .aisle("AFFFFFFFFFFFFFFFFFFFFFFFFFA", "AEEEEEEEEEFFGGGFFEEEEEEEEEA", " EE     EE D   D EE     EE ", " EE     EE D   D EE     EE ", " EE     EE D   D EE     EE ", " EE     EE D   D EE     EE ", " EE     EE D   D EE     EE ", " EE     EE D   D EE     EE ", " EEGGMGGEE DKKKD EEGGMGGEE ", "  JJ   JJ         JJ   JJ  ", "  JJ   JJ  DKKKD  JJ   JJ  ", "  LJ   JL         LJ   JL  ", "  JJ   JJ  DKKKD  JJ   JJ  ", "  JJ   JJ  D   D  JJ   JJ  ", "  LJ   JL  DDDDD  LJ   JL  ", "  JJ   JJ   K K   JJ   JJ  ", "  JJ   JJ   K K   JJ   JJ  ", "  LJ   JL   K K   LJ   JL  ", "  JJ   JJ   K K   JJ   JJ  ", "  JJ   JJ   K K   JJ   JJ  ", "  LJ   JL   K K   LJ   JL  ", "  JJ   JJ   K K   JJ   JJ  ", "  JJ   JJ   K K   JJ   JJ  ", "  LJ   JL   K K   LJ   JL  ", "  JJ   JJ   HHH   JJ   JJ  ", "  JJGGGJJ         JJGGGJJ  ", " HJJ   JJH       HJJ   JJH ", " H       H       H       H ", " H       H       H       H ", " H       H       H       H ", " H       H       H       H ", " H       H       H       H ", " H       H       H       H ", " HHHHHHHHH       HHHHHHHHH ", "   LLLLL           LLLLL   ", "                           ", "                           ", "                           ")
                    .aisle(" FFFFFFFFF FFFFF FFFFFFFFF ", " FEEEEEEEF FGGGF FEEEEEEEF ", "  EE   EE  DHHHD  EE   EE  ", "  EE   EE  DHHHD  EE   EE  ", "  EE   EE  DHHHD  EE   EE  ", "  EE   EE  DHHHD  EE   EE  ", "  EE   EE  DHHHD  EE   EE  ", "  EE   EE  DHHHD  EE   EE  ", "  EEGGGEE  DDDDD  EEGGGEE  ", "   JJJJJ           JJJJJ   ", "   JJJJJ   DKKKD   JJJJJ   ", "  LLLLLLL  D   D  LLLLLLL  ", "   JJJJJ   DDDDD   JJJJJ   ", "   JJJJJ           JJJJJ   ", "  LLLLLLL         LLLLLLL  ", "   JJJJJ           JJJJJ   ", "   JJJJJ           JJJJJ   ", "  LLLLLLL         LLLLLLL  ", "   JJJJJ           JJJJJ   ", "   JJJJJ           JJJJJ   ", "  LLLLLLL         LLLLLLL  ", "   JJJJJ           JJJJJ   ", "   JJJJJ           JJJJJ   ", "  LLLLLLL         LLLLLLL  ", "   JJJJJ           JJJJJ   ", "   JJJJJ           JJJJJ   ", "  HJJJJJH         HJJJJJH  ", "  H     H         H     H  ", "  H     H         H     H  ", "  H     H         H     H  ", "  H     H         H     H  ", "  H     H         H     H  ", "  H     H         H     H  ", "  HHHHHHH         HHHHHHH  ", "    LLL             LLL    ", "                           ", "                           ", "                           ")
                    .aisle("  FFFFFFF  FFFFF  FFFFFFF  ", "  FEEEEEF  FGGGF  FEEEEEF  ", "   EEEEE   DDDDD   EEEEE   ", "   EEEEE   D   D   EEEEE   ", "   EEEEE   DDDDD   EEEEE   ", "   EEEEE   D   D   EEEEE   ", "   EEEEE   DDDDD   EEEEE   ", "   EEEEE   D   D   EEEEE   ", "   EEEEE   DDDDD   EEEEE   ", "     C     D   D     C     ", "     C     DDDDD     C     ", "     C               C     ", "     C               C     ", "     C               C     ", "     C               C     ", "     C               C     ", "     C               C     ", "     C               C     ", "     C               C     ", "     C               C     ", "     C               C     ", "     C               C     ", "     C               C     ", "     C               C     ", "     C               C     ", "     C               C     ", "   HHHHH           HHHHH   ", "   HHHHH           HHHHH   ", "   HIIIH           HIIIH   ", "   HIIIH           HIIIH   ", "   HIIIH           HIIIH   ", "   HIIIH           HIIIH   ", "   HHHHH           HHHHH   ", "   HHHHH           HHHHH   ", "                           ", "                           ", "                           ", "                           ")
                    .aisle("   FFFFF   AAAAA   FFFFF   ", "   FFFFF   AAAAA   FFFFF   ", "    C C    DDDDD    C C    ", "    C C    D   D    C C    ", "    C C    DDDDD    C C    ", "    C C    D   D    C C    ", "    C C    DDDDD    C C    ", "    EEE    D   D    EEE    ", "           DDDDD           ", "                           ", "                           ", "                           ", "                           ", "                           ", "                           ", "                           ", "                           ", "                           ", "                           ", "                           ", "                           ", "                           ", "                           ", "                           ", "                           ", "                           ", "                           ", "                           ", "                           ", "                           ", "                           ", "                           ", "                           ", "                           ", "                           ", "                           ", "                           ", "                           ")
                    .where('A', blocks(GTOBlocks.STRENGTHEN_THE_BASE_BLOCK.get())
                            .or(GTOPredicates.autoThreadLaserAbilities(definition.getRecipeTypes()))
                            .or(abilities(PARALLEL_HATCH).setMaxGlobalLimited(1))
                            .or(abilities(MAINTENANCE).setExactLimit(1)))
                    .where('B', controller(blocks(definition.get())))
                    .where('C', blocks(ChemicalHelper.getBlock(TagPrefix.frameGt, GTMaterials.TungstenCarbide)))
                    .where('D', blocks(GTOBlocks.NAQUADAH_REINFORCED_PLANT_CASING.get()))
                    .where('E', blocks(GCYMBlocks.CASING_WATERTIGHT.get()))
                    .where('F', blocks(GTOBlocks.STRENGTHEN_THE_BASE_BLOCK.get()))
                    .where('G', blocks(GTBlocks.HERMETIC_CASING_UHV.get()))
                    .where('H', blocks(GTOBlocks.STERILE_WATER_PLANT_CASING.get()))
                    .where('I', blocks(GTBlocks.CLEANROOM_GLASS.get()))
                    .where('J', blocks(GTBlocks.CASING_STAINLESS_CLEAN.get()))
                    .where('K', blocks(ChemicalHelper.getBlock(TagPrefix.frameGt, GTMaterials.HSLASteel)))
                    .where('L', blocks(GTOBlocks.FLOCCULATION_CASING.get()))
                    .where('M', blocks(GTOBlocks.AMPROSIUM_PIPE_CASING.get()))
                    .where('N', blocks(ChemicalHelper.getBlock(TagPrefix.frameGt, GTMaterials.WatertightSteel)))
                    .where(' ', any())
                    .build())
            .workableCasingRenderer(GTOCore.id("block/casings/strengthen_the_base_block"), GTCEu.id("block/multiblock/gcym/large_distillery"))
            .register();

    public static final MultiblockMachineDefinition SUPERCONDUCTING_ELECTROMAGNETISM = multiblock("superconducting_electromagnetism", "超导电磁工厂", CrossRecipeMultiblockMachine::createHatchParallel)
            .nonYAxisRotation()
            .parallelizableTooltips()
            .laserTooltips()
            .multipleRecipesTooltips()
            .recipeTypes(GTRecipeTypes.POLARIZER_RECIPES)
            .recipeTypes(GTRecipeTypes.ELECTROMAGNETIC_SEPARATOR_RECIPES)
            .recipeTypes(GTRecipeTypes.ELECTROLYZER_RECIPES)
            .block(GTOBlocks.LAFIUM_MECHANICAL_CASING)
            .pattern(definition -> FactoryBlockPattern.start()
                    .aisle("     AAAAA     ", "       A       ", "       A       ", "       A       ", "       A       ", "       A       ", "       A       ", "       A       ", "       A       ", "       A       ", "       A       ", "       A       ", "       A       ", "       A       ", "       A       ", "       A       ", "       A       ", "       A       ", "       A       ", "       A       ", "     AAAAA     ")
                    .aisle("   AAAAAAAAA   ", "     AAAAA     ", "     AAAAA     ", "     AAAAA     ", "     BBBBB     ", "     BBBBB     ", "     BBBBB     ", "     BBBBB     ", "     BBBBB     ", "     BBBBB     ", "     BBBBB     ", "     BBBBB     ", "     BBBBB     ", "     BBBBB     ", "     BBBBB     ", "     BBBBB     ", "     BBBBB     ", "     AAAAA     ", "     AAAAA     ", "     AAAAA     ", "   AAAAAAAAA   ")
                    .aisle("  AAAAAAAAAAA  ", "   AACCCCCAA   ", "   AACCCCCAA   ", "   AA     AA   ", "   AB     BA   ", "   AB     BA   ", "   AB     BA   ", "   AB     BA   ", "   AB     BA   ", "   AB     BA   ", "   AB     BA   ", "   AB     BA   ", "   AB     BA   ", "   AB     BA   ", "   AB     BA   ", "   AB     BA   ", "   AB     BA   ", "   AA     AA   ", "   AACCCCCAA   ", "   AACCCCCAA   ", "  AAAAAAAAAAA  ")
                    .aisle(" AAAAAAAAAAAAA ", "  ACCCDDDCCCA  ", "  ACCC   CCCA  ", "  A         A  ", "  A         A  ", "  A         A  ", "  A         A  ", "  A         A  ", "  A         A  ", "  A         A  ", "  A         A  ", "  A         A  ", "  A         A  ", "  A         A  ", "  A         A  ", "  A         A  ", "  A         A  ", "  A         A  ", "  ACCC   CCCA  ", "  ACCCDDDCCCA  ", " AAAAAAAAAAAAA ")
                    .aisle(" AAAAAAAAAAAAA ", "  ACEEEEEEECA  ", "  AC       CA  ", "  A         A  ", "  B   CCC   B  ", "  B         B  ", "  B         B  ", "  B   CCC   B  ", "  B         B  ", "  B         B  ", "  B   CCC   B  ", "  B         B  ", "  B         B  ", "  B   CCC   B  ", "  B         B  ", "  B         B  ", "  B   CCC   B  ", "  A         A  ", "  AC       CA  ", "  ACEEEEEEECA  ", " AAAAAAAAAAAAA ")
                    .aisle("AAAAAAAAAAAAAAA", " ACCEEEEEEECCA ", " ACC       CCA ", " A           A ", " B   C   C   B ", " B           B ", " B           B ", " B   C   C   B ", " B           B ", " B           B ", " B   C   C   B ", " B           B ", " B           B ", " B   C   C   B ", " B           B ", " B           B ", " B   C   C   B ", " A           A ", " ACC       CCA ", " ACCEEEEEEECCA ", "AAAAAAAFAAAAAAA")
                    .aisle("AAAAAAAAAAAAAAA", " ACDEEECEEEDCA ", " AC   ECE   CA ", " A    ECE    A ", " B  C ECE C  B ", " B    ECE    B ", " B    ECE    B ", " B  C ECE C  B ", " B    ECE    B ", " B    ECE    B ", " B  C ECE C  B ", " B    ECE    B ", " B    ECE    B ", " B  C ECE C  B ", " B    ECE    B ", " B    ECE    B ", " B  C ECE C  B ", " A    ECE    A ", " AC   ECE   CA ", " ACDEEECEEEDCA ", "AAAAAAFFFAAAAAA")
                    .aisle("AAAAAAAAAAAAAAA", "AACDEECHCEEDCAA", "AAC   CHC   CAA", "AA    CHC    AA", "AB  C CHC C  BA", "AB    CHC    BA", "AB    CHC    BA", "AB  C CHC C  BA", "AB    CHC    BA", "AB    CHC    BA", "AB  C CHC C  BA", "AB    CHC    BA", "AB    CHC    BA", "AB  C CHC C  BA", "AB    CHC    BA", "AB    CHC    BA", "AB  C CHC C  BA", "AA    CHC    AA", "AAC   CHC   CAA", "AACDEECHCEEDCAA", "AAAAAFFFFFAAAAA")
                    .aisle("AAAAAAAAAAAAAAA", " ACDEEECEEEDCA ", " AC   ECE   CA ", " A    ECE    A ", " B  C ECE C  B ", " B    ECE    B ", " B    ECE    B ", " B  C ECE C  B ", " B    ECE    B ", " B    ECE    B ", " B  C ECE C  B ", " B    ECE    B ", " B    ECE    B ", " B  C ECE C  B ", " B    ECE    B ", " B    ECE    B ", " B  C ECE C  B ", " A    ECE    A ", " AC   ECE   CA ", " ACDEEECEEEDCA ", "AAAAAAFFFAAAAAA")
                    .aisle("AAAAAAAAAAAAAAA", " ACCEEEEEEECCA ", " ACC       CCA ", " A           A ", " B   C   C   B ", " B           B ", " B           B ", " B   C   C   B ", " B           B ", " B           B ", " B   C   C   B ", " B           B ", " B           B ", " B   C   C   B ", " B           B ", " B           B ", " B   C   C   B ", " A           A ", " ACC       CCA ", " ACCEEEEEEECCA ", "AAAAAAAFAAAAAAA")
                    .aisle(" AAAAAAAAAAAAA ", "  ACEEEEEEECA  ", "  AC       CA  ", "  A         A  ", "  B   CCC   B  ", "  B         B  ", "  B         B  ", "  B   CCC   B  ", "  B         B  ", "  B         B  ", "  B   CCC   B  ", "  B         B  ", "  B         B  ", "  B   CCC   B  ", "  B         B  ", "  B         B  ", "  B   CCC   B  ", "  A         A  ", "  AC       CA  ", "  ACEEEEEEECA  ", " AAAAAAAAAAAAA ")
                    .aisle(" AAAAAAAAAAAAA ", "  ACCCDDDCCCA  ", "  ACCC   CCCA  ", "  A         A  ", "  A         A  ", "  A         A  ", "  A         A  ", "  A         A  ", "  A         A  ", "  A         A  ", "  A         A  ", "  A         A  ", "  A         A  ", "  A         A  ", "  A         A  ", "  A         A  ", "  A         A  ", "  A         A  ", "  ACCC   CCCA  ", "  ACCCDDDCCCA  ", " AAAAAAAAAAAAA ")
                    .aisle("  AAAAAAAAAAA  ", "   AACCCCCAA   ", "   AACCCCCAA   ", "   AA     AA   ", "   AB     BA   ", "   AB     BA   ", "   AB     BA   ", "   AB     BA   ", "   AB     BA   ", "   AB     BA   ", "   AB     BA   ", "   AB     BA   ", "   AB     BA   ", "   AB     BA   ", "   AB     BA   ", "   AB     BA   ", "   AB     BA   ", "   AA     AA   ", "   AACCCCCAA   ", "   AACCCCCAA   ", "  AAAAAAAAAAA  ")
                    .aisle("   AAAAAAAAA   ", "     FFAFF     ", "     FFAFF     ", "     FFAFF     ", "     BBBBB     ", "     BBBBB     ", "     BBBBB     ", "     BBBBB     ", "     BBBBB     ", "     BBBBB     ", "     BBBBB     ", "     BBBBB     ", "     BBBBB     ", "     BBBBB     ", "     BBBBB     ", "     BBBBB     ", "     BBBBB     ", "     AAAAA     ", "     AAAAA     ", "     AAAAA     ", "   AAAAAAAAA   ")
                    .aisle("     AA~AA     ", "       A       ", "       A       ", "       A       ", "       A       ", "       A       ", "       A       ", "       A       ", "       A       ", "       A       ", "       A       ", "       A       ", "       A       ", "       A       ", "       A       ", "       A       ", "       A       ", "       A       ", "       A       ", "       A       ", "     AAAAA     ")
                    .where('~', controller(blocks(definition.get())))
                    .where('A', blocks(GTOBlocks.LAFIUM_MECHANICAL_CASING.get()))
                    .where('B', blocks(GTBlocks.CASING_TEMPERED_GLASS.get()))
                    .where('C', blocks(GTOBlocks.IMPROVED_SUPERCONDUCTOR_COIL.get()))
                    .where('D', blocks(GCYMBlocks.MOLYBDENUM_DISILICIDE_COIL_BLOCK.get()))
                    .where('E', blocks(GCYMBlocks.ELECTROLYTIC_CELL.get()))
                    .where('F', blocks(GTOBlocks.LAFIUM_MECHANICAL_CASING.get())
                            .or(abilities(PARALLEL_HATCH).setMaxGlobalLimited(1))
                            .or(GTOPredicates.autoThreadLaserAbilities(definition.getRecipeTypes()))
                            .or(abilities(MAINTENANCE).setExactLimit(1)))
                    .where('H', blocks(GTOBlocks.ACCELERATED_PIPELINE.get()))
                    .where(' ', any())
                    .build())
            .workableCasingRenderer(GTOCore.id("block/casings/lafium_mechanical_casing"), GTCEu.id("block/multiblock/fusion_reactor"))
            .register();

    public static final MultiblockMachineDefinition CRYSTAL_BUILDER = multiblock("crystal_builder", "晶体构建者", CoilCrossRecipeMultiblockMachine::createCoilParallel)
            .nonYAxisRotation()
            .coilParallelTooltips()
            .laserTooltips()
            .multipleRecipesTooltips()
            .recipeTypes(GTRecipeTypes.AUTOCLAVE_RECIPES)
            .recipeTypes(GTORecipeTypes.CRYSTALLIZATION_RECIPES)
            .block(GTOBlocks.MOLECULAR_CASING)
            .pattern(definition -> FactoryBlockPattern.start(RelativeDirection.RIGHT, RelativeDirection.UP, RelativeDirection.BACK)
                    .aisle("          AAA          ", "          QQQ          ", "          QRQ          ", "          QQQ          ", "                       ", "                       ", "                       ", "                       ", "                       ", "                       ", "                       ", "                       ", "                       ", "                       ", "                       ", "                       ", "                       ", "                       ", "                       ", "                       ", "                       ", "                       ", "                       ", "                       ", "                       ", "                       ", "                       ", "                       ", "                       ", "                       ", "                       ", "                       ", "                       ", "                       ")
                    .aisle("       AAAAAAAAA       ", "       QQQBBBQQQ       ", "       QQCBBBCQQ       ", "       QQCBBBCQQ       ", "       DDDDDDDDD       ", "       BBCBBBCBB       ", "       BBCBBBCBB       ", "       BBBBBBBBB       ", "                       ", "                       ", "       BBBBBBBBB       ", "       BBBBBBBBB       ", "       BBBBBBBBB       ", "                       ", "                       ", "                       ", "                       ", "                       ", "                       ", "                       ", "                       ", "                       ", "                       ", "                       ", "                       ", "                       ", "                       ", "                       ", "                       ", "                       ", "                       ", "                       ", "                       ", "                       ")
                    .aisle("      AAAAAAAAAAA      ", "      BBBBBBBBBBB      ", "      B  CCCCC  B      ", "      B  CCCCC  B      ", "      D         D      ", "      B  CCCCC  B      ", "      B  CCCCC  B      ", "      BBBBBBBBBBB      ", "                       ", "                       ", "      BBBBBBBBBBB      ", "      BBEEEEEEEBB      ", "      BBFFFFFFFBB      ", "       GFFFFFFFG       ", "       GFFFFFFFG       ", "       GFFFFFFFG       ", "       GFFFFFFFG       ", "       GFFFFFFFG       ", "       GGGGGGGGG       ", "       GFFFFFFFG       ", "       GFFFFFFFG       ", "       GFFFFFFFG       ", "       GFFFFFFFG       ", "       GFFFFFFFG       ", "       GGGGGGGGG       ", "       GFFFFFFFG       ", "       GFFFFFFFG       ", "       GFFFFFFFG       ", "       GFFFFFFFG       ", "       GFFFFFFFG       ", "       GGGGGGGGG       ", "       BBBBBBBBB       ", "       BHHHHHHHB       ", "       BBBBBBBBB       ")
                    .aisle("     AAAAAAAAAAAAA     ", "     BBBBBBBBBBBBB     ", "     B     C     B     ", "     B     C     B     ", "     D     C     D     ", "     B     C     B     ", "     B     C     B     ", "     BBBBBBBBBBBBB     ", "       HHHHHHHHH       ", "       HHHHHHHHH       ", "     BBBBBBBBBBBBB     ", "     BBEEEEEEEEEBB     ", "     BBF       FBB     ", "       F       F       ", "       F       F       ", "       F       F       ", "       F       F       ", "       F       F       ", "      GG       GG      ", "       F       F       ", "       F       F       ", "       F       F       ", "       F       F       ", "       F       F       ", "      GG       GG      ", "       F       F       ", "       F       F       ", "       F       F       ", "       F       F       ", "       F       F       ", "      GGIIIIIIIGG      ", "      BBBBBBBBBBB      ", "      BBBBBBBBBBB      ", "      BBBBBBBBBBB      ")
                    .aisle("    AAAAAAAAAAAAAAA    ", "    BBBBBBBBBBBBBBB    ", "    BBBBBBBBBBBBBBB    ", "    B     CCC     B    ", "    D     CCC     D    ", "    B     CCC     B    ", "    B     CCC     B    ", "    BBBB  CCC  BBBB    ", "      HH  CCC  HH      ", "      HH  CCC  HH      ", "    BBBB  CCC  BBBB    ", "    BBEEEECCCEEEEBB    ", "    BBFF  CCC  FFBB    ", "      FF  CCC  FF      ", "      FF  JJJ  FF      ", "      FF       FF      ", "      FF       FF      ", "      FF       FF      ", "     GGK       KGG     ", "      FF       FF      ", "      FF       FF      ", "      FF       FF      ", "      FF       FF      ", "      FF       FF      ", "     GGK       KGG     ", "      FF       FF      ", "      FF       FF      ", "      FF       FF      ", "      FF       FF      ", "      FF       FF      ", "     GGGGGGGGGGGGG     ", "     BBBBBBBBBBBBB     ", "     BBBBBBBBBBBBB     ", "     BBB       BBB     ")
                    .aisle("   AAAAAAAAAAAAAAAAA   ", "   BBBBBBBBBBBBBBBBB   ", "   B      B B      B   ", "   B      C C      B   ", "   D      C C      D   ", "   B      C C      B   ", "   B      C C      B   ", "   BBBB   C C   BBBB   ", "     HH   C C   HH     ", "     HH   CKC   HH     ", "   BBBB   CKC   BBBB   ", "   BBEEEEECKCEEEEEBB   ", "   BBFF   CKC   FFBB   ", "     FF   CKC   FF     ", "     FF   JKJ   FF     ", "     FF    L    FF     ", "     FF         FF     ", "     FF         FF     ", "    GGK         KGG    ", "     FF         FF     ", "     FF         FF     ", "     FF         FF     ", "     FF         FF     ", "     FF         FF     ", "    GGK         KGG    ", "     FF         FF     ", "     FF         FF     ", "     FF         FF     ", "     FF         FF     ", "     FF         FF     ", "    GGGGGGGGGGGGGGG    ", "    BBCCCCCCCCCCCBB    ", "    BBBBBBBBBBBBBBB    ", "    BBB         BBB    ")
                    .aisle("  AAAAAAAAAAAAAAAAAAA  ", "  BBBBBBBBBBBBBBBBBBB  ", "  BBBBBBBBBBBBBBBBBBB  ", "  B       CCC       B  ", "  D       CCC       D  ", "  B       CCC       B  ", "  B       CCC       B  ", "  BBBB    CCC    BBBB  ", "    HH    CCC    HH    ", "    HH    CCC    HH    ", "  BBBB    CCC    BBBB  ", "  BBEEEEEECCCEEEEEEBB  ", "  BBFF    CCC    FFBB  ", "   GFF    CCC    FFG   ", "   GFF    JJJ    FFG   ", "   GFF           FFG   ", "   GFF           FFG   ", "   GFF           FFG   ", "   GGK           KGG   ", "   GFF           FFG   ", "   GFF           FFG   ", "   GFF           FFG   ", "   GFF           FFG   ", "   GFF           FFG   ", "   GGK           KGG   ", "   GFF           FFG   ", "   GFF           FFG   ", "   GFF   M   M   FFG   ", "   GFF   M   M   FFG   ", "   GFF   M   M   FFG   ", "   GGGG  M   M  GGGG   ", "   BBBCCCCCCCCCCCBBB   ", "   BBBBBBBBBBBBBBBBB   ", "   BBB           BBB   ")
                    .aisle("AAAAAAAAAAAAAAAAAAAAAAA", "NNBBBBBBBBBBBBBBBBBBBNN", " NB  B B       B B  BN ", " NB                 BN ", " ND                 DN ", " NB                 BN ", " NB                 BN ", " NBBB             BBBN ", " NNNH             HNNN ", " NNNH             HNNN ", "  BBB             BBB  ", "  BEEEEEEEEEEEEEEEEEB  ", "  BF      OOO      FB  ", "   F               F   ", "   F      OOO      F   ", "   F               F   ", "   F      OOO      F   ", "   F               F   ", "   G      OOO      G   ", "   F               F   ", "   F      OOO      F   ", "   F               F   ", "   F      OOO      F   ", "   F               F   ", "   G      OOO      G   ", "   F               F   ", "   F               F   ", "   F               F   ", "   F               F   ", "   F               F   ", "   GIGG  H   H  GGIG   ", "   BBBCCCCCCCCCCCBBB   ", "   HBBBBBBBBBBBBBBBH   ", "   BB             BB   ")
                    .aisle("AAAAAAAAAAAAAAAAAAAAAAA", "N BBBBBBBBBBBBBBBBBBB N", "  CC B B O   O B B CC  ", "  CC     O   O     CC  ", "  D      O   O      D  ", "  CC     O   O     CC  ", "  CC     O   O     CC  ", "  BBB    O   O    BBB  ", "  INH    O   O    HNI  ", " N IH    O   O    HI N ", "  BBB    O   O    BBB  ", "  BEEEEEEOEEEOEEEEEEB  ", "  BF     O   O     FB  ", "   F     O   O     F   ", "   F     O   O     F   ", "   F     O   O     F   ", "   F     O   O     F   ", "   F     O   O     F   ", "   G     O   O     G   ", "   F     O   O     F   ", "   F     O   O     F   ", "   F     O   O     F   ", "   F     O   O     F   ", "   F     O   O     F   ", "   G     O   O     G   ", "   F               F   ", "   F               F   ", "   F   M       M   F   ", "   F   M       M   F   ", "   F   M L   L M   F   ", "   GIGGMHHHHHHHMGGIG   ", "   BBBCCCCCCCCCCCBBB   ", "   HBBBBCBBBBBCBBBBH   ", "   BCCCCCPPPPPCCCCCB   ")
                    .aisle("AAAAAAAAAAAAAAAAAAAAAAA", "NNBBBBBBBBBBBBBBBBBBBNN", " NBC B B       B B CBN ", " NBC CCC  CCC  CCC CBN ", " ND  CCC  CCC  CCC  DN ", " NBC CCC  CCC  CCC CBN ", " NBC CCC  CCC  CCC CBN ", " NBBBCCC  CCC  CCCBBBN ", " NINHCCC  CCC  CCCHNIN ", " NNNHCCC  CCC  CCCHNNN ", " NBBBCCC  CCC  CCCBBBN ", " NBEECCCEECCCEECCCEEBN ", "  BF CCCO CCC OCCC FB  ", "   F CCC  CCC  CCC F   ", "   F JJJO CCC OJJJ F   ", "   F      JJJ      F   ", "   F    O JJJ O    F   ", "   F      JJJ      F   ", "   G    O JJJ O    G   ", "   F      JJJ      F   ", "   F    O JJJ O    F   ", "   F      JJJ      F   ", "   F    O     O    F   ", "   F               F   ", "   G    O     O    G   ", "   F               F   ", "   F               F   ", "   F               F   ", "   F               F   ", "   F               F   ", "   GIGG  H   H  GGIG   ", "   BBBCCCCCCCCCCCBBB   ", "   HBBBBCBBBBBCBBBBH   ", "   BCCCCCPHHHPCCCCCB   ")
                    .aisle("AAAAAAAAAAAAAAAAAAAAAAA", "N BBBBBBBBBBBBBBBBBBB N", "  BCCB B       B BCCB  ", "  BCCC C  C C  C CCCB  ", "  D CC C  C C  C CC D  ", "  BCCC C  C C  C CCCB  ", "  BCCC C  C C  C CCCB  ", "  BBBC C  C C  C CBBB  ", "  INHC C  C C  C CHNI  ", "   IHCKC  CKC  CKCHI   ", "  BBBCKC  CKC  CKCBBB  ", " NBEECKCEECKCEECKCEEBN ", "  BF CKCO CKC OCKC FB  ", "   F CKC  CKC  CKC F   ", "   F JKJO CKC OJKJ F   ", "   F  L   JKJ   L  F   ", "   F    O JKJ O    F   ", "   F      JKJ      F   ", "   G    O JKJ O    G   ", "   F      JKJ      F   ", "   F    O JKJ O    F   ", "   F      JKJ      F   ", "   F    O  L  O    F   ", "   F               F   ", "   G    O     O    G   ", "   F               F   ", "   F               F   ", "   F               F   ", "   F               F   ", "   F               F   ", "   GIGG  H   H  GGIG   ", "   BBBCCCCCCCCCCCBBB   ", "   HBBBBBBBBBBBBBBBH   ", "   BBPPPPPHHHPPPPPBB   ")
                    .aisle("AAAAAAAAAAAAAAAAAAAAAAA", "NNBBBBBBBBBBBBBBBBBBBNN", " NBC B B       B B CBN ", " NBC CCC  CCC  CCC CBN ", " ND  CCC  CCC  CCC  DN ", " NBC CCC  CCC  CCC CBN ", " NBC CCC  CCC  CCC CBN ", " NBBBCCC  CCC  CCCBBBN ", " NINHCCC  CCC  CCCHNIN ", " NNNHCCC  CCC  CCCHNNN ", " NBBBCCC  CCC  CCCBBBN ", " NBEECCCEECCCEECCCEEBN ", "  BF CCCO CCC OCCC FB  ", "   F CCC  CCC  CCC F   ", "   F JJJO CCC OJJJ F   ", "   F      JJJ      F   ", "   F    O JJJ O    F   ", "   F      JJJ      F   ", "   G    O JJJ O    G   ", "   F      JJJ      F   ", "   F    O JJJ O    F   ", "   F      JJJ      F   ", "   F    O     O    F   ", "   F               F   ", "   G    O     O    G   ", "   F               F   ", "   F               F   ", "   F               F   ", "   F               F   ", "   F               F   ", "   GIGG  H   H  GGIG   ", "   BBBCCCCCCCCCCCBBB   ", "   HBBBBCBBBBBCBBBBH   ", "   BCCCCCPHHHPCCCCCB   ")
                    .aisle("AAAAAAAAAAAAAAAAAAAAAAA", "N BBBBBBBBBBBBBBBBBBB N", "  CC B B O   O B B CC  ", "  CC     O   O     CC  ", "  D      O   O      D  ", "  CC     O   O     CC  ", "  CC     O   O     CC  ", "  BBB    O   O    BBB  ", "  INH    O   O    HNI  ", " N IH    O   O    HI N ", "  BBB    O   O    BBB  ", "  BEEEEEEOEEEOEEEEEEB  ", "  BF     O   O     FB  ", "   F     O   O     F   ", "   F     O   O     F   ", "   F     O   O     F   ", "   F     O   O     F   ", "   F     O   O     F   ", "   G     O   O     G   ", "   F     O   O     F   ", "   F     O   O     F   ", "   F     O   O     F   ", "   F     O   O     F   ", "   F     O   O     F   ", "   G     O   O     G   ", "   F               F   ", "   F               F   ", "   F   M       M   F   ", "   F   M       M   F   ", "   F   M L   L M   F   ", "   GIGGMHHHHHHHMGGIG   ", "   BBBCCCCCCCCCCCBBB   ", "   HBBBBCBBBBBCBBBBH   ", "   BCCCCCPPPPPCCCCCB   ")
                    .aisle("AAAAAAAAAAAAAAAAAAAAAAA", "NNBBBBBBBBBBBBBBBBBBBNN", " NB  B B       B B  BN ", " NB                 BN ", " ND                 DN ", " NB                 BN ", " NB                 BN ", " NBBB             BBBN ", " NNNH             HNNN ", " NNNH             HNNN ", "  BBB             BBB  ", "  BEEEEEEEEEEEEEEEEEB  ", "  BF      OOO      FB  ", "   F               F   ", "   F      OOO      F   ", "   F               F   ", "   F      OOO      F   ", "   F               F   ", "   G      OOO      G   ", "   F               F   ", "   F      OOO      F   ", "   F               F   ", "   F      OOO      F   ", "   F               F   ", "   G      OOO      G   ", "   F               F   ", "   F               F   ", "   F               F   ", "   F               F   ", "   F               F   ", "   GIGG  H   H  GGIG   ", "   BBBCCCCCCCCCCCBBB   ", "   HBBBBBBBBBBBBBBBH   ", "   BB             BB   ")
                    .aisle("  AAAAAAAAAAAAAAAAAAA  ", "  BBBBBBBBBBBBBBBBBBB  ", "  BBBBBBBBBBBBBBBBBBB  ", "  B       CCC       B  ", "  D       CCC       D  ", "  B       CCC       B  ", "  B       CCC       B  ", "  BBBB    CCC    BBBB  ", "    HH    CCC    HH    ", "    HH    CCC    HH    ", "  BBBB    CCC    BBBB  ", "  BBEEEEEECCCEEEEEEBB  ", "  BBFF    CCC    FFBB  ", "   GFF    CCC    FFG   ", "   GFF    JJJ    FFG   ", "   GFF           FFG   ", "   GFF           FFG   ", "   GFF           FFG   ", "   GGK           KGG   ", "   GFF           FFG   ", "   GFF           FFG   ", "   GFF           FFG   ", "   GFF           FFG   ", "   GFF           FFG   ", "   GGK           KGG   ", "   GFF           FFG   ", "   GFF           FFG   ", "   GFF   M   M   FFG   ", "   GFF   M   M   FFG   ", "   GFF   M   M   FFG   ", "   GGGG  M   M  GGGG   ", "   BBBCCCCCCCCCCCBBB   ", "   BBBBBBBBBBBBBBBBB   ", "   BBB           BBB   ")
                    .aisle("   AAAAAAAAAAAAAAAAA   ", "   BBBBBBBBBBBBBBBBB   ", "   B      B B      B   ", "   B      C C      B   ", "   D      C C      D   ", "   B      C C      B   ", "   B      C C      B   ", "   BBBB   C C   BBBB   ", "     HH   C C   HH     ", "     HH   CKC   HH     ", "   BBBB   CKC   BBBB   ", "   BBEEEEECKCEEEEEBB   ", "   BBFF   CKC   FFBB   ", "     FF   CKC   FF     ", "     FF   JKJ   FF     ", "     FF    L    FF     ", "     FF         FF     ", "     FF         FF     ", "    GGK         KGG    ", "     FF         FF     ", "     FF         FF     ", "     FF         FF     ", "     FF         FF     ", "     FF         FF     ", "    GGK         KGG    ", "     FF         FF     ", "     FF         FF     ", "     FF         FF     ", "     FF         FF     ", "     FF         FF     ", "    GGGGGGGGGGGGGGG    ", "    BBCCCCCCCCCCCBB    ", "    BBBBBBBBBBBBBBB    ", "    BBB         BBB    ")
                    .aisle("    AAAAAAAAAAAAAAA    ", "    BBBBBBBBBBBBBBB    ", "    BBBBBBBBBBBBBBB    ", "    B     CCC     B    ", "    D     CCC     D    ", "    B     CCC     B    ", "    B     CCC     B    ", "    BBBB  CCC  BBBB    ", "      HH  CCC  HH      ", "      HH  CCC  HH      ", "    BBBB  CCC  BBBB    ", "    BBEEEECCCEEEEBB    ", "    BBFF  CCC  FFBB    ", "      FF  CCC  FF      ", "      FF  JJJ  FF      ", "      FF       FF      ", "      FF       FF      ", "      FF       FF      ", "     GGK       KGG     ", "      FF       FF      ", "      FF       FF      ", "      FF       FF      ", "      FF       FF      ", "      FF       FF      ", "     GGK       KGG     ", "      FF       FF      ", "      FF       FF      ", "      FF       FF      ", "      FF       FF      ", "      FF       FF      ", "     GGGGGGGGGGGGG     ", "     BBBBBBBBBBBBB     ", "     BBBBBBBBBBBBB     ", "     BBB       BBB     ")
                    .aisle("     AAAAAAAAAAAAA     ", "     BBBBBBBBBBBBB     ", "     B     C     B     ", "     B     C     B     ", "     D     C     D     ", "     B     C     B     ", "     B     C     B     ", "     BBBBBBBBBBBBB     ", "       HHHHHHHHH       ", "       HHHHHHHHH       ", "     BBBBBBBBBBBBB     ", "     BBEEEEEEEEEBB     ", "     BBF       FBB     ", "       F       F       ", "       F       F       ", "       F       F       ", "       F       F       ", "       F       F       ", "      GG       GG      ", "       F       F       ", "       F       F       ", "       F       F       ", "       F       F       ", "       F       F       ", "      GG       GG      ", "       F       F       ", "       F       F       ", "       F       F       ", "       F       F       ", "       F       F       ", "      GGIIIIIIIGG      ", "      BBBBBBBBBBB      ", "      BBBBBBBBBBB      ", "      BBBBBBBBBBB      ")
                    .aisle("      AAAAAAAAAAA      ", "      BBBBBBBBBBB      ", "      B  CCCCC  B      ", "      B  CCCCC  B      ", "      D         D      ", "      B  CCCCC  B      ", "      B  CCCCC  B      ", "      BBBBBBBBBBB      ", "                       ", "                       ", "      BBBBBBBBBBB      ", "      BBEEEEEEEBB      ", "      BBFFFFFFFBB      ", "       GFFFFFFFG       ", "       GFFFFFFFG       ", "       GFFFFFFFG       ", "       GFFFFFFFG       ", "       GFFFFFFFG       ", "       GGGGGGGGG       ", "       GFFFFFFFG       ", "       GFFFFFFFG       ", "       GFFFFFFFG       ", "       GFFFFFFFG       ", "       GFFFFFFFG       ", "       GGGGGGGGG       ", "       GFFFFFFFG       ", "       GFFFFFFFG       ", "       GFFFFFFFG       ", "       GFFFFFFFG       ", "       GFFFFFFFG       ", "       GGGGGGGGG       ", "       BBBBBBBBB       ", "       BHHHHHHHB       ", "       BBBBBBBBB       ")
                    .aisle("       AAAAAAAAA       ", "       BBBBBBBBB       ", "       BBCBBBCBB       ", "       BBCBBBCBB       ", "       DDDDDDDDD       ", "       BBCBBBCBB       ", "       BBCBBBCBB       ", "       BBBBBBBBB       ", "                       ", "                       ", "       BBBBBBBBB       ", "       BBBBBBBBB       ", "       BBBBBBBBB       ", "                       ", "                       ", "                       ", "                       ", "                       ", "                       ", "                       ", "                       ", "                       ", "                       ", "                       ", "                       ", "                       ", "                       ", "                       ", "                       ", "                       ", "                       ", "                       ", "                       ", "                       ")
                    .aisle("                       ", "                       ", "                       ", "                       ", "                       ", "                       ", "                       ", "                       ", "                       ", "                       ", "                       ", "                       ", "                       ", "                       ", "                       ", "                       ", "                       ", "                       ", "                       ", "                       ", "                       ", "                       ", "                       ", "                       ", "                       ", "                       ", "                       ", "                       ", "                       ", "                       ", "                       ", "                       ", "                       ", "                       ")
                    .where('A', blocks(GTOBlocks.HIGH_STRENGTH_CONCRETE.get()))
                    .where('B', blocks(GTOBlocks.MOLECULAR_CASING.get()))
                    .where('C', blocks(GTBlocks.HIGH_POWER_CASING.get()))
                    .where('D', blocks(GTOBlocks.PIKYONIUM_MACHINE_CASING.get()))
                    .where('E', blocks(GTOBlocks.NAQUADAH_REINFORCED_PLANT_CASING.get()))
                    .where('F', blocks(GTBlocks.FUSION_GLASS.get()))
                    .where('G', blocks(GTOBlocks.PRESSURE_CONTAINMENT_CASING.get()))
                    .where('H', blocks(GTOBlocks.LASER_CASING.get()))
                    .where('I', blocks(GCYMBlocks.ELECTROLYTIC_CELL.get()))
                    .where('J', blocks(GTOBlocks.QUANTUM_GLASS.get()))
                    .where('K', blocks(GTOBlocks.HYPER_CORE.get()))
                    .where('L', blocks(GTOBlocks.MOLECULAR_COIL.get()))
                    .where('M', blocks(GTOBlocks.CONTAINMENT_FIELD_GENERATOR.get()))
                    .where('N', blocks(GCYMBlocks.CASING_NONCONDUCTING.get()))
                    .where('O', heatingCoils())
                    .where('P', blocks(GTBlocks.CASING_GRATE.get()))
                    .where('Q', blocks(GTOBlocks.MOLECULAR_CASING.get())
                            .or(GTOPredicates.autoThreadLaserAbilities(definition.getRecipeTypes()))
                            .or(abilities(MAINTENANCE).setExactLimit(1)))
                    .where('R', controller(blocks(definition.get())))
                    .where(' ', any())
                    .build())
            .workableCasingRenderer(GTOCore.id("block/casings/molecular_casing"), GTCEu.id("block/multiblock/fusion_reactor"))
            .register();

    public static final MultiblockMachineDefinition HOLY_SEPARATOR = multiblock("holy_separator", "神圣分离者", CrossRecipeMultiblockMachine::createHatchParallel)
            .nonYAxisRotation()
            .parallelizableTooltips()
            .laserTooltips()
            .multipleRecipesTooltips()
            .recipeTypes(GTRecipeTypes.CENTRIFUGE_RECIPES)
            .block(GTOBlocks.MOLECULAR_CASING)
            .pattern(definition -> FactoryBlockPattern.start(RelativeDirection.FRONT, RelativeDirection.UP, RelativeDirection.RIGHT)
                    .aisle("            ABBBBBA            ", "             C   C             ", "                               ", "                               ", "                               ", "                               ", "                               ", "                               ", "                               ", "                               ", "                               ")
                    .aisle("            ABE EBA            ", "             BEFEB             ", "             CE EC             ", "                               ", "                               ", "                               ", "                               ", "                               ", "                               ", "                               ", "                               ")
