package com.gtocore.common.data.machines;

import com.gtocore.api.machine.part.GTOPartAbility;
import com.gtocore.api.pattern.GTOPredicates;
import com.gtocore.client.renderer.machine.*;
import com.gtocore.common.block.FusionCasings;
import com.gtocore.common.data.*;
import com.gtocore.common.machine.multiblock.electric.*;
import com.gtocore.common.machine.multiblock.electric.adventure.SlaughterhouseMachine;
import com.gtocore.common.machine.multiblock.electric.assembly.AdvancedAssemblyLineMachine;
import com.gtocore.common.machine.multiblock.electric.assembly.CircuitAssemblyLineMachine;
import com.gtocore.common.machine.multiblock.electric.bioengineering.IncubatorMachine;
import com.gtocore.common.machine.multiblock.electric.nano.NanoForgeMachine;
import com.gtocore.common.machine.multiblock.electric.processing.ColdIceFreezerMachine;
import com.gtocore.common.machine.multiblock.electric.processing.ProcessingPlantMachine;
import com.gtocore.common.machine.multiblock.electric.smelter.BlazeBlastFurnaceMachine;
import com.gtocore.common.machine.multiblock.electric.smelter.DimensionallyTranscendentPlasmaForgeMachine;
import com.gtocore.common.machine.multiblock.electric.space.SpaceElevatorMachine;
import com.gtocore.common.machine.multiblock.electric.space.SpaceElevatorModuleMachine;
import com.gtocore.common.machine.multiblock.electric.space.SpaceProbeSurfaceReceptionMachine;
import com.gtocore.common.machine.multiblock.electric.voidseries.INFFluidDrillMachine;
import com.gtocore.common.machine.multiblock.noenergy.GodForgeMachine;
import com.gtocore.common.machine.multiblock.noenergy.HarmonyMachine;
import com.gtocore.common.machine.multiblock.noenergy.HeatExchangerMachine;
import com.gtocore.common.machine.multiblock.noenergy.NeutronActivatorMachine;

import com.gtolib.GTOCore;
import com.gtolib.api.annotation.NewDataAttributes;
import com.gtolib.api.annotation.component_builder.ComponentBuilder;
import com.gtolib.api.annotation.component_builder.StyleBuilder;
import com.gtolib.api.lang.CNEN;
import com.gtolib.api.machine.multiblock.CrossRecipeMultiblockMachine;
import com.gtolib.api.machine.multiblock.ElectricMultiblockMachine;
import com.gtolib.api.recipe.modifier.RecipeModifierFunction;
import com.gtolib.utils.*;

import com.gregtechceu.gtceu.GTCEu;
import com.gregtechceu.gtceu.api.GTValues;
import com.gregtechceu.gtceu.api.data.chemical.ChemicalHelper;
import com.gregtechceu.gtceu.api.data.tag.TagPrefix;
import com.gregtechceu.gtceu.api.machine.MultiblockMachineDefinition;
import com.gregtechceu.gtceu.api.pattern.FactoryBlockPattern;
import com.gregtechceu.gtceu.api.pattern.MultiblockShapeInfo;
import com.gregtechceu.gtceu.api.pattern.Predicates;
import com.gregtechceu.gtceu.api.pattern.TraceabilityPredicate;
import com.gregtechceu.gtceu.api.pattern.util.RelativeDirection;
import com.gregtechceu.gtceu.client.renderer.machine.FusionReactorRenderer;
import com.gregtechceu.gtceu.common.data.*;
import com.gregtechceu.gtceu.common.machine.multiblock.electric.FusionReactorMachine;
import com.gregtechceu.gtceu.utils.FormattingUtil;

import net.minecraft.core.BlockPos;
import net.minecraft.core.Direction;
import net.minecraft.network.chat.Component;
import net.minecraft.server.MinecraftServer;
import net.minecraft.world.entity.Entity;
import net.minecraft.world.entity.item.ItemEntity;
import net.minecraft.world.entity.player.Player;
import net.minecraft.world.item.ItemStack;
import net.minecraft.world.level.Level;
import net.minecraft.world.level.block.Block;
import net.minecraft.world.level.block.Blocks;
import net.minecraft.world.phys.AABB;

import java.util.ArrayList;
import java.util.List;
import java.util.Locale;
import java.util.Objects;

import static com.gregtechceu.gtceu.api.machine.multiblock.PartAbility.*;
import static com.gregtechceu.gtceu.api.pattern.Predicates.*;
import static com.gtocore.common.block.BlockMap.SEPMMAP;
import static com.gtolib.api.GTOValues.POWER_MODULE_TIER;
import static com.gtolib.utils.register.MachineRegisterUtils.multiblock;
import static com.gtolib.utils.register.MachineRegisterUtils.registerTieredMultis;

public final class MultiBlockD {

    public static void init() {}

    public static final MultiblockMachineDefinition GREENHOUSE = multiblock("greenhouse", "温室", GreenhouseMachine::new)
            .nonYAxisRotation()
            .recipeTypes(GTORecipeTypes.GREENHOUSE_RECIPES)
            .tooltips(NewDataAttributes.EMPTY_WITH_BAR.create(
                    h -> h.addLines("运行条件", "Operating Conditions", StyleBuilder::setGold),
                    c -> c.addLines(
                            NewDataAttributes.EMPTY_WITH_POINT.createBuilder(x -> x.addLines("需要阳光才能运行", "Requires sunlight to operate", StyleBuilder::setWhite), p -> p, StyleBuilder::setOneTab),
                            NewDataAttributes.EMPTY_WITH_POINT.createBuilder(x -> x.addLines("太阳光照不足时速度减缓", "Speed slows down when sunlight is insufficient", StyleBuilder::setRed), p -> p, StyleBuilder::setOneTab))))
            .overclock()
            .block(GTBlocks.MACHINE_CASING_ULV)
            .pattern(definition -> FactoryBlockPattern.start(definition)
                    .aisle("0BBB0", "0BBB0", "0BBB0", "0BBB0", "0BBB0")
                    .aisle("BBBBB", "BdddB", "B###B", "B###B", "BGGGB")
                    .aisle("BBBBB", "BdddB", "B###B", "B###B", "BGGGB")
                    .aisle("BBBBB", "BdddB", "B###B", "B###B", "BGGGB")
                    .aisle("0BBB0", "0BEB0", "0BBB0", "0BBB0", "0BBB0")
                    .where('E', controller(blocks(definition.get())))
                    .where('G', blocks(GTBlocks.CASING_TEMPERED_GLASS.get()))
                    .where('B', blocks(GTBlocks.MACHINE_CASING_ULV.get())
                            .setMinGlobalLimited(40)
                            .or(autoAbilities(definition.getRecipeTypes()))
                            .or(abilities(MAINTENANCE).setExactLimit(1)))
                    .where('d', blocks(RegistriesUtils.getBlock("farmersdelight:rich_soil")))
                    .where('#', air())
                    .where('0', any())
                    .build())
            .workableCasingRenderer(GTCEu.id("block/casings/voltage/ulv/side"), GTCEu.id("block/multiblock/fusion_reactor"))
            .register();

    public static final MultiblockMachineDefinition EYE_OF_HARMONY = multiblock("eye_of_harmony", "鸿蒙之眼", HarmonyMachine::new)
            .nonYAxisRotation()
            .recipeTypes(GTORecipeTypes.COSMOS_SIMULATION_RECIPES)
            .tooltips(NewDataAttributes.MAIN_FUNCTION.create(v -> v.addLines("创造微缩宇宙并获取资源", "Creates a mini-universe and gathers resources inside")))
            .tooltips(NewDataAttributes.EMPTY_WITH_BAR.create(
                    h -> h.addLines("供电系统", "Power System", StyleBuilder::setGold),
                    c -> c.addLines(
                            NewDataAttributes.EMPTY_WITH_POINT.createBuilder(x -> x.addLines("需要太多EU，无法用常规手段供能", "Requires too much EU, unable to power with conventional means", StyleBuilder::setRed), p -> p, StyleBuilder::setOneTab),
                            NewDataAttributes.EMPTY_WITH_POINT.createBuilder(x -> x.addLines("由无线EU网络直接供给", "Directly supplied by wireless EU network", StyleBuilder::setWhite), p -> p, StyleBuilder::setOneTab),
                            NewDataAttributes.EMPTY_WITH_POINT.createBuilder(x -> x.addLines("具体数值可在GUI内查看", "Specific values can be viewed in the GUI", StyleBuilder::setGray), p -> p, StyleBuilder::setOneTab))))
            .tooltips(NewDataAttributes.EMPTY_WITH_BAR.create(
                    h -> h.addLines("特殊超频", "Special Overclocking", StyleBuilder::setGold),
                    c -> c.addLines(
                            NewDataAttributes.EMPTY_WITH_POINT.createBuilder(x -> x.addLines("每提升16倍功率提升2倍速度", "Increasing speed by 2x for every 16x power increase", StyleBuilder::setWhite), p -> p, StyleBuilder::setOneTab),
                            NewDataAttributes.EMPTY_WITH_POINT.createBuilder(x -> x.addLines("超频由编程电路调节", "Overclocking is adjusted by programmed circuits", StyleBuilder::setWhite), p -> p, StyleBuilder::setOneTab),
                            NewDataAttributes.EMPTY_WITH_POINT.createBuilder(x -> x.addLines("电路1: 不执行超频", "Circuit 1: No overclocking", StyleBuilder::setGray), p -> p, StyleBuilder::setOneTab),
                            NewDataAttributes.EMPTY_WITH_POINT.createBuilder(x -> x.addLines("电路2-4: 分别执行1-3次超频", "Circuits 2-4: Execute 1-3 times overclocking", StyleBuilder::setGray), p -> p, StyleBuilder::setOneTab))))
            .tooltips(NewDataAttributes.EMPTY_WITH_BAR.create(
                    h -> h.addLines("启动需求", "Startup Requirements", StyleBuilder::setGold),
                    c -> c.addLines(
                            NewDataAttributes.EMPTY_WITH_POINT.createBuilder(x -> x.addLines("1024B宇宙素", "1024B Cosmic Element", StyleBuilder::setWhite), p -> p, StyleBuilder::setOneTab),
                            NewDataAttributes.EMPTY_WITH_POINT.createBuilder(x -> x.addLines("1024KB氢", "1024KB Hydrogen", StyleBuilder::setWhite), p -> p, StyleBuilder::setOneTab),
                            NewDataAttributes.EMPTY_WITH_POINT.createBuilder(x -> x.addLines("1024KB氦", "1024KB Helium", StyleBuilder::setWhite), p -> p, StyleBuilder::setOneTab),
                            NewDataAttributes.EMPTY_WITH_POINT.createBuilder(x -> x.addLines("氢氦存储在机器内部并持续消耗", "Hydrogen and helium stored inside and continuously consumed", StyleBuilder::setRed), p -> p, StyleBuilder::setOneTab))))
            .alwaysTryModifyRecipe(true)
            .fromSourceTooltips("GTNH")
            .block(GTBlocks.HIGH_POWER_CASING)
            .pattern(definition -> FactoryBlockPattern.start(definition)
                    .aisle("                                 ", "                                 ", "                                 ", "                                 ", "                                 ", "                                 ", "                                 ", "                                 ", "                                 ", "                                 ", "                                 ", "                                 ", "               A A               ", "               A A               ", "               A A               ", "            AAAAAAAAA            ", "               A A               ", "            AAAAAAAAA            ", "               A A               ", "               A A               ", "               A A               ", "                                 ", "                                 ", "                                 ", "                                 ", "                                 ", "                                 ", "                                 ", "                                 ", "                                 ", "                                 ", "                                 ", "                                 ")
                    .aisle("                                 ", "                                 ", "                                 ", "                                 ", "                                 ", "                                 ", "                                 ", "                                 ", "                                 ", "               A A               ", "               A A               ", "               A A               ", "               A A               ", "              DDDDD              ", "             DDADADD             ", "         AAAADAADAADAAAA         ", "             DDDDDDD             ", "         AAAADAADAADAAAA         ", "             DDADADD             ", "              DDDDD              ", "               A A               ", "               A A               ", "               A A               ", "               A A               ", "                                 ", "                                 ", "                                 ", "                                 ", "                                 ", "                                 ", "                                 ", "                                 ", "                                 ")
                    .aisle("                                 ", "                                 ", "                                 ", "                                 ", "                                 ", "                                 ", "                                 ", "               A A               ", "               A A               ", "               A A               ", "                D                ", "                D                ", "             DDDDDDD             ", "            DD     DD            ", "            D  EEE  D            ", "       AAA  D EFFFE D  AAA       ", "          DDD EFFFE DDD          ", "       AAA  D EFFFE D  AAA       ", "            D  EEE  D            ", "            DD     DD            ", "             DDDDDDD             ", "                D                ", "                D                ", "               A A               ", "               A A               ", "               A A               ", "                                 ", "                                 ", "                                 ", "                                 ", "                                 ", "                                 ", "                                 ")
                    .aisle("                                 ", "                                 ", "                                 ", "                                 ", "                                 ", "                                 ", "               A A               ", "               A A               ", "                D                ", "                D                ", "                                 ", "                                 ", "                                 ", "                                 ", "                                 ", "      AA                 AA      ", "        DD             DD        ", "      AA                 AA      ", "                                 ", "                                 ", "                                 ", "                                 ", "                                 ", "                D                ", "                D                ", "               A A               ", "               A A               ", "                                 ", "                                 ", "                                 ", "                                 ", "                                 ", "                                 ")
                    .aisle("                                 ", "                                 ", "                                 ", "                                 ", "                                 ", "               A A               ", "              AAAAA              ", "                D                ", "                F                ", "                F                ", "                                 ", "                                 ", "                                 ", "                                 ", "      A                   A      ", "     AA                   AA     ", "      ADFF             FFDA      ", "     AA                   AA     ", "      A                   A      ", "                                 ", "                                 ", "                                 ", "                                 ", "                F                ", "                F                ", "                D                ", "              AAAAA              ", "               A A               ", "                                 ", "                                 ", "                                 ", "                                 ", "                                 ")
                    .aisle("                                 ", "                                 ", "                                 ", "                                 ", "               A A               ", "               A A               ", "                D                ", "             GEEFEEG             ", "                                 ", "                                 ", "                                 ", "                                 ", "                                 ", "       G                 G       ", "       E                 E       ", "    AA E                 E AA    ", "      DF                 FD      ", "    AA E                 E AA    ", "       E                 E       ", "       G                 G       ", "                                 ", "                                 ", "                                 ", "                                 ", "                                 ", "             GEEFEEG             ", "                D                ", "               A A               ", "               A A               ", "                                 ", "                                 ", "                                 ", "                                 ")
                    .aisle("                                 ", "                                 ", "                                 ", "               A A               ", "              AAAAA              ", "                D                ", "                F                ", "                                 ", "                                 ", "                                 ", "                                 ", "                                 ", "                                 ", "                                 ", "    A                       A    ", "   AA                       AA   ", "    ADF                   FDA    ", "   AA                       AA   ", "    A                       A    ", "                                 ", "                                 ", "                                 ", "                                 ", "                                 ", "                                 ", "                                 ", "                F                ", "                D                ", "              AAAAA              ", "               A A               ", "                                 ", "                                 ", "                                 ")
                    .aisle("                                 ", "                                 ", "               A A               ", "               A A               ", "                D                ", "             GEEFEEG             ", "                                 ", "                                 ", "                                 ", "                                 ", "                                 ", "                                 ", "                                 ", "     G                     G     ", "     E                     E     ", "  AA E                     E AA  ", "    DF                     FD    ", "  AA E                     E AA  ", "     E                     E     ", "     G                     G     ", "                                 ", "                                 ", "                                 ", "                                 ", "                                 ", "                                 ", "                                 ", "             GEEFEEG             ", "                D                ", "               A A               ", "               A A               ", "                                 ", "                                 ")
                    .aisle("                                 ", "                                 ", "               A A               ", "                D                ", "                F                ", "                                 ", "                                 ", "                                 ", "                                 ", "                                 ", "                                 ", "                                 ", "                                 ", "                                 ", "                                 ", "  A                           A  ", "   DF                       FD   ", "  A                           A  ", "                                 ", "                                 ", "                                 ", "                                 ", "                                 ", "                                 ", "                                 ", "                                 ", "                                 ", "                                 ", "                F                ", "                D                ", "               A A               ", "                                 ", "                                 ")
                    .aisle("                                 ", "               A A               ", "               A A               ", "                D                ", "                F                ", "                                 ", "                                 ", "                                 ", "                                 ", "                                 ", "                                 ", "                                 ", "                                 ", "                                 ", "                                 ", " AA                           AA ", "   DF                       FD   ", " AA                           AA ", "                                 ", "                                 ", "                                 ", "                                 ", "                                 ", "                                 ", "                                 ", "                                 ", "                                 ", "                                 ", "                F                ", "                D                ", "               A A               ", "               A A               ", "                                 ")
                    .aisle("                                 ", "               A A               ", "                D                ", "                                 ", "                                 ", "                                 ", "                                 ", "                                 ", "                                 ", "                                 ", "                                 ", "                                 ", "                                 ", "                                 ", "                                 ", " A                             A ", "  D                           D  ", " A                             A ", "                                 ", "                                 ", "                                 ", "                                 ", "                                 ", "                                 ", "                                 ", "                                 ", "                                 ", "                                 ", "                                 ", "                                 ", "                D                ", "               A A               ", "                                 ")
                    .aisle("                                 ", "               A A               ", "                D                ", "                                 ", "                                 ", "                                 ", "                                 ", "                                 ", "                                 ", "                                 ", "                                 ", "                                 ", "                                 ", "                                 ", "                                 ", " A                             A ", "  D                           D  ", " A                             A ", "                                 ", "                                 ", "                                 ", "                                 ", "                                 ", "                                 ", "                                 ", "                                 ", "                                 ", "                                 ", "                                 ", "                                 ", "                D                ", "               A A               ", "                                 ")
                    .aisle("               A A               ", "               A A               ", "             DDDDDDD             ", "                                 ", "                                 ", "                                 ", "                                 ", "                                 ", "                                 ", "                                 ", "                                 ", "                                 ", "                                 ", "  D                           D  ", "  D                           D  ", "AAD                           DAA", "  D                           D  ", "AAD                           DAA", "  D                           D  ", "  D                           D  ", "                                 ", "                                 ", "                                 ", "                                 ", "                                 ", "                                 ", "                                 ", "                                 ", "                                 ", "                                 ", "             DDDDDDD             ", "               A A               ", "               A A               ")
                    .aisle("               A A               ", "              DDDDD              ", "            DD     DD            ", "                                 ", "                                 ", "       G                 G       ", "                                 ", "     G                     G     ", "                                 ", "                                 ", "                                 ", "                                 ", "  D                           D  ", "  D                           D  ", " D                             D ", "AD                             DA", " D                             D ", "AD                             DA", " D                             D ", "  D                           D  ", "  D                           D  ", "                                 ", "                                 ", "                                 ", "                                 ", "     G                     G     ", "                                 ", "       G                 G       ", "                                 ", "                                 ", "            DD     DD            ", "              DDDDD              ", "               A A               ")
                    .aisle("               A A               ", "             DDADADD             ", "            D  EEE  D            ", "                                 ", "      A                   A      ", "       E                 E       ", "    A                       A    ", "     E                     E     ", "                                 ", "                                 ", "                                 ", "                                 ", "  D                           D  ", " D                             D ", " D                             D ", "AAE                           EAA", " DE                           ED ", "AAE                           EAA", " D                             D ", " D                             D ", "  D                           D  ", "                                 ", "                                 ", "                                 ", "                                 ", "     E                     E     ", "    A                       A    ", "       E                 E       ", "      A                   A      ", "                                 ", "            D  EEE  D            ", "             DDADADD             ", "               A A               ")
                    .aisle("            AAAAAAAAA            ", "         AAAADAADAADAAAA         ", "       AAA  D EFFFE D  AAA       ", "      AA                 AA      ", "     AA                   AA     ", "    AA E                 E AA    ", "   AA                       AA   ", "  AA E                     E AA  ", "  A                           A  ", " AA                           AA ", " A                             A ", " A                             A ", "AAD                           DAA", "AD                             DA", "AAE                           EAA", "AAF                           FAA", "ADF                           FDA", "AAF                           FAA", "AAE                           EAA", "AD                             DA", "AAD                           DAA", " A                             A ", " A                             A ", " AA                           AA ", "  A                           A  ", "  AA E                     E AA  ", "   AA                       AA   ", "    AA E                 E AA    ", "     AA                   AA     ", "      AA                 AA      ", "       AAA  D EFFFE D  AAA       ", "         AAAADAADAADAAAA         ", "            AAAAAAAAA            ")
                    .aisle("               A A               ", "             DDDDDDD             ", "          DDD EFFFE DDD          ", "        DD             DD        ", "      ADFF             FFDA      ", "      DF                 FD      ", "    ADF                   FDA    ", "    DF                     FD    ", "   DF                       FD   ", "   DF                       FD   ", "  D                           D  ", "  D                           D  ", "  D                           D  ", " D                             D ", " DE                           ED ", "ADF                           FDA", " DF                           FD ", "ADF                           FDA", " DE                           ED ", " D                             D ", "  D                           D  ", "  D                           D  ", "  D                           D  ", "   DF                       FD   ", "   DF                       FD   ", "    DF                     FD    ", "    ADF                   FDA    ", "      DF                 FD      ", "      ADFF             FFDA      ", "        DD             DD        ", "          DDD EFFFE DDD          ", "             DDDDDDD             ", "               A A               ")
                    .aisle("            AAAAAAAAA            ", "         AAAADAADAADAAAA         ", "       AAA  D EFFFE D  AAA       ", "      AA                 AA      ", "     AA                   AA     ", "    AA E                 E AA    ", "   AA                       AA   ", "  AA E                     E AA  ", "  A                           A  ", " AA                           AA ", " A                             A ", " A                             A ", "AAD                           DAA", "AD                             DA", "AAE                           EAA", "AAF                           FAA", "ADF                           FDA", "AAF                           FAA", "AAE                           EAA", "AD                             DA", "AAD                           DAA", " A                             A ", " A                             A ", " AA                           AA ", "  A                           A  ", "  AA E                     E AA  ", "   AA                       AA   ", "    AA E                 E AA    ", "     AA                   AA     ", "      AA                 AA      ", "       AAA  D EFFFE D  AAA       ", "         AAAADAADAADAAAA         ", "            AAAAAAAAA            ")
                    .aisle("               A A               ", "             DDADADD             ", "            D  EEE  D            ", "                                 ", "      A                   A      ", "       E                 E       ", "    A                       A    ", "     E                     E     ", "                                 ", "                                 ", "                                 ", "                                 ", "  D                           D  ", " D                             D ", " D                             D ", "AAE                           EAA", " DE                           ED ", "AAE                           EAA", " D                             D ", " D                             D ", "  D                           D  ", "                                 ", "                                 ", "                                 ", "                                 ", "     E                     E     ", "    A                       A    ", "       E                 E       ", "      A                   A      ", "                                 ", "            D  EEE  D            ", "             DDADADD             ", "               A A               ")
                    .aisle("               A A               ", "              DDDDD              ", "            DD     DD            ", "                                 ", "                                 ", "       G                 G       ", "                                 ", "     G                     G     ", "                                 ", "                                 ", "                                 ", "                                 ", "  D                           D  ", "  D                           D  ", " D                             D ", "AD                             DA", " D                             D ", "AD                             DA", " D                             D ", "  D                           D  ", "  D                           D  ", "                                 ", "                                 ", "                                 ", "                                 ", "     G                     G     ", "                                 ", "       G                 G       ", "                                 ", "                                 ", "            DD     DD            ", "              DDDDD              ", "               A A               ")
                    .aisle("               A A               ", "               A A               ", "             DDDDDDD             ", "                                 ", "                                 ", "                                 ", "                                 ", "                                 ", "                                 ", "                                 ", "                                 ", "                                 ", "                                 ", "  D                           D  ", "  D                           D  ", "AAD                           DAA", "  D                           D  ", "AAD                           DAA", "  D                           D  ", "  D                           D  ", "                                 ", "                                 ", "                                 ", "                                 ", "                                 ", "                                 ", "                                 ", "                                 ", "                                 ", "                                 ", "             DDDDDDD             ", "               A A               ", "               A A               ")
                    .aisle("                                 ", "               A A               ", "                D                ", "                                 ", "                                 ", "                                 ", "                                 ", "                                 ", "                                 ", "                                 ", "                                 ", "                                 ", "                                 ", "                                 ", "                                 ", " A                             A ", "  D                           D  ", " A                             A ", "                                 ", "                                 ", "                                 ", "                                 ", "                                 ", "                                 ", "                                 ", "                                 ", "                                 ", "                                 ", "                                 ", "                                 ", "                D                ", "               A A               ", "                                 ")
                    .aisle("                                 ", "               A A               ", "                D                ", "                                 ", "                                 ", "                                 ", "                                 ", "                                 ", "                                 ", "                                 ", "                                 ", "                                 ", "                                 ", "                                 ", "                                 ", " A                             A ", "  D                           D  ", " A                             A ", "                                 ", "                                 ", "                                 ", "                                 ", "                                 ", "                                 ", "                                 ", "                                 ", "                                 ", "                                 ", "                                 ", "                                 ", "                D                ", "               A A               ", "                                 ")
                    .aisle("                                 ", "               A A               ", "               A A               ", "                D                ", "                F                ", "                                 ", "                                 ", "                                 ", "                                 ", "                                 ", "                                 ", "                                 ", "                                 ", "                                 ", "                                 ", " AA                           AA ", "   DF                       FD   ", " AA                           AA ", "                                 ", "                                 ", "                                 ", "                                 ", "                                 ", "                                 ", "                                 ", "                                 ", "                                 ", "                                 ", "                F                ", "                D                ", "               A A               ", "               A A               ", "                                 ")
                    .aisle("                                 ", "                                 ", "               A A               ", "                D                ", "                F                ", "                                 ", "                                 ", "                                 ", "                                 ", "                                 ", "                                 ", "                                 ", "                                 ", "                                 ", "                                 ", "  A                           A  ", "   DF                       FD   ", "  A                           A  ", "                                 ", "                                 ", "                                 ", "                                 ", "                                 ", "                                 ", "                                 ", "                                 ", "                                 ", "                                 ", "                F                ", "                D                ", "               A A               ", "                                 ", "                                 ")
                    .aisle("                                 ", "                                 ", "               A A               ", "               A A               ", "                D                ", "             GEEFEEG             ", "                                 ", "                                 ", "                                 ", "                                 ", "                                 ", "                                 ", "                                 ", "     G                     G     ", "     E                     E     ", "  AA E                     E AA  ", "    DF                     FD    ", "  AA E                     E AA  ", "     E                     E     ", "     G                     G     ", "                                 ", "                                 ", "                                 ", "                                 ", "                                 ", "                                 ", "                                 ", "             GEEFEEG             ", "                D                ", "               A A               ", "               A A               ", "                                 ", "                                 ")
                    .aisle("                                 ", "                                 ", "                                 ", "               A A               ", "              AAAAA              ", "                D                ", "                F                ", "                                 ", "                                 ", "                                 ", "                                 ", "                                 ", "                                 ", "                                 ", "    A                       A    ", "   AA                       AA   ", "    ADF                   FDA    ", "   AA                       AA   ", "    A                       A    ", "                                 ", "                                 ", "                                 ", "                                 ", "                                 ", "                                 ", "                                 ", "                F                ", "                D                ", "              AAAAA              ", "               A A               ", "                                 ", "                                 ", "                                 ")
                    .aisle("                                 ", "                                 ", "                                 ", "                                 ", "               A A               ", "               A A               ", "                D                ", "             GEEFEEG             ", "                                 ", "                                 ", "                                 ", "                                 ", "                                 ", "       G                 G       ", "       E                 E       ", "    AA E                 E AA    ", "      DF                 FD      ", "    AA E                 E AA    ", "       E                 E       ", "       G                 G       ", "                                 ", "                                 ", "                                 ", "                                 ", "                                 ", "             GEEFEEG             ", "                D                ", "               A A               ", "               A A               ", "                                 ", "                                 ", "                                 ", "                                 ")
                    .aisle("                                 ", "                                 ", "                                 ", "                                 ", "                                 ", "               A A               ", "              AAAAA              ", "                D                ", "                F                ", "                F                ", "                                 ", "                                 ", "                                 ", "                                 ", "      A                   A      ", "     AA                   AA     ", "      ADFF             FFDA      ", "     AA                   AA     ", "      A                   A      ", "                                 ", "                                 ", "                                 ", "                                 ", "                F                ", "                F                ", "                D                ", "              AAAAA              ", "               A A               ", "                                 ", "                                 ", "                                 ", "                                 ", "                                 ")
                    .aisle("                                 ", "                                 ", "                                 ", "                                 ", "                                 ", "                                 ", "               A A               ", "               A A               ", "                D                ", "                D                ", "                                 ", "                                 ", "                                 ", "                                 ", "                                 ", "      AA                 AA      ", "        DD             DD        ", "      AA                 AA      ", "                                 ", "                                 ", "                                 ", "                                 ", "                                 ", "                D                ", "                D                ", "               A A               ", "               A A               ", "                                 ", "                                 ", "                                 ", "                                 ", "                                 ", "                                 ")
                    .aisle("                                 ", "                                 ", "                                 ", "                                 ", "                                 ", "                                 ", "                                 ", "               A A               ", "               A A               ", "               A A               ", "                D                ", "                D                ", "             DDDDDDD             ", "            DD     DD            ", "            D  EEE  D            ", "       AAA  D EFFFE D  AAA       ", "          DDD EFFFE DDD          ", "       AAA  D EFFFE D  AAA       ", "            D  EEE  D            ", "            DD     DD            ", "             DDDDDDD             ", "                D                ", "                D                ", "               A A               ", "               A A               ", "               A A               ", "                                 ", "                                 ", "                                 ", "                                 ", "                                 ", "                                 ", "                                 ")
                    .aisle("                                 ", "                                 ", "                                 ", "                                 ", "                                 ", "                                 ", "                                 ", "                                 ", "                                 ", "               A A               ", "               A A               ", "               A A               ", "               A A               ", "              DDDDD              ", "             DDADADD             ", "         AAAADAADAADAAAA         ", "             DDDDDDD             ", "         AAAADAADAADAAAA         ", "             DDADADD             ", "              DDDDD              ", "               A A               ", "               A A               ", "               A A               ", "               A A               ", "                                 ", "                                 ", "                                 ", "                                 ", "                                 ", "                                 ", "                                 ", "                                 ", "                                 ")
                    .aisle("                                 ", "                                 ", "                                 ", "                                 ", "                                 ", "                                 ", "                                 ", "                                 ", "                                 ", "                                 ", "                                 ", "                                 ", "             AAAAAAA             ", "            AABBBBBAA            ", "            ABBBBBBBA            ", "            ABBAAABBA            ", "            ABBA~ABBA            ", "            ABBAAABBA            ", "            ABBBBBBBA            ", "            AABBBBBAA            ", "             AAAAAAA             ", "                                 ", "                                 ", "                                 ", "                                 ", "                                 ", "                                 ", "                                 ", "                                 ", "                                 ", "                                 ", "                                 ", "                                 ")
                    .where('~', controller(blocks(definition.get())))
                    .where('A', blocks(GTOBlocks.DIMENSIONALLY_TRANSCENDENT_CASING.get()))
                    .where('B', blocks(GTBlocks.HIGH_POWER_CASING.get())
                            .or(abilities(EXPORT_ITEMS).setPreviewCount(1))
                            .or(abilities(IMPORT_ITEMS).setPreviewCount(1))
                            .or(abilities(EXPORT_FLUIDS).setPreviewCount(1))
                            .or(abilities(IMPORT_FLUIDS).setPreviewCount(1)))
                    .where('D', blocks(GTOBlocks.DIMENSION_INJECTION_CASING.get()))
                    .where('E', blocks(GTOBlocks.DIMENSIONAL_BRIDGE_CASING.get()))
                    .where('F', blocks(GTOBlocks.SPACETIME_COMPRESSION_FIELD_GENERATOR.get()))
                    .where('G', blocks(GTOBlocks.DIMENSIONAL_STABILITY_CASING.get()))
                    .where(' ', any())
                    .build())
            .renderer(EyeOfHarmonyRenderer::new)
            .hasTESR(true)
            .register();

    public static final MultiblockMachineDefinition SPACE_PROBE_SURFACE_RECEPTION = multiblock("space_probe_surface_reception", "宇宙探测器地面接收单元", SpaceProbeSurfaceReceptionMachine::new)
            .nonYAxisRotation()
            .recipeTypes(GTORecipeTypes.SPACE_PROBE_SURFACE_RECEPTION_RECIPES)
            .tooltips(NewDataAttributes.EMPTY_WITH_BAR.create(
                    h -> h.addLines("运行限制", "Operating Restrictions", StyleBuilder::setGold),
                    c -> c.addLines(
                            NewDataAttributes.EMPTY_WITH_POINT.createBuilder(x -> x.addLines("只能运行在空间站", "Can only operate on space station", StyleBuilder::setRed), p -> p, StyleBuilder::setOneTab))))
            .tooltips(NewDataAttributes.EMPTY_WITH_BAR.create(
                    h -> h.addLines("戴森球连接", "Dyson Sphere Connection", StyleBuilder::setGold),
                    c -> c.addLines(
                            NewDataAttributes.EMPTY_WITH_POINT.createBuilder(x -> x.addLines("自动连接星系内未使用的戴森球", "Automatically connects to unused Dyson spheres in the galaxy", StyleBuilder::setWhite), p -> p, StyleBuilder::setOneTab),
                            NewDataAttributes.EMPTY_WITH_POINT.createBuilder(x -> x.addLines("根据戴森球模块数量提升产出", "Increases production based on Dyson sphere module count", StyleBuilder::setGreen), p -> p, StyleBuilder::setOneTab),
                            NewDataAttributes.EMPTY_WITH_POINT.createBuilder(x -> x.addLines("该操作不会损坏戴森球", "This operation will not damage the Dyson sphere", StyleBuilder::setGray), p -> p, StyleBuilder::setOneTab))))
            .perfectOCTooltips()
            .alwaysTryModifyRecipe(true)
            .block(GCYMBlocks.CASING_ATOMIC)
            .pattern(definition -> MultiBlockFileReader.start(definition)
                    .where('~', controller(blocks(definition.get())))
                    .where('A', blocks(ChemicalHelper.getBlock(TagPrefix.block, GTMaterials.Neutronium)))
                    .where('B', blocks(GTOBlocks.NAQUADAH_REINFORCED_PLANT_CASING.get()))
                    .where('C', blocks(GTOBlocks.HIGH_PRESSURE_RESISTANT_CASING.get()))
                    .where('D', blocks(ChemicalHelper.getBlock(TagPrefix.frameGt, GTMaterials.Neutronium)))
                    .where('E', blocks(GCYMBlocks.CASING_ATOMIC.get()))
                    .where('F', blocks(GTOBlocks.HYPER_MECHANICAL_CASING.get()))
                    .where('G', blocks(GTOBlocks.NEUTRONIUM_STABLE_CASING.get()))
                    .where('H', blocks(GTOBlocks.HYPER_CORE.get()))
                    .where('I', blocks(GCYMBlocks.HEAT_VENT.get()))
                    .where('J', blocks(GTOBlocks.ANTIFREEZE_HEATPROOF_MACHINE_CASING.get()))
                    .where('K', blocks(GTBlocks.HIGH_POWER_CASING.get()))
                    .where('L', blocks(ChemicalHelper.getBlock(TagPrefix.frameGt, GTOMaterials.BlackTitanium)))
                    .where('M', blocks(GTOBlocks.AMPROSIUM_ACTIVE_CASING.get()))
                    .where('b', blocks(GCYMBlocks.CASING_ATOMIC.get())
                            .or(autoAbilities(definition.getRecipeTypes()))
                            .or(abilities(MAINTENANCE).setExactLimit(1))
                            .or(abilities(COMPUTATION_DATA_RECEPTION).setExactLimit(1)))
                    .where(' ', any())
                    .build())
            .workableCasingRenderer(GTCEu.id("block/casings/gcym/atomic_casing"), GTCEu.id("block/multiblock/data_bank"))
            .register();

    public static final MultiblockMachineDefinition DIMENSIONALLY_TRANSCENDENT_PLASMA_FORGE = multiblock("dimensionally_transcendent_plasma_forge", "超维度等离子锻炉", DimensionallyTranscendentPlasmaForgeMachine::new)
            .nonYAxisRotation()
            .recipeTypes(GTORecipeTypes.DIMENSIONALLY_TRANSCENDENT_PLASMA_FORGE_RECIPES)
            .recipeTypes(GTORecipeTypes.STELLAR_FORGE_RECIPES)
            .parallelizableTooltips()
            .laserTooltips()
            .parallelizableOverclock()
            .block(GTOBlocks.DIMENSIONALLY_TRANSCENDENT_CASING)
            .pattern(definition -> FactoryBlockPattern.start(definition)
                    .aisle(" ddd   ddd             ddd   ddd ", "                                 ", "                                 ", "                                 ", " ddd   ddd             ddd   ddd ", "                                 ", "                                 ", "                                 ", "                                 ", "                                 ", " ddd   ddd             ddd   ddd ", "                                 ", "                                 ", "                                 ", " ddd   ddd   d     d   ddd   ddd ", "         d   d     d   d         ", "         d   d     d   d         ", "                                 ", "                                 ", "                                 ", "         d   d     d   d         ", "         d   d     d   d         ", "         d   d     d   d         ", "                                 ")
                    .aisle("dbbbd dbbbd    d d    dbbbd dbbbd", " CCC   CCC             CCC   CCC ", " CCC   CCC             CCC   CCC ", " CCC   CCC             CCC   CCC ", "dbbbd dbbbd           dbbbd dbbbd", "  d     d               d     d  ", "  d     d               d     d  ", "                                 ", "  d     d               d     d  ", "  d     d               d     d  ", "dbbbd dbbbd           dbbbd dbbbd", " CCC   CCC             CCC   CCC ", " CCC   CCC             CCC   CCC ", " CCC   CCC   d     d   CCC   CCC ", "dbbbd dbbdCCCb     bCCCdbbd dbbbd", "         bCCCb     bCCCb         ", "         bCCCb     bCCCb         ", "         d   d     d   d         ", "                                 ", "         d   d     d   d         ", "         bCCCb     bCCCb         ", "         bCCCb     bCCCb         ", "         bCCCb     bCCCb         ", "         d   d     d   d         ")
                    .aisle("dbbbd dbbbdddddsdsdddddbbbd dbbbd", " CbC   CbC             CbC   CbC ", " CbC   CbC             CbC   CbC ", " CbC   CbC             CbC   CbC ", "dbbbd dbbbd           dbbbd dbbbd", " ddd   ddd             ddd   ddd ", " ddd   ddd             ddd   ddd ", "  s     s               s     s  ", " ddd   ddd             ddd   ddd ", " ddd   ddd             ddd   ddd ", "dbbbd dbbbd           dbbbd dbbbd", " CbC   CbC             CbC   CbC ", " CbC   CbC             CbC   CbC ", " CbC   CbC   d     d   CbC   CbC ", "dbbbd dbbdCCCb     bCCCdbbd dbbbd", "  d     sbbbbbddsddbbbbbs     d  ", "  d      bCCCb     bCCCb      d  ", "  d      d   d     d   d      d  ", "   s                         s   ", "   s     d   d     d   d     s   ", "    ss   bCCCb     bCCCb   ss    ", "      dddbbbbbddsddbbbbbddd      ", "         bCCCb     bCCCb         ", "         d   d     d   d         ")
                    .aisle("dbbbdddbbbd    ded    dbbbdddbbbd", " CCCCCCCCC             CCCCCCCCC ", " CCCCCCCCC             CCCCCCCCC ", " CCCCCCCCC             CCCCCCCCC ", "dbbbdddbbbd           dbbbdddbbbd", "  d     d               d     d  ", "  d     d               d     d  ", "                                 ", "  d     d               d     d  ", "  d     d               d     d  ", "dbbbdddbbbd           dbbbdddbbbd", " CCCCCCCCC             CCCCCCCCC ", " CCCCCCCCC             CCCCCCCCC ", " CCCCCCCCC   d     d   CCCCCCCCC ", "dbbbdddbbdCCCb     bCCCdbbdddbbbd", "         bCCCb     bCCCb         ", "         bCCCb     bCCCb         ", "         dCCCd     dCCCd         ", "  s      dCCCd     dCCCd      s  ", "  s      dCCCd     dCCCd      s  ", "         bCCCb     bCCCb         ", "    ss   bCCCb     bCCCb   ss    ", "         bCCCb     bCCCb         ", "         d   d     d   d         ")
                    .aisle(" ddd   ddd     ded     ddd   ddd ", "   C   C                 C   C   ", "   C   C                 C   C   ", "   C   C                 C   C   ", " ddd   ddd             ddd   ddd ", "                                 ", "                                 ", "                                 ", "                                 ", "                                 ", " ddd   ddd             ddd   ddd ", "   C   C                 C   C   ", "   C   C                 C   C   ", "   C   C                 C   C   ", " ddd   dd    d     d    dd   ddd ", "         d   d     d   d         ", "         dCCCd     dCCCd         ", "                                 ", "                                 ", "                                 ", "  s      dCCCd     dCCCd      s  ", "   s     d   d     d   d     s   ", "         d   d     d   d         ", "                                 ")
                    .aisle("   d   d       ded       d   d   ", "   C   C                 C   C   ", "   C   C                 C   C   ", "   C   C                 C   C   ", "   d   d                 d   d   ", "                                 ", "                                 ", "                                 ", "                                 ", "                                 ", "   d   d                 d   d   ", "   C   C                 C   C   ", "   C   C                 C   C   ", "   C   C                 C   C   ", "   d   d                 d   d   ", "                                 ", "         dCCCd     dCCCd         ", "                                 ", "                                 ", "                                 ", "  s      dCCCd     dCCCd      s  ", "   s                         s   ", "                                 ", "                                 ")
                    .aisle(" ddd   ddd     ded     ddd   ddd ", "   C   C                 C   C   ", "   C   C                 C   C   ", "   C   C                 C   C   ", " ddd   ddd             ddd   ddd ", "                                 ", "                                 ", "                                 ", "                                 ", "                                 ", " ddd   ddd             ddd   ddd ", "   C   C                 C   C   ", "   C   C                 C   C   ", "   C   C                 C   C   ", " ddd   dd    d     d    dd   ddd ", "         d   d     d   d         ", "         dCCCd     dCCCd         ", "                                 ", "                                 ", "                                 ", "         dCCCd     dCCCd         ", "  d      d   d     d   d      d  ", "         d   d     d   d         ", "                                 ")
                    .aisle("dbbbdddbbbd    ded    dbbbdddbbbd", " CCCCCCCCC             CCCCCCCCC ", " CCCCCCCCC             CCCCCCCCC ", " CCCCCCCCC             CCCCCCCCC ", "dbbbdddbbbd           dbbbdddbbbd", "  d     d               d     d  ", "  d     d               d     d  ", "                                 ", "  d     d               d     d  ", "  d     d               d     d  ", "dbbbdddbbbd           dbbbdddbbbd", " CCCCCCCCC             CCCCCCCCC ", " CCCCCCCCC             CCCCCCCCC ", " CCCCCCCCC   d     d   CCCCCCCCC ", "dbbbdddbbdCCCb     bCCCdbbdddbbbd", "         bCCCb     bCCCb         ", "         bCCCb     bCCCb         ", "         dCCCd     dCCCd         ", "         dCCCd     dCCCd         ", "         dCCCd     dCCCd         ", "         bCCCb     bCCCb         ", "  d      bCCCb     bCCCb      d  ", "         bCCCb     bCCCb         ", "         d   d     d   d         ")
                    .aisle("dbbbd dbbbdddddsdsdddddbbbd dbbbd", " CbC   CbC             CbC   CbC ", " CbC   CbC             CbC   CbC ", " CbC   CbC             CbC   CbC ", "dbbbd dbbbd           dbbbd dbbbd", " ddd   ddd             ddd   ddd ", " ddd   ddd             ddd   ddd ", "  s     s               s     s  ", " ddd   ddd             ddd   ddd ", " ddd   ddd             ddd   ddd ", "dbbbd dbbbd           dbbbd dbbbd", " CbC   CbC             CbC   CbC ", " CbC   CbC             CbC   CbC ", " CbC   CbC   d     d   CbC   CbC ", "dbbbd dbbdCCCb     bCCCdbbd dbbbd", "  s     sbbbbbddsddbbbbbs     s  ", "         bCCCb     bCCCb         ", "         d   d     d   d         ", "                                 ", "         d   d     d   d         ", "         bCCCb     bCCCb         ", "  d     sbbbbbddsddbbbbbs     d  ", "         bCCCb     bCCCb         ", "         d   d     d   d         ")
                    .aisle("dbbbd dbbbd    ded    dbbbd dbbbd", " CCC   CCC             CCC   CCC ", " CCC   CCC             CCC   CCC ", " CCC   CCC             CCC   CCC ", "dbbbd dbbbd           dbbbd dbbbd", "  d     d               d     d  ", "  d     d               d     d  ", "                                 ", "  d     d               d     d  ", "  d     d               d     d  ", "dbbbd dbbbd           dbbbd dbbbd", " CCC   CCC             CCC   CCC ", " CCC   CCC             CCC   CCC ", " CCC   CCC   d     d   CCC   CCC ", "dddd   dddCCCb     bCCCddd   dddd", "dbbbd dbbdCCCb     bCCCdbbd dbbbd", "dbbbdddbbdCCCb     bCCCdbbdddbbbd", " ddd   ddd   d     d   ddd   ddd ", "   d   d                 d   d   ", " ddd   ddd   d     d   ddd   ddd ", "dbbbdddbbdCCCb     bCCCdbbdddbbbd", "dbbbd dbbdCCCb     bCCCdbbd dbbbd", "dbbbd dbbdCCCb     bCCCdbbd dbbbd", " ddd   ddd   d     d   ddd   ddd ")
                    .aisle(" ddd   ddd     ded     ddd   ddd ", "                                 ", "                                 ", "                                 ", " ddd   ddd             ddd   ddd ", "                                 ", "                                 ", "                                 ", "                                 ", "                                 ", " ddd   ddd             ddd   ddd ", "                                 ", "                                 ", "                                 ", " CCC   CCC   d     d   CCC   CCC ", " CbC   CbC   d     d   CbC   CbC ", " CCCCCCCCC   d     d   CCCCCCCCC ", "   C   C                 C   C   ", "   C   C                 C   C   ", "   C   C                 C   C   ", " CCCCCCCCC   d     d   CCCCCCCCC ", " CbC   CbC   d     d   CbC   CbC ", " CCC   CCC   d     d   CCC   CCC ", "                                 ")
                    .aisle("  d     d      ded      d     d  ", "                                 ", "                                 ", "                                 ", "                                 ", "                                 ", "                                 ", "                                 ", "                                 ", "                                 ", "                                 ", "                                 ", "                                 ", "                                 ", " CCC   CCC             CCC   CCC ", " CbC   CbC             CbC   CbC ", " CCCCCCCCC             CCCCCCCCC ", "   C   C                 C   C   ", "   C   C                 C   C   ", "   C   C                 C   C   ", " CCCCCCCCC             CCCCCCCCC ", " CbC   CbC             CbC   CbC ", " CCC   CCC             CCC   CCC ", "                                 ")
                    .aisle("  d     d      ded      d     d  ", "                                 ", "                                 ", "                                 ", "                                 ", "                                 ", "                                 ", "                                 ", "                                 ", "                                 ", "                                 ", "                                 ", "                                 ", "                                 ", " CCC   CCC             CCC   CCC ", " CbC   CbC             CbC   CbC ", " CCCCCCCCC             CCCCCCCCC ", "   C   C                 C   C   ", "   C   C                 C   C   ", "   C   C                 C   C   ", " CCCCCCCCC             CCCCCCCCC ", " CbC   CbC             CbC   CbC ", " CCC   CCC             CCC   CCC ", "                                 ")
                    .aisle("  d     d     dsdsd     d     d  ", "                                 ", "                                 ", "                                 ", "                                 ", "                                 ", "                                 ", "                                 ", "                                 ", "                                 ", "                                 ", "                                 ", "                                 ", " ddd   ddd             ddd   ddd ", "dbbbd dbbbd           dbbbd dbbbd", "dbbbd dbbbd           dbbbd dbbbd", "dbbbdddbbbd           dbbbdddbbbd", " ddd   ddd             ddd   ddd ", "   d   d                 d   d   ", " ddd   ddd             ddd   ddd ", "dbbbdddbbbd           dbbbdddbbbd", "dbbbd dbbbd           dbbbd dbbbd", "dbbbd dbbbd           dbbbd dbbbd", " ddd   ddd             ddd   ddd ")
                    .aisle("  d     d    deeeeed    d     d  ", "                                 ", "                                 ", "                                 ", "                                 ", "                                 ", "                                 ", "                                 ", "                                 ", "                                 ", "                                 ", "                                 ", "                                 ", "                                 ", "                                 ", "  d     d               d     d  ", "                                 ", "                                 ", "                                 ", "                                 ", "                                 ", "  d     d               d     d  ", "                                 ", "                                 ")
                    .aisle(" dsdddddsddddseedeesddddsdddddsd ", "                d                ", "                                 ", "                                 ", "                                 ", "                                 ", "                                 ", "                                 ", "                                 ", "                                 ", "                                 ", "                                 ", "                                 ", "                                 ", "                                 ", "  d     d               d     d  ", "                                 ", "                                 ", "                                 ", "                                 ", "                                 ", "  d     d               d     d  ", "                                 ", "                                 ")
                    .aisle("  deeeeedeeeededddedeeeedeeeeed  ", "               ddd               ", "                a                ", "                                 ", "                                 ", "                                 ", "                                 ", "                                 ", "                                 ", "                                 ", "                                 ", "                                 ", "                                 ", "                                 ", "                                 ", "  s     s               s     s  ", "                                 ", "                                 ", "                                 ", "                                 ", "                                 ", "  s     s               s     s  ", "                                 ", "                                 ")
                    .aisle(" dsdddddsddddseedeesddddsdddddsd ", "                d                ", "                                 ", "                                 ", "                                 ", "                                 ", "                                 ", "                                 ", "                                 ", "                                 ", "                                 ", "                                 ", "                                 ", "                                 ", "                                 ", "  d     d               d     d  ", "                                 ", "                                 ", "                                 ", "                                 ", "                                 ", "  d     d               d     d  ", "                                 ", "                                 ")
                    .aisle("  d     d    deeeeed    d     d  ", "                                 ", "                                 ", "                                 ", "                                 ", "                                 ", "                                 ", "                                 ", "                                 ", "                                 ", "                                 ", "                                 ", "                                 ", "                                 ", "                                 ", "  d     d               d     d  ", "                                 ", "                                 ", "                                 ", "                                 ", "                                 ", "  d     d               d     d  ", "                                 ", "                                 ")
                    .aisle("  d     d     dsdsd     d     d  ", "                                 ", "                                 ", "                                 ", "                                 ", "                                 ", "                                 ", "                                 ", "                                 ", "                                 ", "                                 ", "                                 ", "                                 ", " ddd   ddd             ddd   ddd ", "dbbbd dbbbd           dbbbd dbbbd", "dbbbd dbbbd           dbbbd dbbbd", "dbbbdddbbbd           dbbbdddbbbd", " ddd   ddd             ddd   ddd ", "   d   d                 d   d   ", " ddd   ddd             ddd   ddd ", "dbbbdddbbbd           dbbbdddbbbd", "dbbbd dbbbd           dbbbd dbbbd", "dbbbd dbbbd           dbbbd dbbbd", " ddd   ddd             ddd   ddd ")
                    .aisle("  d     d      ded      d     d  ", "                                 ", "                                 ", "                                 ", "                                 ", "                                 ", "                                 ", "                                 ", "                                 ", "                                 ", "                                 ", "                                 ", "                                 ", "                                 ", " CCC   CCC             CCC   CCC ", " CbC   CbC             CbC   CbC ", " CCCCCCCCC             CCCCCCCCC ", "   C   C                 C   C   ", "   C   C                 C   C   ", "   C   C                 C   C   ", " CCCCCCCCC             CCCCCCCCC ", " CbC   CbC             CbC   CbC ", " CCC   CCC             CCC   CCC ", "                                 ")
                    .aisle("  d     d      ded      d     d  ", "                                 ", "                                 ", "                                 ", "                                 ", "                                 ", "                                 ", "                                 ", "                                 ", "                                 ", "                                 ", "                                 ", "                                 ", "                                 ", " CCC   CCC             CCC   CCC ", " CbC   CbC             CbC   CbC ", " CCCCCCCCC             CCCCCCCCC ", "   C   C                 C   C   ", "   C   C                 C   C   ", "   C   C                 C   C   ", " CCCCCCCCC             CCCCCCCCC ", " CbC   CbC             CbC   CbC ", " CCC   CCC             CCC   CCC ", "                                 ")
                    .aisle(" ddd   ddd     ded     ddd   ddd ", "                                 ", "                                 ", "                                 ", " ddd   ddd             ddd   ddd ", "                                 ", "                                 ", "                                 ", "                                 ", "                                 ", " ddd   ddd             ddd   ddd ", "                                 ", "                                 ", "                                 ", " CCC   CCC   d     d   CCC   CCC ", " CbC   CbC   d     d   CbC   CbC ", " CCCCCCCCC   d     d   CCCCCCCCC ", "   C   C                 C   C   ", "   C   C                 C   C   ", "   C   C                 C   C   ", " CCCCCCCCC   d     d   CCCCCCCCC ", " CbC   CbC   d     d   CbC   CbC ", " CCC   CCC   d     d   CCC   CCC ", "                                 ")
                    .aisle("dbbbd dbbbd    ded    dbbbd dbbbd", " CCC   CCC             CCC   CCC ", " CCC   CCC             CCC   CCC ", " CCC   CCC             CCC   CCC ", "dbbbd dbbbd           dbbbd dbbbd", "  d     d               d     d  ", "  d     d               d     d  ", "                                 ", "  d     d               d     d  ", "  d     d               d     d  ", "dbbbd dbbbd           dbbbd dbbbd", " CCC   CCC             CCC   CCC ", " CCC   CCC             CCC   CCC ", " CCC   CCC   d     d   CCC   CCC ", "dddd   dddCCCb     bCCCddd   dddd", "dbbbd dbbdCCCb     bCCCdbbd dbbbd", "dbbbdddbbdCCCb     bCCCdbbdddbbbd", " ddd   ddd   d     d   ddd   ddd ", "   d   d                 d   d   ", " ddd   ddd   d     d   ddd   ddd ", "dbbbdddbbdCCCb     bCCCdbbdddbbbd", "dbbbd dbbdCCCb     bCCCdbbd dbbbd", "dbbbd dbbdCCCb     bCCCdbbd dbbbd", " ddd   ddd   d     d   ddd   ddd ")
                    .aisle("dbbbd dbbbdddddsdsdddddbbbd dbbbd", " CbC   CbC             CbC   CbC ", " CbC   CbC             CbC   CbC ", " CbC   CbC             CbC   CbC ", "dbbbd dbbbd           dbbbd dbbbd", " ddd   ddd             ddd   ddd ", " ddd   ddd             ddd   ddd ", "  s     s               s     s  ", " ddd   ddd             ddd   ddd ", " ddd   ddd             ddd   ddd ", "dbbbd dbbbd           dbbbd dbbbd", " CbC   CbC             CbC   CbC ", " CbC   CbC             CbC   CbC ", " CbC   CbC   d     d   CbC   CbC ", "dbbbd dbbdCCCb     bCCCdbbd dbbbd", "  s     sbbbbbddsddbbbbbs     s  ", "         bCCCb     bCCCb         ", "         d   d     d   d         ", "                                 ", "         d   d     d   d         ", "         bCCCb     bCCCb         ", "  d     sbbbbbddsddbbbbbs     d  ", "         bCCCb     bCCCb         ", "         d   d     d   d         ")
                    .aisle("dbbbdddbbbd    ded    dbbbdddbbbd", " CCCCCCCCC             CCCCCCCCC ", " CCCCCCCCC             CCCCCCCCC ", " CCCCCCCCC             CCCCCCCCC ", "dbbbdddbbbd           dbbbdddbbbd", "  d     d               d     d  ", "  d     d               d     d  ", "                                 ", "  d     d               d     d  ", "  d     d               d     d  ", "dbbbdddbbbd           dbbbdddbbbd", " CCCCCCCCC             CCCCCCCCC ", " CCCCCCCCC             CCCCCCCCC ", " CCCCCCCCC   d     d   CCCCCCCCC ", "dbbbdddbbdCCCb     bCCCdbbdddbbbd", "         bCCCb     bCCCb         ", "         bCCCb     bCCCb         ", "         dCCCd     dCCCd         ", "         dCCCd     dCCCd         ", "         dCCCd     dCCCd         ", "         bCCCb     bCCCb         ", "  d      bCCCb     bCCCb      d  ", "         bCCCb     bCCCb         ", "         d   d     d   d         ")
                    .aisle(" ddd   ddd     ded     ddd   ddd ", "   C   C                 C   C   ", "   C   C                 C   C   ", "   C   C                 C   C   ", " ddd   ddd             ddd   ddd ", "                                 ", "                                 ", "                                 ", "                                 ", "                                 ", " ddd   ddd             ddd   ddd ", "   C   C                 C   C   ", "   C   C                 C   C   ", "   C   C                 C   C   ", " ddd   dd    d     d    dd   ddd ", "         d   d     d   d         ", "         dCCCd     dCCCd         ", "                                 ", "                                 ", "                                 ", "         dCCCd     dCCCd         ", "  d      d   d     d   d      d  ", "         d   d     d   d         ", "                                 ")
                    .aisle("   d   d       ded       d   d   ", "   C   C                 C   C   ", "   C   C                 C   C   ", "   C   C                 C   C   ", "   d   d                 d   d   ", "                                 ", "                                 ", "                                 ", "                                 ", "                                 ", "   d   d                 d   d   ", "   C   C                 C   C   ", "   C   C                 C   C   ", "   C   C                 C   C   ", "   d   d                 d   d   ", "                                 ", "         dCCCd     dCCCd         ", "                                 ", "                                 ", "                                 ", "  s      dCCCd     dCCCd      s  ", "   s                         s   ", "                                 ", "                                 ")
                    .aisle(" ddd   ddd     ded     ddd   ddd ", "   C   C                 C   C   ", "   C   C                 C   C   ", "   C   C                 C   C   ", " ddd   ddd             ddd   ddd ", "                                 ", "                                 ", "                                 ", "                                 ", "                                 ", " ddd   ddd             ddd   ddd ", "   C   C                 C   C   ", "   C   C                 C   C   ", "   C   C                 C   C   ", " ddd   dd    d     d    dd   ddd ", "         d   d     d   d         ", "         dCCCd     dCCCd         ", "                                 ", "                                 ", "                                 ", "  s      dCCCd     dCCCd      s  ", "   s     d   d     d   d     s   ", "         d   d     d   d         ", "                                 ")
                    .aisle("dbbbdddbbbd    ded    dbbbdddbbbd", " CCCCCCCCC             CCCCCCCCC ", " CCCCCCCCC             CCCCCCCCC ", " CCCCCCCCC             CCCCCCCCC ", "dbbbdddbbbd           dbbbdddbbbd", "  d     d               d     d  ", "  d     d               d     d  ", "                                 ", "  d     d               d     d  ", "  d     d               d     d  ", "dbbbdddbbbd           dbbbdddbbbd", " CCCCCCCCC             CCCCCCCCC ", " CCCCCCCCC             CCCCCCCCC ", " CCCCCCCCC   d     d   CCCCCCCCC ", "dbbbdddbbdCCCb     bCCCdbbdddbbbd", "         bCCCb     bCCCb         ", "         bCCCb     bCCCb         ", "         dCCCd     dCCCd         ", "  s      dCCCd     dCCCd      s  ", "  s      dCCCd     dCCCd      s  ", "         bCCCb     bCCCb         ", "    ss   bCCCb     bCCCb   ss    ", "         bCCCb     bCCCb         ", "         d   d     d   d         ")
                    .aisle("dbbbd dbbbdddddsdsdddddbbbd dbbbd", " CbC   CbC             CbC   CbC ", " CbC   CbC             CbC   CbC ", " CbC   CbC             CbC   CbC ", "dbbbd dbbbd           dbbbd dbbbd", " ddd   ddd             ddd   ddd ", " ddd   ddd             ddd   ddd ", "  s     s               s     s  ", " ddd   ddd             ddd   ddd ", " ddd   ddd             ddd   ddd ", "dbbbd dbbbd           dbbbd dbbbd", " CbC   CbC             CbC   CbC ", " CbC   CbC             CbC   CbC ", " CbC   CbC   d     d   CbC   CbC ", "dbbbd dbbdCCCb     bCCCdbbd dbbbd", "  d     sbbbbbddsddbbbbbs     d  ", "  d      bCCCb     bCCCb      d  ", "  d      d   d     d   d      d  ", "   s                         s   ", "   s     d   d     d   d     s   ", "    ss   bCCCb     bCCCb   ss    ", "      dddbbbbbddsddbbbbbddd      ", "         bCCCb     bCCCb         ", "         d   d     d   d         ")
                    .aisle("dbbbd dbbbd    d d    dbbbd dbbbd", " CCC   CCC             CCC   CCC ", " CCC   CCC             CCC   CCC ", " CCC   CCC             CCC   CCC ", "dbbbd dbbbd           dbbbd dbbbd", "  d     d               d     d  ", "  d     d               d     d  ", "                                 ", "  d     d               d     d  ", "  d     d               d     d  ", "dbbbd dbbbd           dbbbd dbbbd", " CCC   CCC             CCC   CCC ", " CCC   CCC             CCC   CCC ", " CCC   CCC   d     d   CCC   CCC ", "dbbbd dbbdCCCb     bCCCdbbd dbbbd", "         bCCCb     bCCCb         ", "         bCCCb     bCCCb         ", "         d   d     d   d         ", "                                 ", "         d   d     d   d         ", "         bCCCb     bCCCb         ", "         bCCCb     bCCCb         ", "         bCCCb     bCCCb         ", "         d   d     d   d         ")
                    .aisle(" ddd   ddd             ddd   ddd ", "                                 ", "                                 ", "                                 ", " ddd   ddd             ddd   ddd ", "                                 ", "                                 ", "                                 ", "                                 ", "                                 ", " ddd   ddd             ddd   ddd ", "                                 ", "                                 ", "                                 ", " ddd   ddd   d     d   ddd   ddd ", "         d   d     d   d         ", "         d   d     d   d         ", "                                 ", "                                 ", "                                 ", "         d   d     d   d         ", "         d   d     d   d         ", "         d   d     d   d         ", "                                 ")
                    .where('a', controller(blocks(definition.get())))
                    .where('e', blocks(GTOBlocks.DIMENSIONALLY_TRANSCENDENT_CASING.get())
                            .or(abilities(PARALLEL_HATCH).setMaxGlobalLimited(1))
                            .or(GTOPredicates.autoLaserAbilities(definition.getRecipeTypes())))
                    .where('b', blocks(GTOBlocks.DIMENSION_INJECTION_CASING.get()))
                    .where('C', heatingCoils())
                    .where('d', blocks(GTOBlocks.DIMENSIONALLY_TRANSCENDENT_CASING.get()))
                    .where('s', blocks(GTOBlocks.DIMENSIONAL_BRIDGE_CASING.get()))
                    .where(' ', any())
                    .build())
            .workableCasingRenderer(GTOCore.id("block/casings/dimensionally_transcendent_casing"), GTOCore.id("block/multiblock/dimensionally_transcendent_plasma_forge"))
            .register();

    public static final MultiblockMachineDefinition CIRCUIT_ASSEMBLY_LINE = multiblock("circuit_assembly_line", "电路装配线", CircuitAssemblyLineMachine::new)
            .allRotation()
            .recipeTypes(GTORecipeTypes.CIRCUIT_ASSEMBLY_LINE_RECIPES)
            .tooltips(ComponentBuilder.create().addStoryLine("""
                    GTO寰宇格雷科技有限公司的顶级工程师们设计了这条电路装配线。
                    董事长视察时赞叹道："这是我们最优雅的基础设施之一。"
                    透明的层压玻璃展示着内部精密的装配过程，机器人们有条不紊
                    地制造着各种复杂电路。当相同配方的机器人协作时，效率翻倍，
                    这条生产线成为了公司电子工业的核心支柱。
                    """,
                    """
                            Top engineers of GTO designed this elegant circuit assembly line.
                            The CEO praised it as "one of our most graceful infrastructures."
                            Through laminated glass, precise assembly processes are displayed,
                            with robots methodically crafting complex circuits in perfect harmony.
                            This production line became the cornerstone of our electronics industry.
                            """).build())
            .specialParallelizableTooltips()
            .tooltips(NewDataAttributes.ALLOW_PARALLEL_NUMBER.create(h -> h.addLines("同配方机器人数量x2的并行", "Parallelism of x2 for the same recipe robots")))
            .alwaysTryModifyRecipe(true)
            .block(GTOBlocks.PIKYONIUM_MACHINE_CASING)
            .pattern(definition -> FactoryBlockPattern.start(definition)
                    .aisle("bbb", "bbb", "bfb")
                    .aisle("bbb", "cec", "bdb").setRepeatable(16)
                    .aisle("bbb", "bab", "bgb")
                    .where('a', controller(blocks(definition.get())))
                    .where('b', blocks(GTOBlocks.PIKYONIUM_MACHINE_CASING.get())
                            .or(abilities(INPUT_ENERGY).setMaxGlobalLimited(2))
                            .or(abilities(MAINTENANCE).setExactLimit(1)))
                    .where('c', blocks(GTBlocks.CASING_LAMINATED_GLASS.get()))
                    .where('d', blocks(GTOMachines.HUGE_ITEM_IMPORT_BUS.getBlock()).or(blocks(GTMachines.ITEM_IMPORT_BUS[0].getBlock())))
                    .where('e', blocks(GTOBlocks.MACHINE_CASING_CIRCUIT_ASSEMBLY_LINE.get()))
                    .where('f', abilities(EXPORT_ITEMS))
                    .where('g', abilities(IMPORT_FLUIDS_4X))
                    .build())
            .workableCasingRenderer(GTOCore.id("block/casings/pikyonium_machine_casing"), GTCEu.id("block/multiblock/assembly_line"))
            .register();

    public static final MultiblockMachineDefinition ASSEMBLER_MODULE = multiblock("assembler_module", "太空电梯组装模块", (holder) -> new SpaceElevatorModuleMachine(holder, true))
            .nonYAxisRotation()
            .recipeTypes(GTORecipeTypes.ASSEMBLER_MODULE_RECIPES)
            .specialParallelizableTooltips()
            .tooltips(NewDataAttributes.ALLOW_PARALLEL_NUMBER.create(h -> h.addLines("4^(动力模块等级-1)", "4^(Power Module tier - 1)")))
            .alwaysTryModifyRecipe(true)
            .block(GTOBlocks.SPACE_ELEVATOR_MECHANICAL_CASING)
            .pattern(definition -> FactoryBlockPattern.start(definition)
                    .aisle("a", "b", "b", "b", "b")
                    .aisle("a", "b", "b", "b", "b")
                    .aisle("c", "b", "b", "~", "b")
                    .where('~', controller(blocks(definition.get())))
                    .where('b', blocks(GTOBlocks.SPACE_ELEVATOR_MECHANICAL_CASING.get())
                            .or(autoAbilities(definition.getRecipeTypes())))
                    .where('a', blocks(GTOBlocks.SPACE_ELEVATOR_MODULE_BASE.get()))
                    .where('c', blocks(GTOBlocks.MODULE_CONNECTOR.get()))
                    .build())
            .workableCasingRenderer(GTOCore.id("block/casings/space_elevator_mechanical_casing"), GTCEu.id("block/multiblock/gcym/large_assembler"))
            .register();

    public static final MultiblockMachineDefinition RESOURCE_COLLECTION_MODULE = multiblock("resource_collection_module", "太空电梯资源采集模块", (holder) -> new SpaceElevatorModuleMachine(holder, false))
            .nonYAxisRotation()
            .recipeTypes(GTORecipeTypes.MINER_MODULE_RECIPES)
            .recipeTypes(GTORecipeTypes.DRILLING_MODULE_RECIPES)
            .specialParallelizableTooltips()
            .tooltips(NewDataAttributes.ALLOW_PARALLEL_NUMBER.create(h -> h.addLines("4^(动力模块等级-1)", "4^(Power Module tier - 1)")))
            .alwaysTryModifyRecipe(true)
            .block(GTOBlocks.SPACE_ELEVATOR_MECHANICAL_CASING)
            .pattern(definition -> FactoryBlockPattern.start(definition)
                    .aisle("a", "b", "b", "b", "b")
                    .aisle("a", "b", "b", "b", "b")
                    .aisle("c", "b", "b", "~", "b")
                    .where('~', controller(blocks(definition.get())))
                    .where('b', blocks(GTOBlocks.SPACE_ELEVATOR_MECHANICAL_CASING.get())
                            .or(autoAbilities(definition.getRecipeTypes())))
                    .where('a', blocks(GTOBlocks.SPACE_ELEVATOR_MODULE_BASE.get()))
                    .where('c', blocks(GTOBlocks.MODULE_CONNECTOR.get()))
                    .build())
            .workableCasingRenderer(GTOCore.id("block/casings/space_elevator_mechanical_casing"), GTCEu.id("block/multiblock/gcym/large_assembler"))
            .register();

    public static final MultiblockMachineDefinition BLOCK_CONVERSION_ROOM = multiblock("block_conversion_room", "方块转换室", holder -> new BlockConversionRoomMachine(holder, false))
            .noneRotation()
            .recipeTypes(GTORecipeTypes.BLOCK_CONVERSIONRECIPES)
            .tooltips(NewDataAttributes.MAIN_FUNCTION.create(v -> v.addLines("每秒随机转化机器内部方块", "Randomly converts blocks inside the machine every second")))
            .tooltips(NewDataAttributes.EMPTY_WITH_BAR.create(
                    h -> h.addLines("电压等级加成", "Voltage Tier Bonus", StyleBuilder::setGold),
                    c -> c.addLines(
                            NewDataAttributes.EMPTY_WITH_POINT.createBuilder(x -> x.addLines("每高出MV1级，转换方块数量+4", "For each tier above MV1, block conversion +4", StyleBuilder::setWhite), p -> p, StyleBuilder::setOneTab),
                            NewDataAttributes.EMPTY_WITH_POINT.createBuilder(x -> x.addLines("不会重复转换同一方块", "Will not repeatedly convert the same block", StyleBuilder::setGray), p -> p, StyleBuilder::setOneTab))))
            .block(GTOBlocks.ALUMINIUM_BRONZE_CASING)
            .pattern(definition -> FactoryBlockPattern.start(definition)
                    .aisle("bbbbbbb", "bbbbbbb", "bdddddb", "bdddddb", "bdddddb", "bdddddb", "bdddddb", "bbbbbbb")
                    .aisle("bbbbbbb", "bcccccb", "d     d", "d     d", "d     d", "d     d", "d     d", "bbbbbbb")
                    .aisle("bbbbbbb", "bcccccb", "d     d", "d     d", "d     d", "d     d", "d     d", "bbbbbbb")
                    .aisle("bbbbbbb", "bcccccb", "d     d", "d     d", "d     d", "d     d", "d     d", "bbbabbb")
                    .aisle("bbbbbbb", "bcccccb", "d     d", "d     d", "d     d", "d     d", "d     d", "bbbbbbb")
                    .aisle("bbbbbbb", "bcccccb", "d     d", "d     d", "d     d", "d     d", "d     d", "bbbbbbb")
                    .aisle("bbbbbbb", "bbbbbbb", "bdddddb", "bdddddb", "bdddddb", "bdddddb", "bdddddb", "bbbbbbb")
                    .where('a', controller(blocks(definition.get())))
                    .where('b', blocks(GTOBlocks.ALUMINIUM_BRONZE_CASING.get())
                            .or(abilities(INPUT_ENERGY).setMaxGlobalLimited(2))
                            .or(blocks(GTOMachines.BLOCK_BUS.getBlock()).setMaxGlobalLimited(1)))
                    .where('c', blocks(GTOBlocks.SHINING_OBSIDIAN.get()))
                    .where('d', blocks(GTBlocks.CASING_TEMPERED_GLASS.get())
                            .or(blocks(Blocks.IRON_DOOR).setMaxGlobalLimited(4).setPreviewCount(1)))
                    .where(' ', any())
                    .build())
            .workableCasingRenderer(GTOCore.id("block/casings/aluminium_bronze_casing"), GTCEu.id("block/multiblock/cleanroom"))
            .register();

    public static final MultiblockMachineDefinition LARGE_BLOCK_CONVERSION_ROOM = multiblock("large_block_conversion_room", "大型方块转换室", holder -> new BlockConversionRoomMachine(holder, true))
            .noneRotation()
            .recipeTypes(GTORecipeTypes.BLOCK_CONVERSIONRECIPES)
            .tooltips(ComponentBuilder.create().addStoryLine(
                    """
                            一名格雷科技有限公司员工在实验室里焦急地踱步，大型方块转换室是他的最新发明。
                            这台庞然大物由铝青铜外壳构成，能够每秒随机转换内部的一个方块。
                            他记得董事长曾说过，提高电压等级可以增加转换效率，每高出MV1级，转换数量增加64个。
                            第一次测试时，他紧张地启动了机器，看着内部的石头逐渐变成了各种稀有材料。
                            值得注意的是，机器似乎有自己的"记忆"，从不会重复转换同一个方块。
                            GTO寰宇格雷科技有限公司的同事们都惊叹于这项发明，它将彻底改变资源获取的方式。
                            """,
                    """
                            A GregTech Ltd. employee paced anxiously in the laboratory, the Large Block Conversion Room was his latest invention.
                            This behemoth, encased in aluminium bronze, could randomly convert one block inside it every second.
                            He remembered the CEO saying that increasing voltage tiers would improve efficiency, each tier above MV1 adds 64 to conversion count.
                            During the first test, he nervously activated the machine, watching as stones inside gradually transformed into various rare materials.
                            Notably, the machine seemed to have its own "memory," never converting the same block twice.
                            Colleagues at GTO Universal GregTech Company marveled at this invention that would revolutionize resource acquisition.
                            """).build())
            .tooltips(NewDataAttributes.MAIN_FUNCTION.create(v -> v.addLines("每秒随机转化机器内部一个方块", "Randomly converts blocks inside the machine every second")))
            .tooltips(NewDataAttributes.EMPTY_WITH_BAR.create(
                    h -> h.addLines("电压等级加成", "Voltage Tier Bonus", StyleBuilder::setGold),
                    c -> c.addLines(
                            NewDataAttributes.EMPTY_WITH_POINT.createBuilder(x -> x.addLines("每高出MV1级，转换方块数量+64", "For each tier above MV1, block conversion +64", StyleBuilder::setWhite), p -> p, StyleBuilder::setOneTab),
                            NewDataAttributes.EMPTY_WITH_POINT.createBuilder(x -> x.addLines("不会重复转换同一方块", "Will not repeatedly convert the same block", StyleBuilder::setGray), p -> p, StyleBuilder::setOneTab))))
            .block(GTOBlocks.ALUMINIUM_BRONZE_CASING)
            .pattern(definition -> FactoryBlockPattern.start(definition)
                    .aisle("bbbbbbbbbbb", "bbbbbbbbbbb", "bdddddddddb", "bdddddddddb", "bdddddddddb", "bdddddddddb", "bdddddddddb", "bdddddddddb", "bdddddddddb", "bbbbbbbbbbb")
                    .aisle("bbbbbbbbbbb", "bcccccccccb", "d         d", "d         d", "d         d", "d         d", "d         d", "d         d", "d         d", "bbbbbbbbbbb")
                    .aisle("bbbbbbbbbbb", "bcccccccccb", "d         d", "d         d", "d         d", "d         d", "d         d", "d         d", "d         d", "bbbbbbbbbbb")
                    .aisle("bbbbbbbbbbb", "bcccccccccb", "d         d", "d         d", "d         d", "d         d", "d         d", "d         d", "d         d", "bbbbbbbbbbb")
                    .aisle("bbbbbbbbbbb", "bcccccccccb", "d         d", "d         d", "d         d", "d         d", "d         d", "d         d", "d         d", "bbbbbbbbbbb")
                    .aisle("bbbbbbbbbbb", "bcccccccccb", "d         d", "d         d", "d         d", "d         d", "d         d", "d         d", "d         d", "bbbbbabbbbb")
                    .aisle("bbbbbbbbbbb", "bcccccccccb", "d         d", "d         d", "d         d", "d         d", "d         d", "d         d", "d         d", "bbbbbbbbbbb")
                    .aisle("bbbbbbbbbbb", "bcccccccccb", "d         d", "d         d", "d         d", "d         d", "d         d", "d         d", "d         d", "bbbbbbbbbbb")
                    .aisle("bbbbbbbbbbb", "bcccccccccb", "d         d", "d         d", "d         d", "d         d", "d         d", "d         d", "d         d", "bbbbbbbbbbb")
                    .aisle("bbbbbbbbbbb", "bcccccccccb", "d         d", "d         d", "d         d", "d         d", "d         d", "d         d", "d         d", "bbbbbbbbbbb")
                    .aisle("bbbbbbbbbbb", "bbbbbbbbbbb", "bdddddddddb", "bdddddddddb", "bdddddddddb", "bdddddddddb", "bdddddddddb", "bdddddddddb", "bdddddddddb", "bbbbbbbbbbb")
